<?xml version="1.0"?>
<robot>

  <property name="left_leg_gripper_j0_damping" value= "1.0" />
  <property name="left_leg_gripper_j0_friction" value= "0.0" />
  <property name="left_leg_gripper_j1_damping" value= "1.0" />
  <property name="left_leg_gripper_j1_friction" value= "0.0" />
  <property name="left_leg_gripper_j1_damping" value= "1.0" />
  <property name="left_leg_gripper_j1_friction" value= "0.0" />

<!--  placeholder for screw joint-->
  <joint name="${robot_name}left_leg/gripper/joint0" type="revolute">
    <parent link="${robot_name}left_leg_foot"/>
    <child link="${robot_name}left_leg/gripper/link0"/>
    <origin rpy="0.0 0 0" xyz="0 0 0"/>
    <axis xyz="0 0 1"/>
    <dynamics damping="${left_leg_gripper_j0_damping}" friction="${left_leg_gripper_j0_friction}"/>
    <limit effort="330.0" lower="-.1" upper=".75" velocity="1.0"/>
  </joint>

  <joint name="${robot_name}left_leg/gripper/joint1" type="revolute">
    <parent link="${robot_name}left_leg_foot"/>
    <child link="${robot_name}left_leg_jaw0"/>
    <origin rpy="0.0 -0.087266 0.0" xyz="0.01905 0 0.17546"/>
    <axis xyz="0 1 0"/>
    <dynamics damping="${left_leg_gripper_j0_damping}" friction="${left_leg_gripper_j0_friction}"/>
    <limit effort="330.0" lower="-.1" upper=".75" velocity="1.0"/>
  </joint>

  <joint name="${robot_name}left_leg/gripper/joint2" type="revolute">
    <parent link="${robot_name}left_leg_foot"/>
    <child link="${robot_name}left_leg_jaw1"/>
    <origin rpy="0.0 0.087266 0.0" xyz="-0.01905 0 0.17546"/>
    <axis xyz="0 -1 0"/>
    <dynamics damping="${left_leg_gripper_j1_damping}" friction="${left_leg_gripper_j1_friction}"/>
    <limit effort="330.0" lower="-.1" upper=".75" velocity="1.0"/>
  </joint>

  <joint name="${robot_name}fixed/left_leg_foot/left_leg_camera0_physical" type="fixed">
    <parent link="${robot_name}left_leg_foot"/>
    <child link="${robot_name}left_leg_camera0_physical"/>
    <origin rpy="0 0 0" xyz="-0.025 .07 0.13"/>
  </joint>

  <joint name="${robot_name}fixed/left_leg_foot/left_leg_camera1_physical" type="fixed">
    <parent link="${robot_name}left_leg_foot"/>
    <child link="${robot_name}left_leg_camera1_physical"/>
    <origin rpy="0.0 0 0" xyz="0.025 .07 0.13"/>
  </joint>

<!--  placeholder for screw-->
  <non_visual_link name="${robot_name}left_leg/gripper/link0"/>

  <link name="${robot_name}left_leg_jaw0">
    <inertial>
      <mass value="0.01"/>
      <inertia ixx="0.0001" ixy="0.0" ixz="0.0" iyy="0.0001" iyz="0.0" izz="0.0001"/>
      <origin rpy="0 0 0" xyz="0.00236 0 0.02395"/>
    </inertial>
    <visual>
      <geometry>
        <mesh filename="package://r2_description/meshes/r2c_legs/r2cl_foot_jaw1.dae"/>
      </geometry>
      <origin rpy="0 0 0" xyz="0 0 0"/>
    </visual>
    <collision>
      <geometry>
        <mesh filename="package://r2_description/meshes/r2c_legs/r2cl_foot_jaw1.dae"/>
      </geometry>
      <origin rpy="0 0 0" xyz="0 0 0"/>
    </collision>
  </link>

  <link name="${robot_name}left_leg_jaw1">
    <inertial>
      <mass value="0.01"/>
      <inertia ixx="0.0001" ixy="0.0" ixz="0.0" iyy="0.0001" iyz="0.0" izz="0.0001"/>
      <origin rpy="0 0 0" xyz="0.00236 0 0.02395"/>
    </inertial>
    <visual>
      <geometry>
        <mesh filename="package://r2_description/meshes/r2c_legs/r2cl_foot_jaw2.dae"/>
      </geometry>
      <origin rpy="0 0 0" xyz="0 0 0"/>
    </visual>
    <collision>
      <geometry>
        <mesh filename="package://r2_description/meshes/r2c_legs/r2cl_foot_jaw2.dae"/>
      </geometry>
      <origin rpy="0 0 0" xyz="0 0 0"/>
    </collision>
  </link>

  <non_visual_link name="${robot_name}left_leg_camera0_physical"/>

  <joint name="${robot_name}fixed/left_leg_camera0_physical/left_leg_camera0_optical" type="fixed">
    <parent link="${robot_name}left_leg_camera0_physical"/>
    <child link="${robot_name}left_leg_camera0_optical"/>
    <origin rpy="0 -1.5708 -1.5708" xyz="0 0 .03"/>
  </joint>

  <non_visual_link name="${robot_name}left_leg_camera0_optical"/>

  <non_visual_link name="${robot_name}left_leg_camera1_physical"/>

  <joint name="${robot_name}fixed/left_leg_camera1_physical/left_leg_camera1_optical" type="fixed">
    <parent link="${robot_name}left_leg_camera1_physical"/>
    <child link="${robot_name}left_leg_camera1_optical"/>
    <origin rpy="0 -1.5708 -1.5708" xyz="0 0 0.03"/>
  </joint>

  <non_visual_link name="${robot_name}left_leg_camera1_optical"/>

</robot>
