<?xml version="1.0" ?>
<!-- =================================================================================== -->
<!-- |    This document was autogenerated by xacro from /home/athackst/catkin_ws/src/nasa_r2_common/r2_description/robots/r2_fullbody.urdf.xacro | -->
<!-- |    EDITING THIS FILE BY HAND IS NOT RECOMMENDED                                 | -->
<!-- =================================================================================== -->
<robot name="r2_fullbody" xmlns:controller="http://playerstage.sourceforge.net/gazebo/xmlschema/#controller" xmlns:interface="http://playerstage.sourceforge.net/gazebo/xmlschema/#interface" xmlns:sensor="http://playerstage.sourceforge.net/gazebo/xmlschema/#sensor" xmlns:xacro="http://playerstage.sourceforge.net/gazebo/xmlschema/#interface">
  <link name="world"/>
  <!--  transforms in first joint don't seem to work properly-->
  <joint name="r2/fixed/world/robot_world" type="fixed">
    <parent link="world"/>
    <child link="r2/robot_world"/>
    <origin rpy="0 0 0.0" xyz="0.0 0.0 0.0"/>
  </joint>
  <link name="r2/robot_world"/>
  <joint name="r2/fixed/robot_world/robot_base" type="fixed">
    <parent link="r2/robot_world"/>
    <child link="r2/robot_base"/>
    <origin rpy="0 3.14159 1.57079" xyz="0.255 0.9 1.365"/>
  </joint>
  <link name="r2/robot_base"/>
  <joint name="r2/fixed/robot_base/leg_stand_connection" type="fixed">
    <parent link="r2/robot_base"/>
    <child link="r2/leg_stand_connection"/>
    <origin rpy="0 3.14159 0" xyz="0.0 0.0 0.0"/>
  </joint>
  <link name="r2/leg_stand_connection">
    <inertial>
      <mass value="0.01"/>
      <inertia ixx="0.0001" ixy="0.0" ixz="0.0" iyy="0.001" iyz="0.0" izz="0.001"/>
    </inertial>
  </link>
  <material name="white">
    <color rgba="1.0 1.0 1.0 1.0"/>
  </material>
  <material name="dirty_white">
    <color rgba="0.322 0.322 0.322 1.0"/>
  </material>
  <material name="gold">
    <color rgba=".878 .49 0.008 1"/>
  </material>
  <material name="steel">
    <color rgba=".7 .7 .7 1"/>
  </material>
  <material name="blue">
    <color rgba="0 0 0.8 1"/>
  </material>
  <joint name="r2/waist/joint0" type="revolute">
    <parent link="r2/robot_base"/>
    <child link="r2/waist_center"/>
    <axis xyz="0 0 1"/>
    <origin rpy="0.0 0 0.0" xyz="0.0 0.0 0.0"/>
    <dynamics damping="20.0" friction="1.0"/>
    <limit effort="10000000.0" lower="-3.14" upper="3.14" velocity="10"/>
  </joint>
  <link name="r2/waist_center">
    <visual>
      <geometry>
        <mesh filename="package://r2_description/meshes/Body.dae"/>
      </geometry>
      <origin rpy="-1.57 0 -1.57" xyz="0.01 0.05 -0.5625"/>
    </visual>
    <!-- <collision>
      <geometry>
         <mesh filename="package://r2_description/meshes/Body.dae"/>  
      </geometry>
      <origin rpy="-1.57 0 -1.57" xyz="0.00 0.05 -0.5625"/>
    </collision> -->
    <inertial>
      <mass value="10"/>
      <inertia ixx="1" ixy="0.0" ixz="0.0" iyy="1" iyz="0.0" izz="1"/>
    </inertial>
  </link>
  <joint name="r2/fixed/waist_center/robot_reference" type="fixed">
    <parent link="r2/waist_center"/>
    <child link="r2/robot_reference"/>
    <origin rpy="0.0 0 0.0" xyz="0.1234 0.0 0.0"/>
  </joint>
  <joint name="r2/fixed/waist_center/body_cover" type="fixed">
    <parent link="r2/waist_center"/>
    <child link="r2/body_cover"/>
    <origin rpy="0.0 0.0 0.0" xyz="0 0.0 0.0"/>
  </joint>
  <joint name="r2/fixed/waist_center/backpack" type="fixed">
    <parent link="r2/waist_center"/>
    <child link="r2/backpack"/>
    <origin rpy="0.0 0.0 0.0" xyz="0 0.0 0.0"/>
  </joint>
  <joint name="r2/fixed/waist_center/chest_center" type="fixed">
    <parent link="r2/waist_center"/>
    <child link="r2/chest_center"/>
    <origin rpy="0.0 0.0 0.0" xyz="-0.01235 0.0 0.0"/>
  </joint>
  <link name="r2/robot_reference">
    <inertial>
      <mass value="0.01"/>
      <inertia ixx="0.0001" ixy="0.0" ixz="0.0" iyy="0.001" iyz="0.0" izz="0.001"/>
    </inertial>
  </link>
  <link name="r2/body_cover">
    <visual>
      <geometry>
        <mesh filename="package://r2_description/meshes/Body_Cover.dae"/>
      </geometry>
      <!--       <origin rpy="-1.57 0 -1.57" xyz="0.02 0.05 -0.5625"/>
 -->
      <origin rpy="-1.57 0 -1.57" xyz="0.01 0.05 -0.5625"/>
    </visual>
    <collision>
      <geometry>
        <mesh filename="package://r2_description/meshes/Body_Cover.dae"/>
      </geometry>
      <origin rpy="-1.57 0 -1.57" xyz="0.01 0.05 -0.5625"/>
    </collision>
    <inertial>
      <mass value="0.1"/>
      <inertia ixx="0.001" ixy="0.0" ixz="0.0" iyy="0.001" iyz="0.0" izz="0.001"/>
    </inertial>
  </link>
  <link name="r2/backpack">
    <visual>
      <geometry>
        <mesh filename="package://r2_description/meshes/Backpack.dae"/>
      </geometry>
      <origin rpy="0 0 0.25" xyz="0.0 0.0 -0.54"/>
    </visual>
    <collision>
      <geometry>
        <mesh filename="package://r2_description/meshes/Backpack.dae"/>
      </geometry>
      <origin rpy="0 0 0.25" xyz="0.0 0.0 -0.54"/>
    </collision>
    <inertial>
      <mass value="10"/>
      <inertia ixx="1" ixy="0.0" ixz="0.0" iyy="1" iyz="0.0" izz="1"/>
    </inertial>
  </link>
  <link name="r2/chest_center">
    <inertial>
      <mass value="0.01"/>
      <inertia ixx="0.0001" ixy="0.0" ixz="0.0" iyy="0.001" iyz="0.0" izz="0.001"/>
    </inertial>
  </link>
  <joint name="r2/fixed/chest_center/chest_base" type="fixed">
    <parent link="r2/chest_center"/>
    <child link="r2/chest_base"/>
    <origin rpy="0.0 -0.0 0.0 " xyz="-0.05299202 -0.0 -0.5442458"/>
  </joint>
  <link name="r2/chest_base">
    <inertial>
      <mass value="0.01"/>
      <inertia ixx="0.0001" ixy="0.0" ixz="0.0" iyy="0.001" iyz="0.0" izz="0.001"/>
    </inertial>
  </link>
  <joint name="r2/neck/joint0" type="revolute">
    <parent link="r2/waist_center"/>
    <child link="r2/neck_base"/>
    <origin rpy=" -1.570796 -0.0 0.0 " xyz=" 0.08636 0.0 -0.6142228 "/>
    <dynamics damping="1.0" friction="0.0"/>
    <axis xyz="0 0 1"/>
    <limit effort="10000.0" lower="-0.7" upper="0.175" velocity="10"/>
  </joint>
  <link name="r2/neck_base">
    <visual>
      <geometry>
        <mesh filename="package://r2_description/meshes/Neck_Lower.dae"/>
      </geometry>
      <origin rpy="-1.57 1.57 0" xyz="0.0 0.0 0.0"/>
    </visual>
    <inertial>
      <mass value=".1"/>
      <inertia ixx=".0010" ixy="0.0" ixz="0.0" iyy=".0010" iyz="0.0" izz=".0010"/>
    </inertial>
    <collision>
      <geometry>
        <mesh filename="package://r2_description/meshes/Neck_Lower.dae"/>
      </geometry>
      <origin rpy="-1.57 1.57 0" xyz="0.0 0.0 0.0"/>
    </collision>
  </link>
  <joint name="r2/neck/joint1" type="revolute">
    <parent link="r2/neck_base"/>
    <child link="r2/neck_lower_pitch"/>
    <origin rpy=" -1.570796 -0.0 0.0 " xyz=" -0.0762 -0.0 0.0 "/>
    <dynamics damping="1.0" friction="0.0"/>
    <axis xyz="0 0 1"/>
    <limit effort="10000.0" lower="-1.22" upper="1.22" velocity="10"/>
  </joint>
  <link name="r2/neck_lower_pitch">
    <visual>
      <geometry>
        <mesh filename="package://r2_description/meshes/Neck_Upper.dae"/>
      </geometry>
      <origin rpy="0 0 1.57" xyz="0.075 0.0 0.0"/>
    </visual>
    <inertial>
      <mass value=".1"/>
      <inertia ixx=".0010" ixy="0.0" ixz="0.0" iyy=".0010" iyz="0.0" izz=".0010"/>
    </inertial>
    <collision>
      <geometry>
        <mesh filename="package://r2_description/meshes/Neck_Upper.dae"/>
      </geometry>
      <origin rpy="0 0 1.57" xyz="0.075 0.0 0.0"/>
    </collision>
  </link>
  <joint name="r2/neck/joint2" type="revolute">
    <parent link="r2/neck_lower_pitch"/>
    <child link="r2/neck_roll"/>
    <origin rpy=" 1.570796 -0.0 0.0 " xyz=" 0.0508 0.0 0.1777619 "/>
    <dynamics damping="1.0" friction="0.0"/>
    <axis xyz="0 0 1"/>
    <limit effort="10000.0" lower="-0.7" upper="0.175" velocity="10"/>
  </joint>
  <link name="r2/neck_roll">
    <visual>
      <geometry>
        <mesh filename="package://r2_description/meshes/Head.dae"/>
      </geometry>
      <origin rpy="0 1.57 0" xyz="-0.0 0.07 0.0"/>
    </visual>
    <collision>
      <geometry>
        <mesh filename="package://r2_description/meshes/Head.dae"/>
      </geometry>
      <origin rpy="0 1.57 0" xyz="-0.0 0.07 0.0"/>
    </collision>
    <inertial>
      <mass value=".1"/>
      <inertia ixx=".0010" ixy="0.0" ixz="0.0" iyy=".0010" iyz="0.0" izz=".0010"/>
    </inertial>
  </link>
  <joint name="r2/fixed/neck_roll/neck_upper_pitch" type="fixed">
    <parent link="r2/neck_roll"/>
    <child link="r2/neck_upper_pitch"/>
    <origin rpy=" 1.570796 -0.0 0.0 " xyz=" 0.0 0.0 0.0 "/>
  </joint>
  <link name="r2/neck_upper_pitch">
    <inertial>
      <mass value=".1"/>
      <inertia ixx=".0010" ixy="0.0" ixz="0.0" iyy=".0010" iyz="0.0" izz=".0010"/>
    </inertial>
  </link>
  <joint name="r2/fixed/neck_upper_pitch/asus_frame" type="fixed">
    <parent link="r2/neck_upper_pitch"/>
    <child link="r2/asus_frame"/>
    <origin rpy="1.50 0.0 1.57 " xyz="0.12 -0.015 -0.14 "/>
    <!-- OK    <origin rpy="1.45 0 1.57 " xyz="0.11 -0.040 -0.15 "/>  -->
    <!-- ORIGINAL     <origin rpy="1.57 0 1.57 " xyz="0.066675 -0.0508 -0.116205 "/>  -->
  </joint>
  <joint name="r2/fixed/neck_upper_pitch/simulated_asus_camera_frame" type="fixed">
    <parent link="r2/neck_upper_pitch"/>
    <child link="r2/simulated_asus_camera_frame"/>
    <dynamics damping="1.0"/>
    <origin rpy="3.14 0 0" xyz="0.12 -0.015 -0.14 "/>
    <!--     <origin rpy="0 0 0" xyz="0.12 -0.015 -0.14 "/> -->
  </joint>
  <joint name="r2/fixed/neck_upper_pitch/simulated_asus_depth_frame" type="fixed">
    <parent link="r2/neck_upper_pitch"/>
    <child link="r2/simulated_asus_depth_frame"/>
    <dynamics damping="1.0"/>
    <origin rpy="1.57 0 1.57" xyz="0.12 -0.015 -0.14 "/>
    <!--     <origin rpy="0 0 0" xyz="0.12 -0.015 -0.14 "/> -->
  </joint>
  <joint name="r2/fixed/neck_upper_pitch/vision_center_frame" type="fixed">
    <parent link="r2/neck_upper_pitch"/>
    <child link="r2/vision_center_frame"/>
    <dynamics damping="1.0"/>
    <origin rpy="1.57 -1.57 1.57" xyz=" 0.066675 0.0 -0.116205 "/>
  </joint>
  <link name="r2/asus_frame">
    <inertial>
      <mass value=".01"/>
      <inertia ixx=".0010" ixy="0.0" ixz="0.0" iyy=".0010" iyz="0.0" izz=".0010"/>
    </inertial>
  </link>
  <joint name="r2/fixed/asus_frame/openni_depth_frame" type="fixed">
    <parent link="r2/asus_frame"/>
    <child link="r2/openni_depth_frame"/>
    <origin rpy="1.57 -1.57 0 " xyz="0 0 0 "/>
  </joint>
  <link name="r2/openni_depth_frame">
    <inertial>
      <mass value=".01"/>
      <inertia ixx=".0010" ixy="0.0" ixz="0.0" iyy=".0010" iyz="0.0" izz=".0010"/>
    </inertial>
  </link>
  <link name="r2/simulated_asus_camera_frame">
    <inertial>
      <mass value=".01"/>
      <inertia ixx=".0010" ixy="0.0" ixz="0.0" iyy=".0010" iyz="0.0" izz=".0010"/>
    </inertial>
  </link>
  <link name="r2/simulated_asus_depth_frame">
    <inertial>
      <mass value=".01"/>
      <inertia ixx=".0010" ixy="0.0" ixz="0.0" iyy=".0010" iyz="0.0" izz=".0010"/>
    </inertial>
  </link>
  <link name="r2/vision_center_frame">
    <inertial>
      <mass value=".1"/>
      <inertia ixx=".0010" ixy="0.0" ixz="0.0" iyy=".0010" iyz="0.0" izz=".0010"/>
    </inertial>
  </link>
  <joint name="r2/fixed/vision_center_frame/left_camera_frame" type="fixed">
    <parent link="r2/vision_center_frame"/>
    <child link="r2/left_camera_frame"/>
    <dynamics damping="1.0"/>
    <origin rpy="0 0 1.57" xyz="0.0087 0.04887 0.01789"/>
  </joint>
  <joint name="r2/fixed/vision_center_frame/right_camera_frame" type="fixed">
    <parent link="r2/vision_center_frame"/>
    <child link="r2/right_camera_frame"/>
    <dynamics damping="1.0"/>
    <origin rpy="0 0 1.57" xyz="0.0087 -0.04887 0.01789"/>
  </joint>
  <link name="r2/left_camera_frame">
    <inertial>
      <mass value=".1"/>
      <inertia ixx=".0010" ixy="0.0" ixz="0.0" iyy=".0010" iyz="0.0" izz=".0010"/>
    </inertial>
  </link>
  <joint name="r2/fixed/left_camera_frame/left_camera_optical_frame" type="fixed">
    <parent link="r2/left_camera_frame"/>
    <child link="r2/left_camera_optical_frame"/>
    <dynamics damping="1.0"/>
    <origin rpy="-1.57 -1.57 0" xyz="0 0 0"/>
  </joint>
  <link name="r2/left_camera_optical_frame">
    <inertial>
      <mass value=".1"/>
      <inertia ixx=".0010" ixy="0.0" ixz="0.0" iyy=".0010" iyz="0.0" izz=".0010"/>
    </inertial>
  </link>
  <link name="r2/right_camera_frame">
    <inertial>
      <mass value=".1"/>
      <inertia ixx=".0010" ixy="0.0" ixz="0.0" iyy=".0010" iyz="0.0" izz=".0010"/>
    </inertial>
  </link>
  <joint name="r2/fixed/right_camera_frame/right_camera_optical_frame" type="fixed">
    <parent link="r2/right_camera_frame"/>
    <child link="r2/right_camera_optical_frame"/>
    <dynamics damping="1.0"/>
    <origin rpy="-1.57 -1.57 0" xyz="0 0 0"/>
  </joint>
  <link name="r2/right_camera_optical_frame">
    <inertial>
      <mass value=".1"/>
      <inertia ixx=".0010" ixy="0.0" ixz="0.0" iyy=".0010" iyz="0.0" izz=".0010"/>
    </inertial>
  </link>
  <joint name="r2/left_arm/joint0" type="revolute">
    <parent link="r2/chest_base"/>
    <child link="r2/left_shoulder_roll"/>
    <origin rpy=" -1.5664 -0.0 -2.8802 " xyz=" -0.0 -0.0 0.0 "/>
    <axis xyz="0 0 1"/>
    <dynamics damping="10.0" friction="0.0"/>
    <limit effort="100.0" lower="-1.57" upper="1.57" velocity="10"/>
  </joint>
  <link name="r2/left_shoulder_roll">
    <visual>
      <geometry>
        <mesh filename="package://r2_description/meshes/Left_Shoulder_Upper.dae"/>
      </geometry>
      <material name="dirty_white"/>
      <origin rpy="0 0 1.57" xyz="0 0 .08"/>
    </visual>
    <!-- <collision>
      <geometry>
        <mesh filename="package://r2_description/meshes/Left_Shoulder_Upper.dae" scale="0.7 0.7 0.7"/>
      </geometry>
      <origin rpy="0 0 1.57" xyz="0 0 .08"/>
    </collision> -->
    <inertial>
      <origin xyz="-0.0089916 -0.00131572   0.10287   "/>
      <mass value="6.168856232"/>
      <inertia ixx="0.0198585269" ixy="-0.0060195977" ixz="-0.0003950635" iyy="0.0671900643" iyz="0.00012683" izz="0.0634150128"/>
    </inertial>
  </link>
  <joint name="r2/left_arm/joint1" type="revolute">
    <parent link="r2/left_shoulder_roll"/>
    <child link="r2/left_shoulder_pitch"/>
    <origin rpy=" -1.5701 -0.0 1.570796 " xyz=" 0.0 0.0 0.316611 "/>
    <axis xyz="0 0 1"/>
    <dynamics damping="10.0" friction="0.0"/>
    <limit effort="100.0" lower="-1.66" upper=".175" velocity="10"/>
  </joint>
  <link name="r2/left_shoulder_pitch">
    <visual>
      <geometry>
        <mesh filename="package://r2_description/meshes/Left_Shoulder_Lower.dae"/>
      </geometry>
      <material name="dirty_white"/>
      <origin rpy=".0 0 -1.57" xyz="0 0 0"/>
    </visual>
    <!-- <collision>
      <geometry>
        <mesh filename="package://r2_description/meshes/Left_Shoulder_Lower.dae"/>
      </geometry>
      <origin rpy=".0 0 -1.57" xyz="0 0 0"/>
    </collision> -->
    <inertial>
      <origin xyz="0.037084 -0.00028448   0.0077978   "/>
      <mass value="4.4270615312"/>
      <inertia ixx="0.02701064" ixy="0.001512947" ixz="-0.000052382497887" iyy="0.0113836825" iyz="0.0000217138622526" izz="0.0251962741"/>
    </inertial>
  </link>
  <joint name="r2/left_arm/joint2" type="revolute">
    <parent link="r2/left_shoulder_pitch"/>
    <child link="r2/left_upper_arm"/>
    <origin rpy=" 1.57 -0.0 0.0 " xyz=" 0.0 0.0 0.0 "/>
    <axis xyz="0 0 1"/>
    <dynamics damping="10.0" friction="0.0"/>
    <limit effort="100.0" lower="-4.89" upper="-0.79" velocity="10"/>
  </joint>
  <link name="r2/left_upper_arm">
    <visual>
      <geometry>
        <mesh filename="package://r2_description/meshes/Left_Upper_Arm.dae"/>
      </geometry>
      <material name="dirty_white"/>
      <origin rpy="0 0 3.14" xyz="0 0 .1016"/>
    </visual>
    <collision>
      <geometry>
        <mesh filename="package://r2_description/meshes/Left_Upper_Arm.dae" scale="0.8 0.8 0.8"/>
      </geometry>
      <origin rpy="0 0 3.14" xyz="0 0 .1016"/>
    </collision>
    <inertial>
      <origin xyz="-0.0074168 -0.041402   0.1016   "/>
      <mass value="4.853438359"/>
      <inertia ixx="0.016007389" ixy="-0.00339462" ixz="0.0065843922" iyy="0.0462370652" iyz="0.0013754064" izz="0.04214011"/>
    </inertial>
  </link>
  <joint name="r2/left_arm/joint3" type="revolute">
    <parent link="r2/left_upper_arm"/>
    <child link="r2/left_elbow"/>
    <origin rpy=" -1.5748 -0.0 0.0 " xyz=" -0.05437886 -0.0 0.3564382 "/>
    <axis xyz="0 0 1"/>
    <dynamics damping="1.0" friction="0.0"/>
    <limit effort="100.0" lower="-2.79" upper="-.087" velocity="10"/>
  </joint>
  <link name="r2/left_elbow">
    <visual>
      <geometry>
        <mesh filename="package://r2_description/meshes/Left_Elbow.dae"/>
      </geometry>
      <material name="dirty_white"/>
      <origin rpy="0 0 -1.57" xyz="0 0 0"/>
    </visual>
    <collision>
      <geometry>
        <mesh filename="package://r2_description/meshes/Left_Elbow.dae"/>
      </geometry>
      <origin rpy="0 0 -1.57" xyz="0 0 0"/>
    </collision>
    <inertial>
      <origin xyz="0.026162 0.033782   0.0154432   "/>
      <mass value="2.9710300235"/>
      <inertia ixx="0.0120274897" ixy="0.0016417085" ixz="-0.001188117" iyy="0.0088377175" iyz="0.0031605083" izz="0.0105350275"/>
    </inertial>
  </link>
  <joint name="r2/left_arm/joint4" type="revolute">
    <parent link="r2/left_elbow"/>
    <child link="r2/left_lower_arm"/>
    <origin rpy=" 1.5738 -0.0 0.0 " xyz=" 0.0540385 0.0 0.0 "/>
    <axis xyz="0 0 1"/>
    <dynamics damping="1.0" friction="0.0"/>
    <limit effort="100.0" lower="-1.3" upper="4.45" velocity="10"/>
  </joint>
  <link name="r2/left_lower_arm">
    <visual>
      <geometry>
        <mesh filename="package://r2_description/meshes/Left_Forearm.dae"/>
      </geometry>
      <origin xyz="0 0 0.1"/>
      <material name="dirty_white"/>
    </visual>
    <collision>
      <geometry>
        <mesh filename="package://r2_description/meshes/Left_Forearm.dae"/>
      </geometry>
      <origin xyz="0 0 0.1"/>
    </collision>
    <inertial>
      <origin xyz="0.0003556 -0.00122682   0.17653   "/>
      <mass value="6.939963261"/>
      <inertia ixx="0.0125249771" ixy="-0.0002446467" ixz="0.0005208986" iyy="0.0395063532" iyz="-0.0001691457" izz="0.0403842721"/>
    </inertial>
  </link>
  <joint name="r2/left_arm/joint5" type="revolute">
    <parent link="r2/left_lower_arm"/>
    <child link="r2/left_wrist_pitch"/>
    <origin rpy=" -1.5952 -0.0 0.0 " xyz=" 0.0 0.0 0.3570478 "/>
    <axis xyz="0 0 1"/>
    <dynamics damping="1.0" friction="0.0"/>
    <limit effort="100.0" lower="-1.22" upper="1.22" velocity="10"/>
  </joint>
  <link name="r2/left_wrist_pitch">
    <inertial>
      <origin xyz="-0.004064   0.000000152908   -0.00092202"/>
      <mass value="0.1165732391"/>
      <inertia ixx="0.1" ixy="0.0" ixz="0.0" iyy="0.1" iyz="0.0" izz="0.1"/>
    </inertial>
  </link>
  <joint name="r2/left_arm/joint6" type="revolute">
    <parent link="r2/left_wrist_pitch"/>
    <child link="r2/left_wrist_yaw"/>
    <origin rpy=" 1.6505 -0.0 -1.5727 " xyz=" -0.00001156 -0.006072621 0.0 "/>
    <axis xyz="0 0 1"/>
    <dynamics damping="1.0" friction="0.0"/>
    <limit effort="100.0" lower="-0.785" upper="0.785" velocity="10"/>
  </joint>
  <link name="r2/left_wrist_yaw">
    <inertial>
      <origin xyz="-0.00090932   -0.0253746  0.067564     "/>
      <mass value="0.1"/>
      <inertia ixx="0.1" ixy="0.0" ixz="0.0" iyy="0.1" iyz="0.0" izz="0.1"/>
    </inertial>
  </link>
  <joint name="r2/fixed/left_wrist_yaw/left_palm" type="fixed">
    <parent link="r2/left_wrist_yaw"/>
    <child link="r2/left_palm"/>
    <origin rpy=" 0.0 -0.0 -0.014 " xyz=" 0.0 -0.0 0.0 "/>
  </joint>
  <link name="r2/left_palm">
    <visual>
      <geometry>
        <mesh filename="package://r2_description/meshes/Left_Palm.dae"/>
      </geometry>
      <origin rpy="3.14 0 1.57" xyz="0.0 0.0 -0.0"/>
    </visual>
    <collision>
      <geometry>
        <mesh filename="package://r2_description/meshes/Left_Palm.dae"/>
      </geometry>
      <origin rpy="3.14 0 1.57" xyz="0.0 0.0 -0.0"/>
    </collision>
    <inertial>
      <origin xyz="0.067564   -0.0253746   -0.00090932"/>
      <mass value="1.1"/>
      <inertia ixx="0.1" ixy="0.0" ixz="0.0" iyy="0.1" iyz="0.0" izz="0.1"/>
    </inertial>
  </link>
  <joint name="r2/left_arm/hand/thumb/joint0" type="revolute">
    <parent link="r2/left_wrist_yaw"/>
    <child link="r2/left_thumb_base"/>
    <origin rpy=" -1.57079632679 -0.0 1.30899702752 " xyz=" 0.03302 0.03048 0.00635 "/>
    <axis xyz="0 0 1"/>
    <limit effort="10000000.0" lower="-1.2217" upper="0.0" velocity="10"/>
    <dynamics damping="0.1" friction="0.0"/>
  </joint>
  <joint name="r2/fixed/left_index_base/left_index_base" type="fixed">
    <parent link="r2/left_wrist_yaw"/>
    <child link="r2/left_index_base"/>
    <origin rpy=" 0.0 -0.0 0.122172725275 " xyz=" 0.0994646728 0.0271119346 -0.0161544 "/>
  </joint>
  <joint name="r2/left_arm/hand/index/joint0" type="revolute">
    <parent link="r2/left_index_base"/>
    <child link="r2/left_index_yaw"/>
    <origin rpy="0.0 0.0 0.0" xyz="0.0 0.0 0.0"/>
    <axis xyz="0 0 1"/>
    <limit effort="10000000.0" lower="-0.3491" upper="0.3491" velocity="10"/>
    <dynamics damping="0.1" friction="0.0"/>
  </joint>
  <joint name="r2/fixed/left_middle_base/left_middle_base" type="fixed">
    <parent link="r2/left_wrist_yaw"/>
    <child link="r2/left_middle_base"/>
    <origin rpy=" 0.0 -0.0 0.0 " xyz=" 0.10646537 0.00254 -0.0161544 "/>
  </joint>
  <joint name="r2/left_arm/hand/middle/joint0" type="revolute">
    <parent link="r2/left_middle_base"/>
    <child link="r2/left_middle_yaw"/>
    <origin rpy="0.0 0.0 0.0" xyz="0.0 0.0 0.0"/>
    <axis xyz="0 0 1"/>
    <limit effort="10000000.0" lower="-0.3491" upper="0.3491" velocity="10"/>
    <dynamics damping="0.1" friction="0.0"/>
  </joint>
  <joint name="r2/left_arm/hand/ring/joint0" type="revolute">
    <parent link="r2/left_wrist_yaw"/>
    <child link="r2/left_ring_proximal"/>
    <origin rpy=" 1.57079632679 -0.0 -0.122172725275 " xyz=" 0.1084570602 -0.0197673468 -0.012319 "/>
    <axis xyz="0 0 1"/>
    <limit effort="10000000.0" lower="0" upper="2.9671" velocity="10"/>
    <dynamics damping="0.1" friction="0.0"/>
  </joint>
  <joint name="r2/left_arm/hand/little/joint0" type="revolute">
    <parent link="r2/left_wrist_yaw"/>
    <child link="r2/left_little_proximal"/>
    <origin rpy=" 1.60570321374 -0.0872667473393 -0.17453258148 " xyz=" 0.094635701 -0.0403792436 -0.0060878212 "/>
    <axis xyz="0 0 1"/>
    <limit effort="10000000.0" lower="0" upper="2.9671" velocity="10"/>
    <dynamics damping="0.1" friction="0.0"/>
  </joint>
  <link name="r2/left_thumb_base">
    <inertial>
      <mass value=".05"/>
      <inertia ixx=".0010" ixy="0.0" ixz="0.0" iyy=".0010" iyz="0.0" izz=".0010"/>
    </inertial>
  </link>
  <joint name="r2/fixed/left_thumb_base/left_thumb_proximal" type="fixed">
    <parent link="r2/left_thumb_base"/>
    <child link="r2/left_thumb_proximal"/>
    <origin rpy=" -1.570796 -0.0 0.0 " xyz=" 0.011938 0.0 0.0 "/>
  </joint>
  <link name="r2/left_thumb_proximal">
    <inertial>
      <mass value=".0010"/>
      <inertia ixx=".0010" ixy="0.0" ixz="0.0" iyy=".0010" iyz="0.0" izz=".0010"/>
    </inertial>
    <visual>
      <geometry>
        <mesh filename="package://r2_description/meshes/Left_Thumb_Carp.dae"/>
      </geometry>
      <origin rpy="-1.57 0 0" xyz="-0.01 0.0 0.0"/>
    </visual>
    <collision>
      <geometry>
        <mesh filename="package://r2_description/meshes/Left_Thumb_Carp.dae"/>
      </geometry>
      <origin rpy="-1.57 0 0" xyz="-0.01 0.0 0.0"/>
    </collision>
  </link>
  <joint name="r2/left_arm/hand/thumb/joint1" type="revolute">
    <parent link="r2/left_thumb_proximal"/>
    <child link="r2/left_thumb_medial_prime"/>
    <origin rpy=" 0.0 -0.0 0.0 " xyz=" 0.0 0.0 0.0 "/>
    <axis xyz="0 0 1"/>
    <limit effort="10000000.0" lower="0.0" upper="1.3963" velocity="10"/>
    <dynamics damping="0.1" friction="0.0"/>
  </joint>
  <link name="r2/left_thumb_medial_prime">
    <inertial>
      <mass value=".0010"/>
      <inertia ixx=".0010" ixy="0.0" ixz="0.0" iyy=".0010" iyz="0.0" izz=".0010"/>
    </inertial>
    <visual>
      <geometry>
        <mesh filename="package://r2_description/meshes/Left_Thumb_MtCar.dae"/>
      </geometry>
      <origin rpy="-1.57 -1.57 0" xyz="-0.0 0 0.0"/>
    </visual>
    <collision>
      <geometry>
        <mesh filename="package://r2_description/meshes/Left_Thumb_MtCar.dae"/>
      </geometry>
      <origin rpy="-1.57 -1.57 0" xyz="0.0 0.0 0.0"/>
    </collision>
  </link>
  <joint name="r2/left_arm/hand/thumb/joint2" type="revolute">
    <parent link="r2/left_thumb_medial_prime"/>
    <child link="r2/left_thumb_medial"/>
    <origin rpy=" -0.698132284627 -0.0 0.0 " xyz=" 0.030734 -0.001905 0.00254 "/>
    <axis xyz="0 0 1"/>
    <limit effort="10000000.0" lower="0.0" upper="1.2217" velocity="10"/>
    <dynamics damping="0.1" friction="0.0"/>
  </joint>
  <link name="r2/left_thumb_medial">
    <inertial>
      <mass value=".0010"/>
      <inertia ixx=".0010" ixy="0.0" ixz="0.0" iyy=".0010" iyz="0.0" izz=".0010"/>
    </inertial>
    <visual>
      <geometry>
        <mesh filename="package://r2_description/meshes/Thumb_Proximal.dae"/>
      </geometry>
      <origin rpy="3.14 0 1.57" xyz="0.0 0.0 0.0"/>
    </visual>
    <collision>
      <geometry>
        <mesh filename="package://r2_description/meshes/Thumb_Proximal.dae"/>
      </geometry>
      <origin rpy="3.14 0 1.57" xyz="0.0 0.0 0.0"/>
    </collision>
  </link>
  <joint name="r2/left_arm/hand/thumb/joint3" type="revolute">
    <parent link="r2/left_thumb_medial"/>
    <child link="r2/left_thumb_distal"/>
    <origin rpy=" 0.0 -0.0 0.0 " xyz=" 0.03937 0.0 0.0 "/>
    <axis xyz="0 0 1"/>
    <limit effort="10000000.0" lower="-0.5236" upper="1.57" velocity="10"/>
    <dynamics damping="0.1" friction="0.0"/>
  </joint>
  <link name="r2/left_thumb_distal">
    <inertial>
      <mass value=".0010"/>
      <inertia ixx=".0010" ixy="0.0" ixz="0.0" iyy=".0010" iyz="0.0" izz=".0010"/>
    </inertial>
    <visual>
      <geometry>
        <mesh filename="package://r2_description/meshes/Thumb_Dist.dae"/>
      </geometry>
      <origin rpy="3.14 3.14 0" xyz="0.0 0.0 0.0"/>
    </visual>
    <collision>
      <geometry>
        <mesh filename="package://r2_description/meshes/Thumb_Dist.dae"/>
      </geometry>
      <origin rpy="3.14 3.14 0" xyz="0.0 0.0 0.0"/>
    </collision>
  </link>
  <joint name="r2/fixed/left_thumb_distal/left_thumb_tip" type="fixed">
    <parent link="r2/left_thumb_distal"/>
    <child link="r2/left_thumb_tip"/>
    <origin rpy=" 0.0 -0.0 0.0 " xyz=" 0.03302 0.0 0.0 "/>
  </joint>
  <link name="r2/left_thumb_tip">
    <inertial>
      <mass value=".0010"/>
      <inertia ixx=".0010" ixy="0.0" ixz="0.0" iyy=".0010" iyz="0.0" izz=".0010"/>
    </inertial>
  </link>
  <link name="r2/left_index_base">
    <inertial>
      <mass value=".0010"/>
      <inertia ixx=".0010" ixy="0.0" ixz="0.0" iyy=".0010" iyz="0.0" izz=".0010"/>
    </inertial>
  </link>
  <link name="r2/left_index_yaw">
    <inertial>
      <mass value=".0010"/>
      <inertia ixx=".0010" ixy="0.0" ixz="0.0" iyy=".0010" iyz="0.0" izz=".0010"/>
    </inertial>
  </link>
  <joint name="r2/left_arm/hand/index/joint1" type="revolute">
    <parent link="r2/left_index_yaw"/>
    <child link="r2/left_index_proximal"/>
    <origin rpy=" 1.570796 0.0 0.0 " xyz=" 0.009652 0.0 0.0 "/>
    <axis xyz="0 0 1"/>
    <limit effort="10000000.0" lower="0.0" upper="1.57" velocity="10"/>
    <dynamics damping="0.1" friction="0.0"/>
  </joint>
  <link name="r2/left_index_proximal">
    <inertial>
      <mass value=".0010"/>
      <inertia ixx=".0010" ixy="0.0" ixz="0.0" iyy=".0010" iyz="0.0" izz=".0010"/>
    </inertial>
    <visual>
      <geometry>
        <mesh filename="package://r2_description/meshes/Finger_Proximal.dae"/>
      </geometry>
      <origin rpy="0 0 1.57" xyz="0.0 0.0 0.0"/>
    </visual>
    <collision>
      <geometry>
        <mesh filename="package://r2_description/meshes/Finger_Proximal.dae"/>
      </geometry>
      <origin rpy="0 0 1.57" xyz="0.0 0.0 0.0"/>
    </collision>
  </link>
  <joint name="r2/left_arm/hand/index/joint2" type="revolute">
    <parent link="r2/left_index_proximal"/>
    <child link="r2/left_index_medial"/>
    <origin rpy=" 0.0 -0.0 0.0 " xyz=" 0.04445 0.0 0.0 "/>
    <axis xyz="0 0 1"/>
    <limit effort="10000000.0" lower="0.0" upper="1.57" velocity="10"/>
    <dynamics damping="0.1" friction="0.0"/>
  </joint>
  <link name="r2/left_index_medial">
    <inertial>
      <mass value=".0010"/>
      <inertia ixx=".0010" ixy="0.0" ixz="0.0" iyy=".0010" iyz="0.0" izz=".0010"/>
    </inertial>
    <visual>
      <geometry>
        <mesh filename="package://r2_description/meshes/Finger_Mid.dae"/>
      </geometry>
      <origin rpy="3.14 0 1.57" xyz="0.0 0.0 0.0"/>
    </visual>
    <collision>
      <geometry>
        <mesh filename="package://r2_description/meshes/Finger_Mid.dae"/>
      </geometry>
      <origin rpy="3.14 0 1.57" xyz="0.0 0.0 0.0"/>
    </collision>
  </link>
  <joint name="r2/left_arm/hand/index/joint3" type="revolute">
    <parent link="r2/left_index_medial"/>
    <child link="r2/left_index_distal"/>
    <origin rpy=" 0.0 -0.0 0.0 " xyz=" 0.03048 0.0 0.0 "/>
    <axis xyz="0 0 1"/>
    <limit effort="10000000.0" lower="0.0" upper="1.57" velocity="10"/>
    <dynamics damping="0.1" friction="0.0"/>
  </joint>
  <link name="r2/left_index_distal">
    <inertial>
      <mass value=".0010"/>
      <inertia ixx=".0010" ixy="0.0" ixz="0.0" iyy=".0010" iyz="0.0" izz=".0010"/>
    </inertial>
    <visual>
      <geometry>
        <mesh filename="package://r2_description/meshes/Finger_Dist.dae"/>
      </geometry>
      <origin rpy="0 -1.57 0" xyz="0.0 0.0 0.0"/>
    </visual>
    <collision>
      <geometry>
        <mesh filename="package://r2_description/meshes/Finger_Dist.dae"/>
      </geometry>
      <origin rpy="0 -1.57 0" xyz="0.0 0.0 0.0"/>
    </collision>
  </link>
  <joint name="r2/fixed/left_index_distal/left_index_tip" type="fixed">
    <parent link="r2/left_index_distal"/>
    <child link="r2/left_index_tip"/>
    <origin rpy=" 0.0 -0.0 0.0 " xyz=" 0.024638 0.0 0.0 "/>
  </joint>
  <link name="r2/left_index_tip">
    <inertial>
      <mass value=".0010"/>
      <inertia ixx=".0010" ixy="0.0" ixz="0.0" iyy=".0010" iyz="0.0" izz=".0010"/>
    </inertial>
  </link>
  <link name="r2/left_middle_base">
    <inertial>
      <mass value=".0010"/>
      <inertia ixx=".0010" ixy="0.0" ixz="0.0" iyy=".0010" iyz="0.0" izz=".0010"/>
    </inertial>
  </link>
  <link name="r2/left_middle_yaw">
    <inertial>
      <mass value=".0010"/>
      <inertia ixx=".0010" ixy="0.0" ixz="0.0" iyy=".0010" iyz="0.0" izz=".0010"/>
    </inertial>
  </link>
  <joint name="r2/left_arm/hand/middle/joint1" type="revolute">
    <parent link="r2/left_middle_yaw"/>
    <child link="r2/left_middle_proximal"/>
    <origin rpy=" 1.570796 -0.0 0.0 " xyz=" 0.009652 0.0 0.0 "/>
    <axis xyz="0 0 1"/>
    <limit effort="10000000.0" lower="0.0" upper="1.57" velocity="10"/>
    <dynamics damping="0.1" friction="0.0"/>
  </joint>
  <link name="r2/left_middle_proximal">
    <inertial>
      <mass value=".0010"/>
      <inertia ixx=".0010" ixy="0.0" ixz="0.0" iyy=".0010" iyz="0.0" izz=".0010"/>
    </inertial>
    <visual>
      <geometry>
        <mesh filename="package://r2_description/meshes/Finger_Proximal.dae"/>
      </geometry>
      <origin rpy="0 0 1.57" xyz="0.0 0.0 0.0"/>
    </visual>
    <collision>
      <geometry>
        <mesh filename="package://r2_description/meshes/Finger_Proximal.dae"/>
      </geometry>
      <origin rpy="0 0 1.57" xyz="0.0 0.0 0.0"/>
    </collision>
  </link>
  <joint name="r2/left_arm/hand/middle/joint2" type="revolute">
    <parent link="r2/left_middle_proximal"/>
    <child link="r2/left_middle_medial"/>
    <origin rpy=" 0.0 -0.0 0.0 " xyz=" 0.04445 0.0 0.0 "/>
    <axis xyz="0 0 1"/>
    <limit effort="10000000.0" lower="0.0" upper="1.57" velocity="10"/>
    <dynamics damping="0.1" friction="0.0"/>
  </joint>
  <link name="r2/left_middle_medial">
    <inertial>
      <mass value=".0010"/>
      <inertia ixx=".0010" ixy="0.0" ixz="0.0" iyy=".0010" iyz="0.0" izz=".0010"/>
    </inertial>
    <visual>
      <geometry>
        <mesh filename="package://r2_description/meshes/Finger_Mid.dae"/>
      </geometry>
      <origin rpy="3.14 0 1.57" xyz="0.0 0.0 0.0"/>
    </visual>
    <collision>
      <geometry>
        <mesh filename="package://r2_description/meshes/Finger_Mid.dae"/>
      </geometry>
      <origin rpy="3.14 0 1.57" xyz="0.0 0.0 0.0"/>
    </collision>
  </link>
  <joint name="r2/left_arm/hand/middle/joint3" type="revolute">
    <parent link="r2/left_middle_medial"/>
    <child link="r2/left_middle_distal"/>
    <origin rpy=" 0.0 -0.0 0.0 " xyz=" 0.03048 0.0 0.0 "/>
    <axis xyz="0 0 1"/>
    <limit effort="10000000.0" lower="0.0" upper="1.57" velocity="10"/>
    <dynamics damping="0.1" friction="0.0"/>
  </joint>
  <link name="r2/left_middle_distal">
    <inertial>
      <mass value=".0010"/>
      <inertia ixx=".0010" ixy="0.0" ixz="0.0" iyy=".0010" iyz="0.0" izz=".0010"/>
    </inertial>
    <visual>
      <geometry>
        <mesh filename="package://r2_description/meshes/Finger_Dist.dae"/>
      </geometry>
      <origin rpy="0 -1.57 0" xyz="0.0 0.0 0.0"/>
    </visual>
    <collision>
      <geometry>
        <mesh filename="package://r2_description/meshes/Finger_Dist.dae"/>
      </geometry>
      <origin rpy="0 -1.57 0" xyz="0.0 0.0 0.0"/>
    </collision>
  </link>
  <joint name="r2/fixed/left_middle_distal/left_middle_tip" type="fixed">
    <parent link="r2/left_middle_distal"/>
    <child link="r2/left_middle_tip"/>
    <origin rpy=" 0.0 -0.0 0.0 " xyz=" 0.024638 0.0 0.0 "/>
  </joint>
  <link name="r2/left_middle_tip">
    <inertial>
      <mass value=".0010"/>
      <inertia ixx=".0010" ixy="0.0" ixz="0.0" iyy=".0010" iyz="0.0" izz=".0010"/>
    </inertial>
  </link>
  <link name="r2/left_ring_proximal">
    <inertial>
      <mass value=".0010"/>
      <inertia ixx=".0010" ixy="0.0" ixz="0.0" iyy=".0010" iyz="0.0" izz=".0010"/>
    </inertial>
    <visual>
      <geometry>
        <mesh filename="package://r2_description/meshes/Finger_Proximal.dae"/>
      </geometry>
      <origin rpy="0 0 1.57" xyz="0.0 0.0 0.0"/>
    </visual>
    <collision>
      <geometry>
        <mesh filename="package://r2_description/meshes/Finger_Proximal.dae"/>
      </geometry>
      <origin rpy="0 0 1.57" xyz="0.0 0.0 0.0"/>
    </collision>
  </link>
  <joint name="r2/left_arm/hand/ring/joint1" type="revolute">
    <parent link="r2/left_ring_proximal"/>
    <child link="r2/left_ring_medial"/>
    <origin rpy=" 0.0 -0.0 0.0 " xyz=" 0.04445 0.0 0.0 "/>
    <axis xyz="0 0 1"/>
    <limit effort="10000000.0" lower="0" upper="2.9671" velocity="10"/>
    <dynamics damping="0.1" friction="0.0"/>
  </joint>
  <link name="r2/left_ring_medial">
    <inertial>
      <mass value=".0010"/>
      <inertia ixx=".0010" ixy="0.0" ixz="0.0" iyy=".0010" iyz="0.0" izz=".0010"/>
    </inertial>
    <visual>
      <geometry>
        <mesh filename="package://r2_description/meshes/Finger_Mid.dae"/>
      </geometry>
      <origin rpy="3.14 0 1.57" xyz="0.0 0.0 0.0"/>
    </visual>
    <collision>
      <geometry>
        <mesh filename="package://r2_description/meshes/Finger_Mid.dae"/>
      </geometry>
      <origin rpy="3.14 0 1.57" xyz="0.0 0.0 0.0"/>
    </collision>
  </link>
  <joint name="r2/left_arm/hand/ring/joint2" type="revolute">
    <parent link="r2/left_ring_medial"/>
    <child link="r2/left_ring_distal"/>
    <origin rpy=" 0.0 -0.0 0.0 " xyz=" 0.03048 0.0 0.0 "/>
    <axis xyz="0 0 1"/>
    <limit effort="10000000.0" lower="0" upper="2.9671" velocity="10"/>
    <dynamics damping="0.1" friction="0.0"/>
  </joint>
  <link name="r2/left_ring_distal">
    <inertial>
      <mass value=".0010"/>
      <inertia ixx=".0010" ixy="0.0" ixz="0.0" iyy=".0010" iyz="0.0" izz=".0010"/>
    </inertial>
    <visual>
      <geometry>
        <mesh filename="package://r2_description/meshes/Finger_Dist.dae"/>
      </geometry>
      <origin rpy="0 -1.57 0" xyz="0.0 0.0 0.0"/>
    </visual>
    <collision>
      <geometry>
        <mesh filename="package://r2_description/meshes/Finger_Dist.dae"/>
      </geometry>
      <origin rpy="0 -1.57 0" xyz="0.0 0.0 0.0"/>
    </collision>
  </link>
  <joint name="r2/fixed/left_ring_distal/left_ring_tip" type="fixed">
    <parent link="r2/left_ring_distal"/>
    <child link="r2/left_ring_tip"/>
    <origin rpy=" 0.0 -0.0 0.0 " xyz=" 0.024638 0.0 0.0 "/>
  </joint>
  <link name="r2/left_ring_tip">
    <inertial>
      <mass value=".0010"/>
      <inertia ixx=".0010" ixy="0.0" ixz="0.0" iyy=".0010" iyz="0.0" izz=".0010"/>
    </inertial>
  </link>
  <link name="r2/left_little_proximal">
    <inertial>
      <mass value=".0010"/>
      <inertia ixx=".0010" ixy="0.0" ixz="0.0" iyy=".0010" iyz="0.0" izz=".0010"/>
    </inertial>
    <visual>
      <geometry>
        <mesh filename="package://r2_description/meshes/Finger_Proximal.dae"/>
      </geometry>
      <origin rpy="0 0 1.57" xyz="0.0 0.0 0.0"/>
    </visual>
    <collision>
      <geometry>
        <mesh filename="package://r2_description/meshes/Finger_Proximal.dae"/>
      </geometry>
      <origin rpy="0 0 1.57" xyz="0.0 0.0 0.0"/>
    </collision>
  </link>
  <joint name="r2/left_arm/hand/little/joint1" type="revolute">
    <parent link="r2/left_little_proximal"/>
    <child link="r2/left_little_medial"/>
    <origin rpy=" 0.0 -0.0 0.0 " xyz=" 0.04445 0.0 0.0 "/>
    <axis xyz="0 0 1"/>
    <limit effort="10000000.0" lower="0" upper="2.9671" velocity="10"/>
    <dynamics damping="0.1" friction="0.0"/>
  </joint>
  <link name="r2/left_little_medial">
    <inertial>
      <mass value=".0010"/>
      <inertia ixx=".0010" ixy="0.0" ixz="0.0" iyy=".0010" iyz="0.0" izz=".0010"/>
    </inertial>
    <visual>
      <geometry>
        <mesh filename="package://r2_description/meshes/Finger_Mid.dae"/>
      </geometry>
      <origin rpy="3.14 0 1.57" xyz="0.0 0.0 0.0"/>
    </visual>
    <collision>
      <geometry>
        <mesh filename="package://r2_description/meshes/Finger_Mid.dae"/>
      </geometry>
      <origin rpy="3.14 0 1.57" xyz="0.0 0.0 0.0"/>
    </collision>
  </link>
  <joint name="r2/left_arm/hand/little/joint2" type="revolute">
    <parent link="r2/left_little_medial"/>
    <child link="r2/left_little_distal"/>
    <origin rpy=" 0.0 -0.0 0.0 " xyz=" 0.03048 0.0 0.0 "/>
    <axis xyz="0 0 1"/>
    <limit effort="10000000.0" lower="0" upper="2.9671" velocity="10"/>
    <dynamics damping="0.1" friction="0.0"/>
  </joint>
  <link name="r2/left_little_distal">
    <inertial>
      <mass value=".0010"/>
      <inertia ixx=".0010" ixy="0.0" ixz="0.0" iyy=".0010" iyz="0.0" izz=".0010"/>
    </inertial>
    <visual>
      <geometry>
        <mesh filename="package://r2_description/meshes/Finger_Dist.dae"/>
      </geometry>
      <origin rpy="0 -1.57 0" xyz="0.0 0.0 0.0"/>
    </visual>
    <collision>
      <geometry>
        <mesh filename="package://r2_description/meshes/Finger_Dist.dae"/>
      </geometry>
      <origin rpy="0 -1.57 0" xyz="0.0 0.0 0.0"/>
    </collision>
  </link>
  <joint name="r2/fixed/left_little_distal/left_little_tip" type="fixed">
    <parent link="r2/left_little_distal"/>
    <child link="r2/left_little_tip"/>
    <origin rpy=" 0.0 -0.0 0.0 " xyz=" 0.024638 0.0 0.0 "/>
  </joint>
  <link name="r2/left_little_tip">
    <inertial>
      <mass value=".0010"/>
      <inertia ixx=".0010" ixy="0.0" ixz="0.0" iyy=".0010" iyz="0.0" izz=".0010"/>
    </inertial>
  </link>
  <joint name="r2/right_arm/joint0" type="revolute">
    <parent link="r2/chest_base"/>
    <child link="r2/right_shoulder_roll"/>
    <origin rpy=" -1.5596 -0.0 -0.26157" xyz=" 0.0 -0.0 0.0"/>
    <axis xyz="0 0 1"/>
    <dynamics damping="10.0" friction="0.0"/>
    <limit effort="100.0" lower="-1.57" upper="1.57" velocity="10"/>
  </joint>
  <link name="r2/right_shoulder_roll">
    <visual>
      <geometry>
        <mesh filename="package://r2_description/meshes/Right_Shoulder_Upper.dae"/>
      </geometry>
      <material name="dirty_white"/>
      <origin rpy="0 0 2.25" xyz="0 0 .0254"/>
    </visual>
    <!-- <collision>
      <geometry>
        <mesh filename="package://r2_description/meshes/Right_Shoulder_Upper.dae"/>
      </geometry>
      <origin rpy="0 0 2.35" xyz="0 0 .0254"/>
    </collision> -->
    <inertial>
      <origin xyz="0.0089916 -0.00131572  0.10287"/>
      <mass value="6.168856232"/>
      <inertia ixx="0.0198585269" ixy="0.0060195977" ixz="0.0003950635" iyy="0.0671900643" iyz="0.00012683" izz="0.0634150128"/>
    </inertial>
  </link>
  <joint name="r2/right_arm/joint1" type="revolute">
    <parent link="r2/right_shoulder_roll"/>
    <child link="r2/right_shoulder_pitch"/>
    <origin rpy=" 1.5637 -0.0 -1.570796" xyz=" 0.0 -0.0 0.320929"/>
    <axis xyz="0 0 1"/>
    <dynamics damping="10.0" friction="0.0"/>
    <limit effort="100.0" lower="-1.66" upper=".175" velocity="10"/>
  </joint>
  <link name="r2/right_shoulder_pitch">
    <visual>
      <geometry>
        <mesh filename="package://r2_description/meshes/Right_Shoulder_Lower.dae"/>
      </geometry>
      <material name="dirty_white"/>
      <origin rpy=".0 0 1.57" xyz="0 0 0"/>
    </visual>
    <!--   <collision>
      <geometry>
        <mesh filename="package://r2_description/meshes/Right_Shoulder_Lower.dae"/>
      </geometry>
      <origin rpy=".0 0 1.57" xyz="0 0 0"/>
    </collision> -->
    <inertial>
      <origin xyz="0.0077978 0.037084 0.00028448"/>
      <mass value="4.4270615312"/>
      <inertia ixx="0.0113836825" ixy="-.0000217138622526" ixz="-.001512947" iyy="0.0251962741" iyz="-0.000052382497887" izz="0.02701064"/>
    </inertial>
  </link>
  <joint name="r2/right_arm/joint2" type="revolute">
    <parent link="r2/right_shoulder_pitch"/>
    <child link="r2/right_upper_arm"/>
    <origin rpy=" -1.5679 -0.0 0.0" xyz=" 0.0 0.0 0.0"/>
    <axis xyz="0 0 1"/>
    <dynamics damping="10.0" friction="0.0"/>
    <limit effort="100.0" lower="0.785" upper="4.89" velocity="10"/>
  </joint>
  <link name="r2/right_upper_arm">
    <visual>
      <geometry>
        <mesh filename="package://r2_description/meshes/Right_Upper_Arm.dae"/>
      </geometry>
      <material name="dirty_white"/>
      <origin rpy="0 0 0" xyz="0 0 .1016"/>
    </visual>
    <collision>
      <geometry>
        <mesh filename="package://r2_description/meshes/Right_Upper_Arm.dae"/>
      </geometry>
      <origin rpy="0 0 0" xyz="0 0 .1016"/>
    </collision>
    <inertial>
      <origin xyz="0.041402  -0.0074168  0.1016"/>
      <mass value="4.853438359"/>
      <inertia ixx="0.04214011" ixy="-0.0013754064" ixz="-0.0065843922" iyy="0.0462370652" iyz="-0.00339462" izz="0.016007389"/>
    </inertial>
  </link>
  <joint name="r2/right_arm/joint3" type="revolute">
    <parent link="r2/right_upper_arm"/>
    <child link="r2/right_elbow"/>
    <origin rpy=" 1.5684 -0.0 0.0" xyz=" 0.0536067 0.0 0.355219"/>
    <axis xyz="0 0 1"/>
    <dynamics damping="1.0" friction="0.0"/>
    <limit effort="100.0" lower="-2.79" upper="-.087" velocity="10"/>
  </joint>
  <link name="r2/right_elbow">
    <visual>
      <geometry>
        <mesh filename="package://r2_description/meshes/Right_Elbow.dae"/>
      </geometry>
      <material name="dirty_white"/>
      <origin rpy="0 0 1.57" xyz="0 0 0"/>
    </visual>
    <collision>
      <geometry>
        <mesh filename="package://r2_description/meshes/Right_Elbow.dae"/>
      </geometry>
      <origin rpy="0 0 1.57" xyz="0 0 0"/>
    </collision>
    <inertial>
      <origin xyz=" -0.026162  0.033782 0.0154432"/>
      <mass value="2.9710300235"/>
      <inertia ixx="0.0120274897" ixy="-0.001188117" ixz="0.0016417085" iyy="0.0088377175" iyz="-0.0031605083" izz="0.0105350275"/>
    </inertial>
  </link>
  <joint name="r2/right_arm/joint4" type="revolute">
    <parent link="r2/right_elbow"/>
    <child link="r2/right_lower_arm"/>
    <origin rpy=" -1.5656 -0.0 0.0" xyz=" -0.0537464 -0.0 0.0"/>
    <axis xyz="0 0 1"/>
    <dynamics damping="1.0" friction="0.0"/>
    <limit effort="100.0" lower="-4.45" upper="1.31" velocity="10"/>
  </joint>
  <link name="r2/right_lower_arm">
    <visual>
      <geometry>
        <mesh filename="package://r2_description/meshes/Right_Forearm.dae"/>
      </geometry>
      <material name="dirty_white"/>
      <origin xyz="0 0 0.1"/>
    </visual>
    <collision>
      <geometry>
        <mesh filename="package://r2_description/meshes/Right_Forearm.dae"/>
      </geometry>
      <origin xyz="0 0 0.1"/>
    </collision>
    <inertial>
      <origin xyz="0.0003556 -0.00122682 0.17653"/>
      <mass value="6.939963261"/>
      <inertia ixx="0.0125249771" ixy="0.0002446467" ixz="0.0005208986" iyy="0.0395063532" iyz="0.0001691457" izz="0.0403842721"/>
    </inertial>
  </link>
  <joint name="r2/right_arm/joint5" type="revolute">
    <parent link="r2/right_lower_arm"/>
    <child link="r2/right_wrist_pitch"/>
    <origin rpy=" 1.5329 -0.0 0.0" xyz=" 0.0 0.0 0.3569462"/>
    <axis xyz="0 0 1"/>
    <dynamics damping="1.0" friction="0.0"/>
    <limit effort="100.0" lower="-1.22" upper="1.22" velocity="10"/>
  </joint>
  <link name="r2/right_wrist_pitch">
    <inertial>
      <origin xyz="0.00092202 -0.004064 0.000000152908"/>
      <mass value="0.1165732391"/>
      <inertia ixx="0.1" ixy="0.0" ixz="0.0" iyy="0.1" iyz="0.0" izz="0.1"/>
    </inertial>
  </link>
  <joint name="r2/right_arm/joint6" type="revolute">
    <parent link="r2/right_wrist_pitch"/>
    <child link="r2/right_wrist_yaw"/>
    <origin rpy=" 1.5612 -0.0 1.5923" xyz=" -0.000139607 0.006491247 0.0"/>
    <axis xyz="0 0 1"/>
    <dynamics damping="1.0" friction="0.0"/>
    <limit effort="100.0" lower="-0.785" upper="0.785" velocity="10"/>
  </joint>
  <link name="r2/right_wrist_yaw">
    <inertial>
      <origin xyz="0.067564 0.00090932 0.0253746"/>
      <mass value="0.1"/>
      <inertia ixx="0.1" ixy="0.0" ixz="0.0" iyy="0.1" iyz="0.0" izz="0.1"/>
    </inertial>
  </link>
  <joint name="r2/fixed/right_wrist_yaw/right_palm" type="fixed">
    <parent link="r2/right_wrist_yaw"/>
    <child link="r2/right_palm"/>
    <origin rpy=" 0.0 -0.0 0.0299" xyz=" 0.0 0.0 0.0"/>
  </joint>
  <link name="r2/right_palm">
    <visual>
      <geometry>
        <mesh filename="package://r2_description/meshes/Right_Palm.dae"/>
      </geometry>
      <origin rpy="3.14 0 1.57" xyz="0.0 0.0 -0.0"/>
    </visual>
    <collision>
      <geometry>
        <mesh filename="package://r2_description/meshes/Right_Palm.dae"/>
      </geometry>
      <origin rpy="3.14 0 1.57" xyz="0.0 0.0 -0.0"/>
    </collision>
    <inertial>
      <mass value="1.1"/>
      <inertia ixx="0.1" ixy="0.0" ixz="0.0" iyy="0.1" iyz="0.0" izz="0.1"/>
    </inertial>
  </link>
  <joint name="r2/right_arm/hand/thumb/joint0" type="revolute">
    <parent link="r2/right_wrist_yaw"/>
    <child link="r2/right_thumb_base"/>
    <origin rpy=" 1.57079632679 0.174532791018 -1.30899687745 " xyz="0.03302 -0.03048 0.00635 "/>
    <axis xyz="0 0 1"/>
    <limit effort="10000000.0" lower="0.0" upper="1.2217" velocity="10"/>
    <dynamics damping="0.1" friction="0.0"/>
  </joint>
  <joint name="r2/fixed/right_index_base/right_index_base" type="fixed">
    <parent link="r2/right_wrist_yaw"/>
    <child link="r2/right_index_base"/>
    <origin rpy=" 0.0 -0.0 -0.122172725275  " xyz=" 0.0994646728 -0.0271119346 -0.0161544 "/>
  </joint>
  <joint name="r2/right_arm/hand/index/joint0" type="revolute">
    <parent link="r2/right_index_base"/>
    <child link="r2/right_index_yaw"/>
    <origin rpy="0.0 0.0 0.0" xyz="0.0 0.0 0.0"/>
    <axis xyz="0 0 1"/>
    <limit effort="10000000.0" lower="-0.3491" upper="0.3491" velocity="10"/>
    <dynamics damping="0.1" friction="0.0"/>
  </joint>
  <joint name="r2/fixed/right_middle_base/right_middle_base" type="fixed">
    <parent link="r2/right_wrist_yaw"/>
    <child link="r2/right_middle_base"/>
    <origin rpy=" 0.0 -0.0 0.0 " xyz="0.10646537 -0.00254 -0.0161544 "/>
  </joint>
  <joint name="r2/right_arm/hand/middle/joint0" type="revolute">
    <parent link="r2/right_middle_base"/>
    <child link="r2/right_middle_yaw"/>
    <origin rpy="0.0 0.0 0.0" xyz="0.0 0.0 0.0"/>
    <axis xyz="0 0 1"/>
    <limit effort="10000000.0" lower="-0.3491" upper="0.3491" velocity="10"/>
    <dynamics damping="0.1" friction="0.0"/>
  </joint>
  <joint name="r2/right_arm/hand/ring/joint0" type="revolute">
    <parent link="r2/right_wrist_yaw"/>
    <child link="r2/right_ring_proximal"/>
    <origin rpy=" 1.57079632679 -0.0 0.122172725275  " xyz=" 0.1084539614 0.019792569 -0.012319 "/>
    <axis xyz="0 0 1"/>
    <limit effort="10000000.0" lower="0" upper="2.9671" velocity="10"/>
    <dynamics damping="0.1" friction="0.0"/>
  </joint>
  <joint name="r2/right_arm/hand/little/joint0" type="revolute">
    <parent link="r2/right_wrist_yaw"/>
    <child link="r2/right_little_proximal"/>
    <origin rpy=" 1.53588943985 -0.0872667473393 0.17453258148  " xyz=" 0.094635701 0.0403792436 -0.0060878212 "/>
    <axis xyz="0 0 1"/>
    <limit effort="10000000.0" lower="0" upper="2.9671" velocity="10"/>
    <dynamics damping="0.1" friction="0.0"/>
  </joint>
  <link name="r2/right_thumb_base">
    <inertial>
      <mass value=".05"/>
      <inertia ixx=".0010" ixy="0.0" ixz="0.0" iyy=".0010" iyz="0.0" izz=".0010"/>
    </inertial>
  </link>
  <joint name="r2/fixed/right_thumb_base/right_thumb_proximal" type="fixed">
    <parent link="r2/right_thumb_base"/>
    <child link="r2/right_thumb_proximal"/>
    <origin rpy=" -1.570796 -0.0 0.0 " xyz=" 0.011938 0.0 0.0 "/>
  </joint>
  <link name="r2/right_thumb_proximal">
    <inertial>
      <mass value=".05"/>
      <inertia ixx=".0010" ixy="0.0" ixz="0.0" iyy=".0010" iyz="0.0" izz=".0010"/>
    </inertial>
    <visual>
      <geometry>
        <mesh filename="package://r2_description/meshes/Left_Thumb_Carp.dae"/>
      </geometry>
      <origin rpy="-1.57 0 0" xyz="-0.01 0.0 0.0"/>
    </visual>
    <collision>
      <geometry>
        <mesh filename="package://r2_description/meshes/Left_Thumb_Carp.dae" scale="0.9 0.9 0.9"/>
      </geometry>
      <origin rpy="-1.57 0 0" xyz="-0.01 0.0 0.0"/>
    </collision>
  </link>
  <joint name="r2/right_arm/hand/thumb/joint1" type="revolute">
    <parent link="r2/right_thumb_proximal"/>
    <child link="r2/right_thumb_medial_prime"/>
    <origin rpy=" 0.0 -0.0 0.0 " xyz=" 0.0 0.0 0.0 "/>
    <axis xyz="0 0 1"/>
    <limit effort="10000000.0" lower="0.0" upper="1.3963" velocity="10"/>
    <dynamics damping="0.1" friction="0.0"/>
  </joint>
  <link name="r2/right_thumb_medial_prime">
    <inertial>
      <mass value=".05"/>
      <inertia ixx=".0010" ixy="0.0" ixz="0.0" iyy=".0010" iyz="0.0" izz=".0010"/>
    </inertial>
    <visual>
      <geometry>
        <mesh filename="package://r2_description/meshes/Right_Thumb_MtCar.dae"/>
      </geometry>
      <origin rpy="-1.57 -1.57 0 " xyz="-0.0 0 0.0"/>
    </visual>
    <collision>
      <geometry>
        <mesh filename="package://r2_description/meshes/Right_Thumb_MtCar.dae" scale="0.9 0.9 0.9"/>
      </geometry>
      <origin rpy="-1.57 -1.57 0 " xyz="-0.0 0 0.0"/>
    </collision>
  </link>
  <joint name="r2/right_arm/hand/thumb/joint2" type="revolute">
    <parent link="r2/right_thumb_medial_prime"/>
    <child link="r2/right_thumb_medial"/>
    <origin rpy=" 0.698132284627 -0.0 0.0 " xyz=" 0.030734 -0.001905 -0.00254 "/>
    <axis xyz="0 0 1"/>
    <limit effort="10000000.0" lower="0.0" upper="1.2217" velocity="10"/>
    <dynamics damping="0.1" friction="0.0"/>
  </joint>
  <link name="r2/right_thumb_medial">
    <inertial>
      <mass value=".05"/>
      <inertia ixx=".0010" ixy="0.0" ixz="0.0" iyy=".0010" iyz="0.0" izz=".0010"/>
    </inertial>
    <visual>
      <geometry>
        <mesh filename="package://r2_description/meshes/Thumb_Proximal.dae"/>
      </geometry>
      <origin rpy="3.14 0 1.57" xyz="0.0 0.0 0.0"/>
    </visual>
    <collision>
      <geometry>
        <mesh filename="package://r2_description/meshes/Thumb_Proximal.dae"/>
      </geometry>
      <origin rpy="3.14 0 1.57" xyz="0.0 0.0 0.0"/>
    </collision>
  </link>
  <joint name="r2/right_arm/hand/thumb/joint3" type="revolute">
    <parent link="r2/right_thumb_medial"/>
    <child link="r2/right_thumb_distal"/>
    <origin rpy=" 0.0 -0.0 0.0 " xyz=" 0.03937 0.0 0.0 "/>
    <axis xyz="0 0 1"/>
    <limit effort="10000000.0" lower="-0.5236" upper="1.57" velocity="10"/>
    <dynamics damping="0.1" friction="0.0"/>
  </joint>
  <link name="r2/right_thumb_distal">
    <inertial>
      <mass value=".05"/>
      <inertia ixx=".0010" ixy="0.0" ixz="0.0" iyy=".0010" iyz="0.0" izz=".0010"/>
    </inertial>
    <visual>
      <geometry>
        <mesh filename="package://r2_description/meshes/Thumb_Dist.dae"/>
      </geometry>
      <origin rpy="3.14 3.14 0" xyz="0.0 0.0 0.0"/>
    </visual>
    <collision>
      <geometry>
        <mesh filename="package://r2_description/meshes/Thumb_Dist.dae"/>
      </geometry>
      <origin rpy="3.14 3.14 0" xyz="0.0 0.0 0.0"/>
    </collision>
  </link>
  <joint name="r2/fixed/right_thumb_distal/right_thumb_tip" type="fixed">
    <parent link="r2/right_thumb_distal"/>
    <child link="r2/right_thumb_tip"/>
    <origin rpy=" 0.0 -0.0 0.0 " xyz=" 0.03302 0.0 0.0 "/>
  </joint>
  <link name="r2/right_thumb_tip">
    <inertial>
      <mass value=".05"/>
      <inertia ixx=".0010" ixy="0.0" ixz="0.0" iyy=".0010" iyz="0.0" izz=".0010"/>
    </inertial>
  </link>
  <link name="r2/right_index_base">
    <inertial>
      <mass value=".05"/>
      <inertia ixx=".0010" ixy="0.0" ixz="0.0" iyy=".0010" iyz="0.0" izz=".0010"/>
    </inertial>
  </link>
  <link name="r2/right_index_yaw">
    <inertial>
      <mass value=".05"/>
      <inertia ixx=".0010" ixy="0.0" ixz="0.0" iyy=".0010" iyz="0.0" izz=".0010"/>
    </inertial>
  </link>
  <joint name="r2/right_arm/hand/index/joint1" type="revolute">
    <parent link="r2/right_index_yaw"/>
    <child link="r2/right_index_proximal"/>
    <origin rpy=" 1.570796 -0.0 0.0 " xyz=" 0.009652 0.0 0.0 "/>
    <axis xyz="0 0 1"/>
    <limit effort="10000000.0" lower="0.0" upper="1.57" velocity="10"/>
    <dynamics damping="0.1" friction="0.0"/>
  </joint>
  <link name="r2/right_index_proximal">
    <inertial>
      <mass value=".05"/>
      <inertia ixx=".0010" ixy="0.0" ixz="0.0" iyy=".0010" iyz="0.0" izz=".0010"/>
    </inertial>
    <visual>
      <geometry>
        <mesh filename="package://r2_description/meshes/Finger_Proximal.dae"/>
      </geometry>
      <origin rpy="0 0 1.57" xyz="0.0 0.0 0.0"/>
    </visual>
    <collision>
      <geometry>
        <mesh filename="package://r2_description/meshes/Finger_Proximal.dae"/>
      </geometry>
      <origin rpy="0 0 1.57" xyz="0.0 0.0 0.0"/>
    </collision>
  </link>
  <joint name="r2/right_arm/hand/index/joint2" type="revolute">
    <parent link="r2/right_index_proximal"/>
    <child link="r2/right_index_medial"/>
    <origin rpy=" 0.0 -0.0 0.0 " xyz=" 0.04445 0.0 0.0 "/>
    <axis xyz="0 0 1"/>
    <limit effort="10000000.0" lower="0.0" upper="1.57" velocity="10"/>
    <dynamics damping="0.1" friction="0.0"/>
  </joint>
  <link name="r2/right_index_medial">
    <inertial>
      <mass value=".05"/>
      <inertia ixx=".0010" ixy="0.0" ixz="0.0" iyy=".0010" iyz="0.0" izz=".0010"/>
    </inertial>
    <visual>
      <geometry>
        <mesh filename="package://r2_description/meshes/Finger_Mid.dae"/>
      </geometry>
      <origin rpy="3.14 0 1.57" xyz="0.0 0.0 0.0"/>
    </visual>
    <collision>
      <geometry>
        <mesh filename="package://r2_description/meshes/Finger_Mid.dae"/>
      </geometry>
      <origin rpy="3.14 0 1.57" xyz="0.0 0.0 0.0"/>
    </collision>
  </link>
  <joint name="r2/right_arm/hand/index/joint3" type="revolute">
    <parent link="r2/right_index_medial"/>
    <child link="r2/right_index_distal"/>
    <origin rpy=" 0.0 -0.0 0.0 " xyz=" 0.03048 0.0 0.0 "/>
    <axis xyz="0 0 1"/>
    <limit effort="10000000.0" lower="0.0" upper="1.57" velocity="10"/>
    <dynamics damping="0.1" friction="0.0"/>
  </joint>
  <link name="r2/right_index_distal">
    <inertial>
      <mass value=".05"/>
      <inertia ixx=".0010" ixy="0.0" ixz="0.0" iyy=".0010" iyz="0.0" izz=".0010"/>
    </inertial>
    <visual>
      <geometry>
        <mesh filename="package://r2_description/meshes/Finger_Dist.dae"/>
      </geometry>
      <origin rpy="0 -1.57 0" xyz="0.0 0.0 0.0"/>
    </visual>
    <collision>
      <geometry>
        <mesh filename="package://r2_description/meshes/Finger_Dist.dae"/>
      </geometry>
      <origin rpy="0 -1.57 0" xyz="0.0 0.0 0.0"/>
    </collision>
  </link>
  <joint name="r2/fixed/right_index_distal/right_index_tip" type="fixed">
    <parent link="r2/right_index_distal"/>
    <child link="r2/right_index_tip"/>
    <origin rpy=" 0.0 -0.0 0.0 " xyz=" 0.024638 0.0 0.0 "/>
  </joint>
  <link name="r2/right_index_tip">
    <inertial>
      <mass value=".05"/>
      <inertia ixx=".0010" ixy="0.0" ixz="0.0" iyy=".0010" iyz="0.0" izz=".0010"/>
    </inertial>
  </link>
  <link name="r2/right_middle_base">
    <inertial>
      <mass value=".0010"/>
      <inertia ixx=".0010" ixy="0.0" ixz="0.0" iyy=".0010" iyz="0.0" izz=".0010"/>
    </inertial>
  </link>
  <link name="r2/right_middle_yaw">
    <inertial>
      <mass value=".0010"/>
      <inertia ixx=".0010" ixy="0.0" ixz="0.0" iyy=".0010" iyz="0.0" izz=".0010"/>
    </inertial>
  </link>
  <joint name="r2/right_arm/hand/middle/joint1" type="revolute">
    <parent link="r2/right_middle_yaw"/>
    <child link="r2/right_middle_proximal"/>
    <origin rpy=" 1.570796 -0.0 0.0 " xyz=" 0.009652 0.0 0.0 "/>
    <axis xyz="0 0 1"/>
    <limit effort="10000000.0" lower="0.0" upper="1.57" velocity="10"/>
    <dynamics damping="0.1" friction="0.0"/>
  </joint>
  <link name="r2/right_middle_proximal">
    <inertial>
      <mass value=".05"/>
      <inertia ixx=".0010" ixy="0.0" ixz="0.0" iyy=".0010" iyz="0.0" izz=".0010"/>
    </inertial>
    <visual>
      <geometry>
        <mesh filename="package://r2_description/meshes/Finger_Proximal.dae"/>
      </geometry>
      <origin rpy="0 0 1.57" xyz="0.0 0.0 0.0"/>
    </visual>
    <collision>
      <geometry>
        <mesh filename="package://r2_description/meshes/Finger_Proximal.dae" scale="0.9 0.9 0.9"/>
      </geometry>
      <origin rpy="0 0 1.57" xyz="0.0 0.0 0.0"/>
    </collision>
  </link>
  <joint name="r2/right_arm/hand/middle/joint2" type="revolute">
    <parent link="r2/right_middle_proximal"/>
    <child link="r2/right_middle_medial"/>
    <origin rpy=" 0.0 -0.0 0.0 " xyz=" 0.04445 0.0 0.0 "/>
    <axis xyz="0 0 1"/>
    <limit effort="10000000.0" lower="0.0" upper="1.57" velocity="10"/>
    <dynamics damping="0.1" friction="0.0"/>
  </joint>
  <link name="r2/right_middle_medial">
    <inertial>
      <mass value=".05"/>
      <inertia ixx=".0010" ixy="0.0" ixz="0.0" iyy=".0010" iyz="0.0" izz=".0010"/>
    </inertial>
    <visual>
      <geometry>
        <mesh filename="package://r2_description/meshes/Finger_Mid.dae"/>
      </geometry>
      <origin rpy="3.14 0 1.57" xyz="0.0 0.0 0.0"/>
    </visual>
    <collision>
      <geometry>
        <mesh filename="package://r2_description/meshes/Finger_Mid.dae" scale="0.9 0.9 0.9"/>
      </geometry>
      <origin rpy="3.14 0 1.57" xyz="0.0 0.0 0.0"/>
    </collision>
  </link>
  <joint name="r2/right_arm/hand/middle/joint3" type="revolute">
    <parent link="r2/right_middle_medial"/>
    <child link="r2/right_middle_distal"/>
    <origin rpy=" 0.0 -0.0 0.0 " xyz=" 0.03048 0.0 0.0 "/>
    <axis xyz="0 0 1"/>
    <limit effort="10000000.0" lower="0.0" upper="1.57" velocity="10"/>
    <dynamics damping="0.1" friction="0.0"/>
  </joint>
  <link name="r2/right_middle_distal">
    <inertial>
      <mass value=".05"/>
      <inertia ixx=".0010" ixy="0.0" ixz="0.0" iyy=".0010" iyz="0.0" izz=".0010"/>
    </inertial>
    <visual>
      <geometry>
        <mesh filename="package://r2_description/meshes/Finger_Dist.dae"/>
      </geometry>
      <origin rpy="0 -1.57 0" xyz="0.0 0.0 0.0"/>
    </visual>
    <collision>
      <geometry>
        <mesh filename="package://r2_description/meshes/Finger_Dist.dae" scale="0.9 0.9 0.9"/>
      </geometry>
      <origin rpy="0 -1.57 0" xyz="0.0 0.0 0.0"/>
    </collision>
  </link>
  <joint name="r2/fixed/right_middle_distal/right_middle_tip" type="fixed">
    <parent link="r2/right_middle_distal"/>
    <child link="r2/right_middle_tip"/>
    <origin rpy=" 0.0 -0.0 0.0 " xyz=" 0.024638 0.0 0.0 "/>
  </joint>
  <link name="r2/right_middle_tip">
    <inertial>
      <mass value=".05"/>
      <inertia ixx=".0010" ixy="0.0" ixz="0.0" iyy=".0010" iyz="0.0" izz=".0010"/>
    </inertial>
  </link>
  <link name="r2/right_ring_proximal">
    <inertial>
      <mass value=".05"/>
      <inertia ixx=".0010" ixy="0.0" ixz="0.0" iyy=".0010" iyz="0.0" izz=".0010"/>
    </inertial>
    <visual>
      <geometry>
        <mesh filename="package://r2_description/meshes/Finger_Proximal.dae"/>
      </geometry>
      <origin rpy="0 0 1.57" xyz="0.0 0.0 0.0"/>
    </visual>
    <collision>
      <geometry>
        <mesh filename="package://r2_description/meshes/Finger_Proximal.dae" scale="0.9 0.9 0.9"/>
      </geometry>
      <origin rpy="0 0 1.57" xyz="0.0 0.0 0.0"/>
    </collision>
  </link>
  <joint name="r2/right_arm/hand/ring/joint1" type="revolute">
    <parent link="r2/right_ring_proximal"/>
    <child link="r2/right_ring_medial"/>
    <origin rpy=" 0.0 -0.0 0.0 " xyz=" 0.04445 0.0 0.0 "/>
    <axis xyz="0 0 1"/>
    <limit effort="10000000.0" lower="0" upper="2.9671" velocity="10"/>
    <dynamics damping="0.1" friction="0.0"/>
  </joint>
  <link name="r2/right_ring_medial">
    <inertial>
      <mass value=".05"/>
      <inertia ixx=".0010" ixy="0.0" ixz="0.0" iyy=".0010" iyz="0.0" izz=".0010"/>
    </inertial>
    <visual>
      <geometry>
        <mesh filename="package://r2_description/meshes/Finger_Mid.dae"/>
      </geometry>
      <origin rpy="3.14 0 1.57" xyz="0.0 0.0 0.0"/>
    </visual>
    <collision>
      <geometry>
        <mesh filename="package://r2_description/meshes/Finger_Mid.dae" scale="0.9 0.9 0.9"/>
      </geometry>
      <origin rpy="3.14 0 1.57" xyz="0.0 0.0 0.0"/>
    </collision>
  </link>
  <joint name="r2/right_arm/hand/ring/joint2" type="revolute">
    <parent link="r2/right_ring_medial"/>
    <child link="r2/right_ring_distal"/>
    <origin rpy=" 0.0 -0.0 0.0 " xyz=" 0.03048 0.0 0.0 "/>
    <axis xyz="0 0 1"/>
    <limit effort="10000000.0" lower="0" upper="2.9671" velocity="10"/>
    <dynamics damping="0.1" friction="0.0"/>
  </joint>
  <link name="r2/right_ring_distal">
    <inertial>
      <mass value=".05"/>
      <inertia ixx=".0010" ixy="0.0" ixz="0.0" iyy=".0010" iyz="0.0" izz=".0010"/>
    </inertial>
    <visual>
      <geometry>
        <mesh filename="package://r2_description/meshes/Finger_Dist.dae"/>
      </geometry>
      <origin rpy="0 -1.57 0" xyz="0.0 0.0 0.0"/>
    </visual>
    <collision>
      <geometry>
        <mesh filename="package://r2_description/meshes/Finger_Dist.dae" scale="0.9 0.9 0.9"/>
      </geometry>
      <origin rpy="0 -1.57 0" xyz="0.0 0.0 0.0"/>
    </collision>
  </link>
  <joint name="r2/fixed/right_ring_distal/right_ring_tip" type="fixed">
    <parent link="r2/right_ring_distal"/>
    <child link="r2/right_ring_tip"/>
    <origin rpy=" 0.0 -0.0 0.0 " xyz=" 0.024638 0.0 0.0 "/>
  </joint>
  <link name="r2/right_ring_tip">
    <inertial>
      <mass value=".05"/>
      <inertia ixx=".0010" ixy="0.0" ixz="0.0" iyy=".0010" iyz="0.0" izz=".0010"/>
    </inertial>
  </link>
  <link name="r2/right_little_proximal">
    <inertial>
      <mass value=".05"/>
      <inertia ixx=".0010" ixy="0.0" ixz="0.0" iyy=".0010" iyz="0.0" izz=".0010"/>
    </inertial>
    <visual>
      <geometry>
        <mesh filename="package://r2_description/meshes/Finger_Proximal.dae"/>
      </geometry>
      <origin rpy="0 0 1.57" xyz="0.0 0.0 0.0"/>
    </visual>
    <collision>
      <geometry>
        <mesh filename="package://r2_description/meshes/Finger_Proximal.dae" scale="0.9 0.9 0.9"/>
      </geometry>
      <origin rpy="0 0 1.57" xyz="0.0 0.0 0.0"/>
    </collision>
  </link>
  <joint name="r2/right_arm/hand/little/joint1" type="revolute">
    <parent link="r2/right_little_proximal"/>
    <child link="r2/right_little_medial"/>
    <origin rpy=" 0.0 -0.0 0.0 " xyz=" 0.04445 0.0 0.0 "/>
    <axis xyz="0 0 1"/>
    <limit effort="10000000.0" lower="0" upper="2.9671" velocity="10"/>
    <dynamics damping="0.1" friction="0.0"/>
  </joint>
  <link name="r2/right_little_medial">
    <inertial>
      <mass value=".05"/>
      <inertia ixx=".0010" ixy="0.0" ixz="0.0" iyy=".0010" iyz="0.0" izz=".0010"/>
    </inertial>
    <visual>
      <geometry>
        <mesh filename="package://r2_description/meshes/Finger_Mid.dae"/>
      </geometry>
      <origin rpy="3.14 0 1.57" xyz="0.0 0.0 0.0"/>
    </visual>
    <collision>
      <geometry>
        <mesh filename="package://r2_description/meshes/Finger_Mid.dae" scale="0.9 0.9 0.9"/>
      </geometry>
      <origin rpy="3.14 0 1.57" xyz="0.0 0.0 0.0"/>
    </collision>
  </link>
  <joint name="r2/right_arm/hand/little/joint2" type="revolute">
    <parent link="r2/right_little_medial"/>
    <child link="r2/right_little_distal"/>
    <origin rpy=" 0.0 -0.0 0.0 " xyz=" 0.03048 0.0 0.0 "/>
    <axis xyz="0 0 1"/>
    <limit effort="10000000.0" lower="0" upper="2.9671" velocity="10"/>
    <dynamics damping="0.1" friction="0.0"/>
  </joint>
  <link name="r2/right_little_distal">
    <inertial>
      <mass value=".05"/>
      <inertia ixx=".0010" ixy="0.0" ixz="0.0" iyy=".0010" iyz="0.0" izz=".0010"/>
    </inertial>
    <visual>
      <geometry>
        <mesh filename="package://r2_description/meshes/Finger_Dist.dae"/>
      </geometry>
      <origin rpy="0 -1.57 0" xyz="0.0 0.0 0.0"/>
    </visual>
    <collision>
      <geometry>
        <mesh filename="package://r2_description/meshes/Finger_Dist.dae" scale="0.9 0.9 0.9"/>
      </geometry>
      <origin rpy="0 -1.57 0" xyz="0.0 0.0 0.0"/>
    </collision>
  </link>
  <joint name="r2/fixed/right_little_distal/right_little_tip" type="fixed">
    <parent link="r2/right_little_distal"/>
    <child link="r2/right_little_tip"/>
    <origin rpy=" 0.0 -0.0 0.0 " xyz=" 0.024638 0.0 0.0 "/>
  </joint>
  <link name="r2/right_little_tip">
    <inertial>
      <mass value=".05"/>
      <inertia ixx=".0010" ixy="0.0" ixz="0.0" iyy=".0010" iyz="0.0" izz=".0010"/>
    </inertial>
  </link>
  <link name="r2/pelvis">
    <inertial>
      <mass value="13.16272"/>
      <inertia ixx="0.11949" ixy="-0.00024" ixz="0.00000" iyy="0.07163" iyz="0.00000" izz="0.11047"/>
    </inertial>
    <visual>
      <geometry>
        <mesh filename="package://r2_description/meshes/r2_legs/r2cl_ext_pelvis.dae"/>
      </geometry>
      <material name="gold"/>
      <origin rpy="0 0 0" xyz="0 0 0"/>
    </visual>
    <collision>
      <geometry>
        <mesh filename="package://r2_description/meshes/r2_legs/r2cl_ext_pelvis.dae"/>
      </geometry>
      <origin rpy="0 0 0" xyz="0 0 0"/>
    </collision>
  </link>
  <joint name="r2/fixed/leg_stand_connection/pelvis" type="fixed">
    <parent link="r2/leg_stand_connection"/>
    <child link="r2/pelvis"/>
    <origin rpy="0 0 0" xyz="0 0 -0.098"/>
  </joint>
  <joint name="r2/fixed/pelvis/left_leg_base" type="fixed">
    <parent link="r2/pelvis"/>
    <child link="r2/left_leg_base"/>
    <origin rpy="0 0.000000 1.570796" xyz="0.0 0 0.0"/>
  </joint>
  <link name="r2/left_leg_base">
    <inertial>
      <mass value="3.2"/>
      <inertia ixx="1.0" ixy="0.0" ixz="0.0" iyy="1.0" iyz="0.0" izz="1.0"/>
    </inertial>
    <visual>
      <geometry>
        <cylinder length=".11" radius=".05"/>
      </geometry>
      <origin rpy="0 -1.82 0" xyz="-0.055 0.0 -.015 "/>
    </visual>
    <collision>
      <geometry>
        <cylinder length=".11" radius=".05"/>
      </geometry>
      <origin rpy="0 -1.82 0" xyz="-0.055 0.0 -.015 "/>
    </collision>
  </link>
  <joint name="r2/fixed/left_leg_base/left_leg_j0_base" type="fixed">
    <parent link="r2/left_leg_base"/>
    <child link="r2/left_leg_j0_base"/>
    <origin rpy="0.0 1.8325957 3.14159" xyz="-0.1104900 0.0 -0.0297180"/>
  </joint>
  <link name="r2/left_leg_j0_base">
    <inertial>
      <mass value="0.01"/>
      <inertia ixx="0.0001" ixy="0.0" ixz="0.0" iyy="0.001" iyz="0.0" izz="0.001"/>
    </inertial>
  </link>
  <joint name="r2/left_leg/joint0" type="revolute">
    <parent link="r2/left_leg_j0_base"/>
    <child link="r2/left_hip_roll"/>
    <origin rpy="0.0 0 0" xyz="0 0 0"/>
    <axis xyz="0 0 1"/>
    <dynamics damping="10.0" friction="0.0"/>
    <limit effort="330.0" lower="-4.71239" upper="4.71239" velocity="1.0"/>
  </joint>
  <link name="r2/left_hip_roll">
    <inertial>
      <mass value="2.33931"/>
      <inertia ixx="0.1" ixy="0.00" ixz="0.0" iyy="0.1" iyz="0.0" izz="0.1"/>
    </inertial>
    <visual>
      <geometry>
        <mesh filename="package://r2_description/meshes/r2_legs/r2cl_ext_bone3.dae"/>
      </geometry>
      <origin rpy="0 0 0" xyz="0.0 0.0 0.0"/>
    </visual>
    <collision>
      <geometry>
        <mesh filename="package://r2_description/meshes/r2_legs/r2cl_ext_bone3.dae"/>
      </geometry>
      <origin rpy="0 0 0" xyz="0.0 0.0 0.0"/>
    </collision>
  </link>
  <joint name="r2/left_leg/joint1" type="revolute">
    <parent link="r2/left_hip_roll"/>
    <child link="r2/left_hip_pitch"/>
    <origin rpy="-1.570796  -0.2617994 0.0000000" xyz="0.050629765 +0.0022860 0.103498576"/>
    <axis xyz="0 0 1"/>
    <dynamics damping="5.0" friction="0.0"/>
    <limit effort="330.0" lower="-1.483" upper="1.27" velocity="1.0"/>
  </joint>
  <link name="r2/left_hip_pitch">
    <inertial>
      <mass value="4.78221"/>
      <inertia ixx="0.1" ixy="0.00" ixz="0.0" iyy="0.1" iyz="0.0" izz="0.1"/>
    </inertial>
    <visual>
      <geometry>
        <mesh filename="package://r2_description/meshes/r2_legs/r2cl_ext_bone1.dae"/>
      </geometry>
      <origin rpy="0 0 0" xyz="0 0 0"/>
    </visual>
    <collision>
      <geometry>
        <mesh filename="package://r2_description/meshes/r2_legs/r2cl_ext_bone1.dae"/>
      </geometry>
      <origin rpy="0 0 0" xyz="0 0 0"/>
    </collision>
  </link>
  <joint name="r2/left_leg/joint2" type="revolute">
    <parent link="r2/left_hip_pitch"/>
    <child link="r2/left_upper_leg"/>
    <origin rpy=" 1.570796 0.0 1.570796" xyz="0.200 -0.050 0.004"/>
    <axis xyz="0 0 1"/>
    <dynamics damping="5.0" friction="0.0"/>
    <limit effort="330.0" lower="-4.71239" upper="4.71239" velocity="1.0"/>
  </joint>
  <link name="r2/left_upper_leg">
    <inertial>
      <mass value="3.73407"/>
      <inertia ixx="0.1" ixy="0.00" ixz="0.0" iyy="0.1" iyz="0.0" izz="0.1"/>
    </inertial>
    <visual>
      <geometry>
        <mesh filename="package://r2_description/meshes/r2_legs/r2cl_ext_bone2.dae"/>
      </geometry>
      <origin rpy="0 0 0" xyz="0 0 0"/>
    </visual>
    <collision>
      <geometry>
        <mesh filename="package://r2_description/meshes/r2_legs/r2cl_ext_bone2.dae"/>
      </geometry>
      <origin rpy="0 0 0" xyz="0 0 0"/>
    </collision>
  </link>
  <joint name="r2/left_leg/joint3" type="revolute">
    <parent link="r2/left_upper_leg"/>
    <child link="r2/left_knee"/>
    <origin rpy="0.0 -1.570796 3.14159" xyz="-0.002 -0.050 0.157"/>
    <axis xyz="0 0 1"/>
    <dynamics damping="5.0" friction="0.0"/>
    <limit effort="330.0" lower="-0.0872664" upper="2.6703515" velocity="1.0"/>
  </joint>
  <link name="r2/left_knee">
    <inertial>
      <mass value="4.78221"/>
      <inertia ixx="0.1" ixy="0.00" ixz="0.0" iyy="0.1" iyz="0.0" izz="0.1"/>
    </inertial>
    <visual>
      <geometry>
        <mesh filename="package://r2_description/meshes/r2_legs/r2cl_ext_bone1.dae"/>
      </geometry>
      <origin rpy="0 0 0" xyz="0 0 0"/>
    </visual>
    <collision>
      <geometry>
        <mesh filename="package://r2_description/meshes/r2_legs/r2cl_ext_bone1.dae"/>
      </geometry>
      <material name="gold"/>
      <origin rpy="0 0 0" xyz="0 0 0"/>
    </collision>
  </link>
  <joint name="r2/left_leg/joint4" type="revolute">
    <parent link="r2/left_knee"/>
    <child link="r2/left_lower_leg"/>
    <origin rpy="0 1.570796 0" xyz="0.200 -0.050 0.004"/>
    <axis xyz="0 0 1"/>
    <dynamics damping="5.0" friction="0.0"/>
    <limit effort="330.0" lower="-4.71239" upper="4.71239" velocity="1.0"/>
  </joint>
  <link name="r2/left_lower_leg">
    <inertial>
      <mass value="3.73407"/>
      <inertia ixx="0.1" ixy="0.00" ixz="0.0" iyy="0.1" iyz="0.0" izz="0.1"/>
    </inertial>
    <visual>
      <geometry>
        <mesh filename="package://r2_description/meshes/r2_legs/r2cl_ext_bone2.dae"/>
      </geometry>
      <origin rpy="0 0 0" xyz="0 0 0"/>
    </visual>
    <collision>
      <geometry>
        <mesh filename="package://r2_description/meshes/r2_legs/r2cl_ext_bone2.dae"/>
      </geometry>
      <origin rpy="0 0 0" xyz="0 0 0"/>
    </collision>
  </link>
  <joint name="r2/left_leg/joint5" type="revolute">
    <parent link="r2/left_lower_leg"/>
    <child link="r2/left_ankle_pitch"/>
    <origin rpy="0.0 -1.570796 3.14159" xyz="-0.002 -0.050 0.157"/>
    <axis xyz="0 0 1"/>
    <dynamics damping="5.0" friction="0.0"/>
    <limit effort="330.0" lower="-0.0872664" upper="2.6703515" velocity="1.0"/>
  </joint>
  <link name="r2/left_ankle_pitch">
    <inertial>
      <mass value="4.78221"/>
      <inertia ixx="0.1" ixy="0.00" ixz="0.0" iyy="0.1" iyz="0.0" izz="0.1"/>
    </inertial>
    <visual>
      <geometry>
        <mesh filename="package://r2_description/meshes/r2_legs/r2cl_ext_bone1.dae"/>
      </geometry>
      <origin rpy="0 0 0" xyz="0 0 0"/>
    </visual>
    <collision>
      <geometry>
        <mesh filename="package://r2_description/meshes/r2_legs/r2cl_ext_bone1.dae"/>
      </geometry>
      <origin rpy="0 0 0" xyz="0 0 0"/>
    </collision>
  </link>
  <joint name="r2/left_leg/joint6" type="revolute">
    <parent link="r2/left_ankle_pitch"/>
    <child link="r2/left_ankle_roll"/>
    <origin rpy="3.14159 -1.570796 0" xyz="0.199643 -0.0508 0.00325"/>
    <axis xyz="0 0 1"/>
    <dynamics damping="5.0" friction="0.0"/>
    <limit effort="330.0" lower="-4.71239" upper="4.71239" velocity="1.0"/>
  </joint>
  <link name="r2/left_ankle_roll">
    <inertial>
      <mass value="1.50471"/>
      <inertia ixx="0.1" ixy="0.00" ixz="0.0" iyy="0.1" iyz="0.0" izz="0.1"/>
    </inertial>
    <visual>
      <geometry>
        <cylinder length=".06" radius=".066"/>
      </geometry>
      <material name="dirty_white"/>
      <origin rpy="0 0 0" xyz="0 0 0.025"/>
    </visual>
    <collision>
      <geometry>
        <cylinder length=".06" radius=".066"/>
      </geometry>
      <origin rpy="0 0 0" xyz="0 0 0.025"/>
    </collision>
  </link>
  <joint name="r2/fixed/left_ankle_roll/left_leg_foot" type="fixed">
    <parent link="r2/left_ankle_roll"/>
    <child link="r2/left_leg_foot"/>
    <origin rpy="0.0 0 0" xyz="0.0 0.0 0.04953"/>
  </joint>
  <link name="r2/left_leg_foot">
    <inertial>
      <mass value="4.40475"/>
      <inertia ixx="0.1" ixy="0.0" ixz="0.0" iyy="0.1" iyz="0.0" izz="0.1"/>
    </inertial>
    <visual>
      <geometry>
        <mesh filename="package://r2_description/meshes/r2_legs/r2cl_foot.dae"/>
      </geometry>
      <origin rpy="0 0 0" xyz="0 0 0"/>
    </visual>
    <collision>
      <geometry>
        <mesh filename="package://r2_description/meshes/r2_legs/r2cl_foot.dae"/>
      </geometry>
      <origin rpy="0 0 0" xyz="0 0 0"/>
    </collision>
  </link>
  <joint name="r2/fixed/left_foot/simulated_camboard" type="fixed">
    <parent link="r2/left_leg_foot"/>
    <child link="r2/simulated_left_foot_camboard_frame"/>
    <dynamics damping="1.0"/>
    <origin rpy="0 -1.57 -1.57" xyz="0.015 0.07 .165"/>
  </joint>
  <joint name="r2/fixed/left_foot/simulated_camboard_depth" type="fixed">
    <parent link="r2/left_leg_foot"/>
    <child link="r2/simulated_left_foot_camboard_depth_frame"/>
    <dynamics damping="1.0"/>
    <origin rpy="3.14 3.14 0" xyz="0.015 0.07 .165"/>
  </joint>
  <joint name="r2/left_leg/gripper/joint0" type="revolute">
    <parent link="r2/left_leg_foot"/>
    <child link="r2/left_leg/gripper/link0"/>
    <origin rpy="0.0 0 0" xyz="0 0 0"/>
    <axis xyz="0 0 1"/>
    <dynamics damping="1.0" friction="0.0"/>
    <limit effort="330.0" lower="-.5" upper=".5" velocity="1.0"/>
  </joint>
  <joint name="r2/left_leg/gripper/joint1" type="revolute">
    <parent link="r2/left_leg_foot"/>
    <child link="r2/left_leg_jaw0"/>
    <origin rpy="0.0 0 0" xyz="0.01905 0 0.17546"/>
    <axis xyz="0 -1 0"/>
    <dynamics damping="1.0" friction="0.0"/>
    <limit effort="330.0" lower="-.5" upper=".5" velocity="1.0"/>
  </joint>
  <joint name="r2/left_leg/gripper/joint2" type="revolute">
    <parent link="r2/left_leg_foot"/>
    <child link="r2/left_leg_jaw1"/>
    <origin rpy="0.0 0 0" xyz="-0.01905 0 0.17546"/>
    <axis xyz="0 1 0"/>
    <dynamics damping="1.0" friction="0.0"/>
    <limit effort="330.0" lower="-.5" upper=".5" velocity="1.0"/>
  </joint>
  <joint name="r2/fixed/left_leg_foot/left_hr_tip" type="fixed">
    <parent link="r2/left_leg_foot"/>
    <child link="r2/left_hr_tip"/>
    <origin rpy="0.0 0 0" xyz="0 0 0.19451"/>
  </joint>
  <joint name="r2/fixed/left_leg_foot/left_st_tip" type="fixed">
    <parent link="r2/left_leg_foot"/>
    <child link="r2/left_st_tip"/>
    <origin rpy="0.0 0 0" xyz="0 0 0.21991"/>
  </joint>
  <joint name="r2/fixed/left_leg_foot/left_leg_camera0_physical" type="fixed">
    <parent link="r2/left_leg_foot"/>
    <child link="r2/left_leg_camera0_physical"/>
    <origin rpy="0 0 0" xyz="-0.025 .07 0.13"/>
  </joint>
  <joint name="r2/fixed/left_leg_foot/left_leg_camera1_physical" type="fixed">
    <parent link="r2/left_leg_foot"/>
    <child link="r2/left_leg_camera1_physical"/>
    <origin rpy="0.0 0 0" xyz="0.025 .07 0.13"/>
  </joint>
  <link name="r2/left_leg/gripper/link0">
    <inertial>
      <mass value="0.01"/>
      <inertia ixx="0.0001" ixy="0.0" ixz="0.0" iyy="0.001" iyz="0.0" izz="0.001"/>
    </inertial>
  </link>
  <link name="r2/left_hr_tip">
    <inertial>
      <mass value="0.01"/>
      <inertia ixx="0.0001" ixy="0.0" ixz="0.0" iyy="0.001" iyz="0.0" izz="0.001"/>
    </inertial>
  </link>
  <link name="r2/left_st_tip">
    <inertial>
      <mass value="0.01"/>
      <inertia ixx="0.0001" ixy="0.0" ixz="0.0" iyy="0.001" iyz="0.0" izz="0.001"/>
    </inertial>
  </link>
  <link name="r2/simulated_left_foot_camboard_frame">
    <inertial>
      <mass value=".1"/>
      <inertia ixx=".01" ixy="0.0" ixz="0.0" iyy=".01" iyz="0.0" izz=".01"/>
    </inertial>
  </link>
  <link name="r2/simulated_left_foot_camboard_depth_frame">
    <inertial>
      <mass value=".1"/>
      <inertia ixx=".01" ixy="0.0" ixz="0.0" iyy=".01" iyz="0.0" izz=".01"/>
    </inertial>
  </link>
  <link name="r2/left_leg_jaw0">
    <inertial>
      <mass value="0.16268"/>
      <inertia ixx="0.1" ixy="0.0" ixz="0.0" iyy="0.1" iyz="0.0" izz="0.1"/>
    </inertial>
    <visual>
      <geometry>
        <mesh filename="package://r2_description/meshes/r2_legs/r2cl_foot_jaw1.dae"/>
      </geometry>
      <origin rpy="0 0 0" xyz="0 0 0"/>
    </visual>
    <collision>
      <geometry>
        <mesh filename="package://r2_description/meshes/r2_legs/r2cl_foot_jaw1.dae"/>
      </geometry>
      <origin rpy="0 0 0" xyz="0 0 0"/>
    </collision>
  </link>
  <link name="r2/left_leg_jaw1">
    <inertial>
      <mass value="0.16268"/>
      <inertia ixx="0.1" ixy="0.0" ixz="0.0" iyy="0.1" iyz="0.0" izz="0.1"/>
    </inertial>
    <visual>
      <geometry>
        <mesh filename="package://r2_description/meshes/r2_legs/r2cl_foot_jaw2.dae"/>
      </geometry>
      <origin rpy="0 0 0" xyz="0 0 0"/>
    </visual>
    <collision>
      <geometry>
        <mesh filename="package://r2_description/meshes/r2_legs/r2cl_foot_jaw2.dae"/>
      </geometry>
      <origin rpy="0 0 0" xyz="0 0 0"/>
    </collision>
  </link>
  <link name="r2/left_leg_camera0_physical">
    <inertial>
      <mass value="0.01"/>
      <inertia ixx="0.0001" ixy="0.0" ixz="0.0" iyy="0.001" iyz="0.0" izz="0.001"/>
    </inertial>
  </link>
  <joint name="r2/fixed/left_leg_camera0_physical/left_leg_camera0_optical" type="fixed">
    <parent link="r2/left_leg_camera0_physical"/>
    <child link="r2/left_leg_camera0_optical"/>
    <origin rpy="0 -1.57 -1.57" xyz="0 0 .03"/>
  </joint>
  <link name="r2/left_leg_camera0_optical">
    <inertial>
      <mass value="0.01"/>
      <inertia ixx="0.0001" ixy="0.0" ixz="0.0" iyy="0.001" iyz="0.0" izz="0.001"/>
    </inertial>
  </link>
  <link name="r2/left_leg_camera1_physical">
    <inertial>
      <mass value="0.01"/>
      <inertia ixx="0.0001" ixy="0.0" ixz="0.0" iyy="0.001" iyz="0.0" izz="0.001"/>
    </inertial>
  </link>
  <joint name="r2/fixed/left_leg_camera1_physical/left_leg_camera1_optical" type="fixed">
    <parent link="r2/left_leg_camera1_physical"/>
    <child link="r2/left_leg_camera1_optical"/>
    <origin rpy="0 -1.57 -1.57" xyz="0 0 0.03"/>
  </joint>
  <link name="r2/left_leg_camera1_optical">
    <inertial>
      <mass value="0.01"/>
      <inertia ixx="0.0001" ixy="0.0" ixz="0.0" iyy="0.001" iyz="0.0" izz="0.001"/>
    </inertial>
  </link>
  <joint name="r2/fixed/pelvis/right_leg_base" type="fixed">
    <parent link="r2/pelvis"/>
    <child link="r2/right_leg_base"/>
    <origin rpy="0 0.000000 1.570796" xyz="0.0 0 0.0"/>
  </joint>
  <link name="r2/right_leg_base">
    <inertial>
      <mass value="3.2"/>
      <inertia ixx="1.0" ixy="0.0" ixz="0.0" iyy="1.0" iyz="0.0" izz="1.0"/>
    </inertial>
    <visual>
      <geometry>
        <cylinder length=".11" radius=".05"/>
      </geometry>
      <origin rpy="0 1.82 0" xyz="0.055 0.0 -.015 "/>
    </visual>
    <collision>
      <geometry>
        <cylinder length=".11" radius=".05"/>
      </geometry>
      <origin rpy="0 1.82 0" xyz="0.055 0.0 -.015 "/>
    </collision>
  </link>
  <joint name="r2/fixed/right_leg_base/right_leg_j0_base" type="fixed">
    <parent link="r2/right_leg_base"/>
    <child link="r2/right_leg_j0_base"/>
    <origin rpy="0.0 1.8325957 0" xyz="0.1104900 0.0 -0.0297180"/>
  </joint>
  <link name="r2/right_leg_j0_base">
    <inertial>
      <mass value="0.01"/>
      <inertia ixx="0.0001" ixy="0.0" ixz="0.0" iyy="0.001" iyz="0.0" izz="0.001"/>
    </inertial>
  </link>
  <joint name="r2/right_leg/joint0" type="revolute">
    <parent link="r2/right_leg_j0_base"/>
    <child link="r2/right_hip_roll"/>
    <origin rpy=" 0.000000 0 0.000000" xyz="0 0 0"/>
    <axis xyz="0 0 1"/>
    <dynamics damping="10.0" friction="0.0"/>
    <limit effort="330.0" lower="-4.71239" upper="4.71239" velocity="1.0"/>
    <traits spring_k="2.5"/>
  </joint>
  <link name="r2/right_hip_roll">
    <inertial>
      <mass value="2.33931"/>
      <inertia ixx="0.1" ixy="0.00" ixz="0.0" iyy="0.1" iyz="0.0" izz="0.1"/>
    </inertial>
    <visual>
      <geometry>
        <mesh filename="package://r2_description/meshes/r2_legs/r2cl_ext_bone3.dae"/>
      </geometry>
      <origin rpy="0 0 0" xyz="0.0 0.0 0.0"/>
    </visual>
    <collision>
      <geometry>
        <mesh filename="package://r2_description/meshes/r2_legs/r2cl_ext_bone3.dae"/>
      </geometry>
      <origin rpy="0 0 0" xyz="0.0 0.0 0.0"/>
    </collision>
  </link>
  <joint name="r2/right_leg/joint1" type="revolute">
    <parent link="r2/right_hip_roll"/>
    <child link="r2/right_hip_pitch"/>
    <origin rpy="-1.570796  -0.2617994 0.0000000" xyz="0.050629765 -0.0022860 0.103498576"/>
    <axis xyz="0 0 1"/>
    <dynamics damping="5.0" friction="0.0"/>
    <limit effort="330.0" lower="-1.483" upper="1.27" velocity="1.0"/>
    <traits spring_k="2.5"/>
  </joint>
  <link name="r2/right_hip_pitch">
    <inertial>
      <mass value="4.78221"/>
      <inertia ixx="0.1" ixy="0.00" ixz="0.0" iyy="0.1" iyz="0.0" izz="0.1"/>
    </inertial>
    <visual>
      <geometry>
        <mesh filename="package://r2_description/meshes/r2_legs/r2cl_ext_bone1.dae"/>
      </geometry>
      <origin rpy="0 0 0" xyz="0 0 0"/>
    </visual>
    <collision>
      <geometry>
        <mesh filename="package://r2_description/meshes/r2_legs/r2cl_ext_bone1.dae"/>
      </geometry>
      <origin rpy="0 0 0" xyz="0 0 0"/>
    </collision>
  </link>
  <joint name="r2/right_leg/joint2" type="revolute">
    <parent link="r2/right_hip_pitch"/>
    <child link="r2/right_upper_leg"/>
    <origin rpy="-1.570796 0.0 -1.570796" xyz="0.200 -0.050 0.004"/>
    <axis xyz="0 0 1"/>
    <dynamics damping="5.0" friction="0.0"/>
    <limit effort="330.0" lower="-4.71239" upper="4.71239" velocity="1.0"/>
    <traits spring_k="2.5"/>
  </joint>
  <link name="r2/right_upper_leg">
    <inertial>
      <mass value="3.73407"/>
      <inertia ixx="0.1" ixy="0.00" ixz="0.0" iyy="0.1" iyz="0.0" izz="0.1"/>
    </inertial>
    <visual>
      <geometry>
        <mesh filename="package://r2_description/meshes/r2_legs/r2cl_ext_bone2.dae"/>
      </geometry>
      <origin rpy="0 0 0" xyz="0 0 0"/>
    </visual>
    <collision>
      <geometry>
        <mesh filename="package://r2_description/meshes/r2_legs/r2cl_ext_bone2.dae"/>
      </geometry>
      <origin rpy="0 0 0" xyz="0 0 0.0"/>
    </collision>
  </link>
  <joint name="r2/right_leg/joint3" type="revolute">
    <parent link="r2/right_upper_leg"/>
    <child link="r2/right_knee"/>
    <origin rpy="0.0 -1.570796 3.14159" xyz="-0.00200 -0.050  0.157"/>
    <axis xyz="0 0 1"/>
    <dynamics damping="5.0" friction="0.0"/>
    <limit effort="330.0" lower="-0.0872664" upper="2.6703515" velocity="1.0"/>
    <traits spring_k="2.5"/>
  </joint>
  <link name="r2/right_knee">
    <inertial>
      <mass value="4.78221"/>
      <inertia ixx="0.1" ixy="0.00" ixz="0.0" iyy="0.1" iyz="0.0" izz="0.1"/>
    </inertial>
    <visual>
      <geometry>
        <mesh filename="package://r2_description/meshes/r2_legs/r2cl_ext_bone1.dae"/>
      </geometry>
      <origin rpy="0 0 0" xyz="0 0 0"/>
    </visual>
    <collision>
      <geometry>
        <mesh filename="package://r2_description/meshes/r2_legs/r2cl_ext_bone1.dae"/>
      </geometry>
      <material name="gold"/>
      <origin rpy="0 0 0" xyz="0 0 0"/>
    </collision>
  </link>
  <joint name="r2/right_leg/joint4" type="revolute">
    <parent link="r2/right_knee"/>
    <child link="r2/right_lower_leg"/>
    <origin rpy="0 1.570796 0" xyz="0.200 -0.050 0.004"/>
    <axis xyz="0 0 1"/>
    <dynamics damping="5.0" friction="0.0"/>
    <limit effort="330.0" lower="-4.71239" upper="4.71239" velocity="1.0"/>
    <traits spring_k="2.5"/>
  </joint>
  <link name="r2/right_lower_leg">
    <inertial>
      <mass value="3.73407"/>
      <inertia ixx="0.1" ixy="0.00" ixz="0.0" iyy="0.1" iyz="0.0" izz="0.1"/>
    </inertial>
    <visual>
      <geometry>
        <mesh filename="package://r2_description/meshes/r2_legs/r2cl_ext_bone2.dae"/>
      </geometry>
      <origin rpy="0 0 0" xyz="0 0 0"/>
    </visual>
    <collision>
      <geometry>
        <mesh filename="package://r2_description/meshes/r2_legs/r2cl_ext_bone2.dae"/>
      </geometry>
      <origin rpy="0 0 0" xyz="0 0 0.0"/>
    </collision>
  </link>
  <joint name="r2/right_leg/joint5" type="revolute">
    <parent link="r2/right_lower_leg"/>
    <child link="r2/right_ankle_pitch"/>
    <origin rpy="0.0 -1.570796 3.14159" xyz="-0.002 -0.050 0.157"/>
    <axis xyz="0 0 1"/>
    <dynamics damping="5.0" friction="0.0"/>
    <limit effort="330.0" lower="-0.0872664" upper="2.6703515" velocity="1.0"/>
    <traits spring_k="2.5"/>
  </joint>
  <link name="r2/right_ankle_pitch">
    <inertial>
      <mass value="4.78221"/>
      <inertia ixx="0.1" ixy="0.00" ixz="0.0" iyy="0.1" iyz="0.0" izz="0.1"/>
    </inertial>
    <visual>
      <geometry>
        <mesh filename="package://r2_description/meshes/r2_legs/r2cl_ext_bone1.dae"/>
      </geometry>
      <origin rpy="0 0 0" xyz="0 0 0"/>
    </visual>
    <collision>
      <geometry>
        <mesh filename="package://r2_description/meshes/r2_legs/r2cl_ext_bone1.dae"/>
      </geometry>
      <origin rpy="0 0 0" xyz="0 0 0"/>
    </collision>
  </link>
  <joint name="r2/right_leg/joint6" type="revolute">
    <parent link="r2/right_ankle_pitch"/>
    <child link="r2/right_ankle_roll"/>
    <origin rpy="3.14159 -1.570796 0 " xyz="0.199643 -0.0508 0.00325"/>
    <axis xyz="0 0 1"/>
    <dynamics damping="5.0" friction="0.0"/>
    <limit effort="330.0" lower="-4.71239" upper="4.71239" velocity="1.0"/>
    <traits spring_k="2.5"/>
  </joint>
  <link name="r2/right_ankle_roll">
    <inertial>
      <mass value="1.50471"/>
      <inertia ixx="0.1" ixy="0.00" ixz="0.0" iyy="0.1" iyz="0.0" izz="0.1"/>
    </inertial>
    <visual>
      <geometry>
        <cylinder length=".06" radius=".066"/>
      </geometry>
      <material name="dirty_white"/>
      <origin rpy="0 0 0" xyz="0 0 0.025"/>
    </visual>
    <collision>
      <geometry>
        <cylinder length=".06" radius=".066"/>
      </geometry>
      <material name="gold"/>
      <origin rpy="0 0 0" xyz="0 0 0.025"/>
    </collision>
  </link>
  <joint name="r2/fixed/right_ankle_roll/right_leg_foot" type="fixed">
    <parent link="r2/right_ankle_roll"/>
    <child link="r2/right_leg_foot"/>
    <origin rpy="0.0 0 0" xyz="0.0 0.0 0.04953"/>
  </joint>
  <link name="r2/right_leg_foot">
    <inertial>
      <mass value="4.40475"/>
      <inertia ixx="0.1" ixy="0.0" ixz="0.0" iyy="0.1" iyz="0.0" izz="0.1"/>
    </inertial>
    <visual>
      <geometry>
        <mesh filename="package://r2_description/meshes/r2_legs/r2cl_foot.dae"/>
      </geometry>
      <material name="gold"/>
      <origin rpy="0 0 0" xyz="0 0 0"/>
    </visual>
    <collision>
      <geometry>
        <mesh filename="package://r2_description/meshes/r2_legs/r2cl_foot.dae"/>
      </geometry>
      <origin rpy="0 0 0" xyz="0 0 0"/>
    </collision>
  </link>
  <joint name="r2/fixed/right_foot/simulated_camboard" type="fixed">
    <parent link="r2/right_leg_foot"/>
    <child link="r2/simulated_right_foot_camboard_frame"/>
    <dynamics damping="1.0"/>
    <origin rpy="0 -1.57 -1.57" xyz="0.015 0.07 .165"/>
  </joint>
  <joint name="r2/fixed/right_foot/simulated_camboard_depth" type="fixed">
    <parent link="r2/right_leg_foot"/>
    <child link="r2/simulated_right_foot_camboard_depth_frame"/>
    <dynamics damping="1.0"/>
    <origin rpy="3.14 3.14 0" xyz="0.015 0.07 .165"/>
  </joint>
  <joint name="r2/right_leg/gripper/joint0" type="prismatic">
    <parent link="r2/right_leg_foot"/>
    <child link="r2/right_leg/gripper/link0"/>
    <origin rpy="0.0 0 0" xyz="0 0 0"/>
    <axis xyz="0 0 1"/>
    <dynamics damping="1.0" friction="0.0"/>
    <limit effort="330.0" lower="-.5" upper=".5" velocity="1.0"/>
  </joint>
  <joint name="r2/right_leg/gripper/joint1" type="revolute">
    <parent link="r2/right_leg_foot"/>
    <child link="r2/right_leg_jaw0"/>
    <origin rpy="0.0 0 0" xyz="0.01905 0 0.17546"/>
    <axis xyz="0 -1 0"/>
    <dynamics damping="1.0" friction="0.0"/>
    <limit effort="330.0" lower="-.5" upper=".5" velocity="1.0"/>
    <traits spring_k="2.5"/>
  </joint>
  <joint name="r2/right_leg/gripper/joint2" type="revolute">
    <parent link="r2/right_leg_foot"/>
    <child link="r2/right_leg_jaw1"/>
    <origin rpy="0.0 0 0" xyz="-0.01905 0 0.17546"/>
    <axis xyz="0 1 0"/>
    <dynamics damping="1.0" friction="0.0"/>
    <limit effort="330.0" lower="-.5" upper=".5" velocity="1.0"/>
    <traits spring_k="2.5"/>
  </joint>
  <joint name="r2/fixed/right_leg_foot/right_hr_tip" type="fixed">
    <parent link="r2/right_leg_foot"/>
    <child link="r2/right_hr_tip"/>
    <origin rpy="0.0 0 0" xyz="0 0 0.19451"/>
  </joint>
  <joint name="r2/fixed/right_leg_foot/right_st_tip" type="fixed">
    <parent link="r2/right_leg_foot"/>
    <child link="r2/right_st_tip"/>
    <origin rpy="0.0 0 0" xyz="0 0 0.21991"/>
  </joint>
  <joint name="r2/fixed/right_leg_foot/right_leg_camera0_physical" type="fixed">
    <parent link="r2/right_leg_foot"/>
    <child link="r2/right_leg_camera0_physical"/>
    <origin rpy="0.0 0  0" xyz="-0.025 .07 0.13"/>
  </joint>
  <joint name="r2/fixed/right_leg_foot/right_leg_camera1_physical" type="fixed">
    <parent link="r2/right_leg_foot"/>
    <child link="r2/right_leg_camera1_physical"/>
    <origin rpy="0.0 0  0" xyz="0.025 .07 0.13"/>
  </joint>
  <link name="r2/right_leg/gripper/link0">
    <inertial>
      <mass value="0.01"/>
      <inertia ixx="0.0001" ixy="0.0" ixz="0.0" iyy="0.001" iyz="0.0" izz="0.001"/>
    </inertial>
  </link>
  <link name="r2/right_hr_tip">
    <inertial>
      <mass value="0.01"/>
      <inertia ixx="0.0001" ixy="0.0" ixz="0.0" iyy="0.001" iyz="0.0" izz="0.001"/>
    </inertial>
  </link>
  <link name="r2/right_st_tip">
    <inertial>
      <mass value="0.01"/>
      <inertia ixx="0.0001" ixy="0.0" ixz="0.0" iyy="0.001" iyz="0.0" izz="0.001"/>
    </inertial>
  </link>
  <link name="r2/simulated_right_foot_camboard_frame">
    <inertial>
      <mass value=".1"/>
      <inertia ixx=".01" ixy="0.0" ixz="0.0" iyy=".01" iyz="0.0" izz=".01"/>
    </inertial>
  </link>
  <link name="r2/simulated_right_foot_camboard_depth_frame">
    <inertial>
      <mass value=".1"/>
      <inertia ixx=".01" ixy="0.0" ixz="0.0" iyy=".01" iyz="0.0" izz=".01"/>
    </inertial>
  </link>
  <link name="r2/right_leg_jaw0">
    <inertial>
      <mass value="0.16268"/>
      <inertia ixx="0.1" ixy="0.0" ixz="0.0" iyy="0.1" iyz="0.0" izz="0.1"/>
    </inertial>
    <visual>
      <geometry>
        <mesh filename="package://r2_description/meshes/r2_legs/r2cl_foot_jaw1.dae"/>
      </geometry>
      <origin rpy="0 0 0" xyz="0 0 0"/>
    </visual>
    <collision>
      <geometry>
        <mesh filename="package://r2_description/meshes/r2_legs/r2cl_foot_jaw1.dae"/>
      </geometry>
      <origin rpy="0 0 0" xyz="0 0 0"/>
    </collision>
  </link>
  <link name="r2/right_leg_jaw1">
    <inertial>
      <mass value="0.16268"/>
      <inertia ixx="0.1" ixy="0.0" ixz="0.0" iyy="0.1" iyz="0.0" izz="0.1"/>
    </inertial>
    <visual>
      <geometry>
        <mesh filename="package://r2_description/meshes/r2_legs/r2cl_foot_jaw2.dae"/>
      </geometry>
      <origin rpy="0 0 0" xyz="0 0 0"/>
    </visual>
    <collision>
      <geometry>
        <mesh filename="package://r2_description/meshes/r2_legs/r2cl_foot_jaw2.dae"/>
      </geometry>
      <origin rpy="0 0 0" xyz="0 0 0"/>
    </collision>
  </link>
  <link name="r2/right_leg_camera0_physical">
    <inertial>
      <mass value="0.01"/>
      <inertia ixx="0.0001" ixy="0.0" ixz="0.0" iyy="0.001" iyz="0.0" izz="0.001"/>
    </inertial>
  </link>
  <joint name="r2/fixed/right_leg_camera0_physical/right_leg_camera0_optical" type="fixed">
    <parent link="r2/right_leg_camera0_physical"/>
    <child link="r2/right_leg_camera0_optical"/>
    <origin rpy="0 -1.57 -1.57" xyz="0 0 0.03"/>
  </joint>
  <link name="r2/right_leg_camera0_optical">
    <inertial>
      <mass value="0.01"/>
      <inertia ixx="0.0001" ixy="0.0" ixz="0.0" iyy="0.001" iyz="0.0" izz="0.001"/>
    </inertial>
  </link>
  <link name="r2/right_leg_camera1_physical">
    <inertial>
      <mass value="0.01"/>
      <inertia ixx="0.0001" ixy="0.0" ixz="0.0" iyy="0.001" iyz="0.0" izz="0.001"/>
    </inertial>
  </link>
  <joint name="r2/fixed/right_leg_camera1_physical/right_leg_camera1_optical" type="fixed">
    <parent link="r2/right_leg_camera1_physical"/>
    <child link="r2/right_leg_camera1_optical"/>
    <origin rpy="0 -1.57 -1.57" xyz="0 0 .03"/>
  </joint>
  <link name="r2/right_leg_camera1_optical">
    <inertial>
      <mass value="0.01"/>
      <inertia ixx="0.0001" ixy="0.0" ixz="0.0" iyy="0.001" iyz="0.0" izz="0.001"/>
    </inertial>
  </link>
</robot>

