<?xml version="1.0" ?>
<!-- =================================================================================== -->
<!-- |    This document was autogenerated by xacro from /home/athackst/catkin_ws/src/nasa_r2_common/r2_description/robots/r2_orocos.sim.urdf.xacro | -->
<!-- |    EDITING THIS FILE BY HAND IS NOT RECOMMENDED                                 | -->
<!-- =================================================================================== -->
<robot name="r2_orocos" xmlns:controller="http://playerstage.sourceforge.net/gazebo/xmlschema/#controller" xmlns:interface="http://playerstage.sourceforge.net/gazebo/xmlschema/#interface" xmlns:sensor="http://playerstage.sourceforge.net/gazebo/xmlschema/#sensor" xmlns:xacro="http://playerstage.sourceforge.net/gazebo/xmlschema/#interface">
  <link name="world"/>
  <link name="/r2/robot_world">
    <inertial>
      <mass value="0.01"/>
      <inertia ixx="0.0001" ixy="0.0" ixz="0.0" iyy="0.0001" iyz="0.0" izz="0.0001"/>
    </inertial>
  </link>
  <joint name="/r2/fixed/world/robot_world" type="fixed">
    <parent link="world"/>
    <child link="/r2/robot_world"/>
    <origin rpy="0.0 0.0 0.0" xyz="0.0 0.0 1.0"/>
  </joint>
  <link name="/r2/robot_base">
    <inertial>
      <mass value="0.01"/>
      <inertia ixx="0.0001" ixy="0.0" ixz="0.0" iyy="0.0001" iyz="0.0" izz="0.0001"/>
    </inertial>
  </link>
  <joint name="/r2/fixed/robot_world/robot_base" type="fixed">
    <parent link="/r2/robot_world"/>
    <child link="/r2/robot_base"/>
    <origin rpy="0.0 3.14159 3.14159" xyz="0.0 0.0 0.0"/>
  </joint>
  <material name="white">
    <color rgba="1.0 1.0 1.0 1.0"/>
  </material>
  <material name="dirty_white">
    <color rgba="0.322 0.322 0.322 1.0"/>
  </material>
  <material name="gold">
    <color rgba=".878 .49 0.008 1"/>
  </material>
  <material name="steel">
    <color rgba=".7 .7 .7 1"/>
  </material>
  <material name="blue">
    <color rgba="0 0 0.8 1"/>
  </material>
  <link name="/r2/imu">
    <inertial>
      <mass value="0.01"/>
      <inertia ixx="0.0001" ixy="0.0" ixz="0.0" iyy="0.0001" iyz="0.0" izz="0.0001"/>
    </inertial>
  </link>
  <joint name="/r2/fixed/robot_base/imu" type="fixed">
    <parent link="/r2/waist_center"/>
    <child link="/r2/imu"/>
    <origin rpy="1.5708 0 0" xyz="0.017351 -0.116179 -0.112236"/>
  </joint>
  <joint name="/r2/fixed/robot_base/waist_mass" type="fixed">
    <parent link="/r2/robot_base"/>
    <child link="/r2/waist_mass"/>
    <origin rpy="0.0 0 0.0" xyz="0.0 0.0 -0.086855"/>
  </joint>
  <link name="/r2/waist_mass">
    <inertial>
      <mass value="4.6259465"/>
      <origin rpy="0.0 0 0.0" xyz="-0.00012809088 0.000041480778 0.039080994"/>
      <inertia ixx="0.01684448" ixy="0.00021529806" ixz="-0.0000036013959" iyy="0.017313387" iyz="0.0" izz="0.028769348"/>
    </inertial>
  </link>
  <joint name="/r2/waist/joint0" type="revolute">
    <parent link="/r2/robot_base"/>
    <child link="/r2/waist_center"/>
    <axis xyz="0 0 1"/>
    <origin rpy="0.0 0 0.0" xyz="0.0 0.0 0.0"/>
    <dynamics damping="10.0" friction="0.0"/>
    <limit effort="10000000.0" lower="-3.14" upper="3.14" velocity="10"/>
  </joint>
  <link name="/r2/waist_center">
    <visual>
      <geometry>
        <mesh filename="package://r2_description/meshes/Body.dae"/>
      </geometry>
      <origin rpy="-1.5708 0 -1.5708" xyz="0.02 0.05 -0.5625"/>
    </visual>
    <collision>
      <geometry>
        <mesh filename="package://r2_description/meshes/Body.dae"/>
      </geometry>
      <origin rpy="-1.5708 0 -1.5708" xyz="0.02 0.05 -0.5625"/>
    </collision>
    <inertial>
      <mass value="47.770842"/>
      <origin rpy="0.0 0 0.0" xyz="-0.020473299 0.0039268948 -0.36456539"/>
      <inertia ixx="1.9926945" ixy="-0.0069480619" ixz="-0.059104048" iyy="1.8449528" iyz="0.01958974" izz="0.69736445"/>
    </inertial>
  </link>
  <joint name="/r2/fixed/waist_center/robot_reference" type="fixed">
    <parent link="/r2/waist_center"/>
    <child link="/r2/robot_reference"/>
    <origin rpy="0.0 0 0.0" xyz="0.1234 0.0 0.0"/>
  </joint>
  <joint name="/r2/fixed/waist_center/body_cover" type="fixed">
    <parent link="/r2/waist_center"/>
    <child link="/r2/body_cover"/>
    <origin rpy="0.0 0.0 0.0" xyz="0 0.0 0.0"/>
  </joint>
  <joint name="/r2/fixed/waist_center/backpack" type="fixed">
    <parent link="/r2/waist_center"/>
    <child link="/r2/backpack"/>
    <origin rpy="0.0 0.0 0.0" xyz="-0.145521 0.0 -0.421894"/>
  </joint>
  <joint name="/r2/fixed/waist_center/left_shoulder_jr3" type="fixed">
    <parent link="/r2/waist_center"/>
    <child link="/r2/left_arm/shoulder/jr3"/>
    <origin rpy="0.0 0.0 1.8326" xyz="-0.0240898 -0.0996837 -0.413899"/>
  </joint>
  <joint name="/r2/fixed/waist_center/right_shoulder_jr3" type="fixed">
    <parent link="/r2/waist_center"/>
    <child link="/r2/right_arm/shoulder/jr3"/>
    <origin rpy="0.0 0.0 -1.83259" xyz="-0.0240898 0.0996837 -0.413899"/>
  </joint>
  <link name="/r2/robot_reference">
    <inertial>
      <mass value="0.01"/>
      <inertia ixx="0.0001" ixy="0.0" ixz="0.0" iyy="0.0001" iyz="0.0" izz="0.0001"/>
    </inertial>
  </link>
  <link name="/r2/body_cover">
    <visual>
      <geometry>
        <mesh filename="package://r2_description/meshes/Body_Cover.dae"/>
      </geometry>
      <origin rpy="-1.5708 0 -1.5708" xyz="0.02 0.05 -0.5625"/>
    </visual>
    <collision>
      <geometry>
        <mesh filename="package://r2_description/meshes/Body_Cover.dae"/>
      </geometry>
      <origin rpy="-1.5708 0 -1.5708" xyz="0.02 0.05 -0.5625"/>
    </collision>
    <inertial>
      <mass value="0.1"/>
      <inertia ixx="0.001" ixy="0.0" ixz="0.0" iyy="0.001" iyz="0.0" izz="0.001"/>
    </inertial>
  </link>
  <link name="/r2/backpack">
    <visual>
      <geometry>
        <mesh filename="package://r2_description/meshes/Backpack.dae"/>
      </geometry>
      <origin rpy="0 0 0.25" xyz="0.145521 0.0 -0.118106"/>
    </visual>
    <collision>
      <geometry>
        <mesh filename="package://r2_description/meshes/Backpack.dae"/>
      </geometry>
      <origin rpy="0 0 0.25" xyz="0.145521 0.0 -0.118106"/>
    </collision>
    <inertial>
      <mass value="23.505356"/>
      <origin rpy="0.0 0 0.0" xyz="-0.068110236 0.00026288234 -0.015523324"/>
      <inertia ixx="0.87608758" ixy="0.0031949152" ixz="-0.0042079052" iyy="0.57168416" iyz="0.0067562903" izz="0.41612859"/>
    </inertial>
  </link>
  <link name="/r2/left_arm/shoulder/jr3">
    <inertial>
      <mass value="0.01"/>
      <inertia ixx="0.0001" ixy="0.0" ixz="0.0" iyy="0.0001" iyz="0.0" izz="0.0001"/>
    </inertial>
  </link>
  <link name="/r2/right_arm/shoulder/jr3">
    <inertial>
      <mass value="0.01"/>
      <inertia ixx="0.0001" ixy="0.0" ixz="0.0" iyy="0.0001" iyz="0.0" izz="0.0001"/>
    </inertial>
  </link>
  <joint name="/r2/neck/joint0" type="revolute">
    <parent link="/r2/waist_center"/>
    <child link="/r2/neck_lower"/>
    <origin rpy=" -1.5708 0.0 0.0 " xyz=" 0.08636 -0.0285749 -0.614172 "/>
    <dynamics damping="10.0" friction="0.0"/>
    <axis xyz="0 0 1"/>
    <limit effort="10000.0" lower="-0.7" upper="0.175" velocity="10"/>
  </joint>
  <link name="/r2/neck_lower">
    <visual>
      <geometry>
        <mesh filename="package://r2_description/meshes/Neck_Lower.dae"/>
      </geometry>
      <origin rpy="-1.5708 1.5708 0" xyz="0.0 0.0 0.0285749"/>
    </visual>
    <inertial>
      <mass value="1.531125"/>
      <origin rpy="0 0 0" xyz="-0.044614256 0.031785824 0.021419445"/>
      <inertia ixx="0.0032988044" ixy="0.0014889073" ixz="0.0004970659" iyy="0.0050478224" iyz="-0.00036827305" izz="0.0052160286"/>
    </inertial>
    <collision>
      <geometry>
        <mesh filename="package://r2_description/meshes/Neck_Lower.dae"/>
      </geometry>
      <origin rpy="-1.5708 1.5708 0" xyz="0.0 0.0 0.0285749"/>
    </collision>
  </link>
  <joint name="/r2/neck/joint1" type="revolute">
    <parent link="/r2/neck_lower"/>
    <child link="/r2/neck_upper"/>
    <origin rpy=" -1.5708 0.0 0.0 " xyz=" -0.0762002 0.0762004 0.028575"/>
    <dynamics damping="10.0" friction="0.0"/>
    <axis xyz="0 0 1"/>
    <limit effort="10000.0" lower="-1.22" upper="1.22" velocity="10"/>
  </joint>
  <link name="/r2/neck_upper">
    <visual>
      <geometry>
        <mesh filename="package://r2_description/meshes/Neck_Upper.dae"/>
      </geometry>
      <origin rpy="0 0 1.5708" xyz="0.0762002 0 -0.0762004"/>
    </visual>
    <inertial>
      <mass value="2.234558"/>
      <origin rpy="0 0 0" xyz="0.0127259 0.0072291452 0.048896507"/>
      <inertia ixx="0.0074125667" ixy="-0.00042898316" ixz="-0.0014528455" iyy="0.0080268117" iyz="-0.00076230267" izz="0.00051467581"/>
    </inertial>
    <collision>
      <geometry>
        <mesh filename="package://r2_description/meshes/Neck_Upper.dae"/>
      </geometry>
      <origin rpy="0 0 1.5708" xyz="0.0762002 0 -0.0762004"/>
    </collision>
  </link>
  <joint name="/r2/neck/joint2" type="revolute">
    <parent link="/r2/neck_upper"/>
    <child link="/r2/head"/>
    <origin rpy=" 1.5708 0.0 0.0 " xyz="0.0508 0.0074676 0.101587"/>
    <dynamics damping="10.0" friction="0.0"/>
    <axis xyz="0 0 1"/>
    <limit effort="10000.0" lower="-0.7" upper="0.175" velocity="10"/>
  </joint>
  <link name="/r2/head">
    <visual>
      <geometry>
        <mesh filename="package://r2_description/meshes/Head.dae"/>
      </geometry>
      <origin rpy="0 1.5708 0" xyz="0.0 0.07 0.0074676"/>
    </visual>
    <collision>
      <geometry>
        <mesh filename="package://r2_description/meshes/Head.dae"/>
      </geometry>
      <origin rpy="0 1.5708 0" xyz="0.0 0.07 0.0074676"/>
    </collision>
    <inertial>
      <mass value="5.8503785"/>
      <origin rpy="0 0 0" xyz="0.0048289919 0.074486518 0.013796703"/>
      <inertia ixx="0.045520172" ixy="0.0076844267" ixz="0.0005272352" iyy="0.035519354" iyz="0.001323319" izz="0.044699541"/>
    </inertial>
  </link>
  <joint name="/r2/fixed/neck_roll/vision_base" type="fixed">
    <parent link="/r2/head"/>
    <child link="/r2/vision_base"/>
    <origin rpy=" 1.5708 0.0 0.0 " xyz=" 0.0 -0.058 0.0074676"/>
  </joint>
  <link name="/r2/vision_base">
    <inertial>
      <mass value=".1"/>
      <inertia ixx=".0010" ixy="0.0" ixz="0.0" iyy=".0010" iyz="0.0" izz=".0010"/>
    </inertial>
  </link>
  <joint name="/r2/fixed/vision_base/asus_frame" type="fixed">
    <parent link="/r2/vision_base"/>
    <child link="/r2/asus_frame"/>
    <origin rpy="1.50 0.0 1.5708 " xyz="0.12 -0.015 -0.14 "/>
    <!-- OK    <origin rpy="1.45 0 1.57 " xyz="0.11 -0.040 -0.15 "/>  -->
    <!-- ORIGINAL     <origin rpy="1.57 0 1.57 " xyz="0.066675 -0.0508 -0.116205 "/>  -->
  </joint>
  <joint name="/r2/fixed/vision_base/simulated_asus_frame" type="fixed">
    <parent link="/r2/vision_base"/>
    <child link="/r2/simulated_asus_frame"/>
    <dynamics damping="1.0"/>
    <origin rpy="0 0 0" xyz="0.12 -0.015 -0.14 "/>
  </joint>
  <joint name="/r2/fixed/vision_base/vision_center_frame" type="fixed">
    <parent link="/r2/vision_base"/>
    <child link="/r2/vision_center_frame"/>
    <dynamics damping="1.0"/>
    <origin rpy="1.5708 -1.5708 1.5708" xyz=" 0.066675 0.0 -0.116205 "/>
  </joint>
  <link name="/r2/asus_frame">
    <inertial>
      <mass value=".01"/>
      <inertia ixx=".0010" ixy="0.0" ixz="0.0" iyy=".0010" iyz="0.0" izz=".0010"/>
    </inertial>
  </link>
  <joint name="/r2/fixed/asus_frame/openni_depth_frame" type="fixed">
    <parent link="/r2/asus_frame"/>
    <child link="/r2/openni_depth_frame"/>
    <origin rpy="1.5708 -1.5708 0 " xyz="0 0 0 "/>
  </joint>
  <link name="/r2/openni_depth_frame">
    <inertial>
      <mass value=".01"/>
      <inertia ixx=".0010" ixy="0.0" ixz="0.0" iyy=".0010" iyz="0.0" izz=".0010"/>
    </inertial>
  </link>
  <link name="/r2/simulated_asus_frame">
    <inertial>
      <mass value=".01"/>
      <inertia ixx=".0010" ixy="0.0" ixz="0.0" iyy=".0010" iyz="0.0" izz=".0010"/>
    </inertial>
  </link>
  <link name="/r2/vision_center_frame">
    <inertial>
      <mass value=".1"/>
      <inertia ixx=".0010" ixy="0.0" ixz="0.0" iyy=".0010" iyz="0.0" izz=".0010"/>
    </inertial>
  </link>
  <joint name="/r2/fixed/vision_center_frame/left_camera_frame" type="fixed">
    <parent link="/r2/vision_center_frame"/>
    <child link="/r2/left_camera_frame"/>
    <dynamics damping="1.0"/>
    <origin rpy="0 0 1.5708" xyz="0.0087 0.04887 0.01789"/>
  </joint>
  <joint name="/r2/fixed/vision_center_frame/right_camera_frame" type="fixed">
    <parent link="/r2/vision_center_frame"/>
    <child link="/r2/right_camera_frame"/>
    <dynamics damping="1.0"/>
    <origin rpy="0 0 1.5708" xyz="0.0087 -0.04887 0.01789"/>
  </joint>
  <link name="/r2/left_camera_frame">
    <inertial>
      <mass value=".1"/>
      <inertia ixx=".0010" ixy="0.0" ixz="0.0" iyy=".0010" iyz="0.0" izz=".0010"/>
    </inertial>
  </link>
  <joint name="/r2/fixed/left_camera_frame/left_camera_optical_frame" type="fixed">
    <parent link="/r2/left_camera_frame"/>
    <child link="/r2/left_camera_optical_frame"/>
    <dynamics damping="1.0"/>
    <origin rpy="-1.5708 -1.5708 0" xyz="0 0 0"/>
  </joint>
  <link name="/r2/left_camera_optical_frame">
    <inertial>
      <mass value=".1"/>
      <inertia ixx=".0010" ixy="0.0" ixz="0.0" iyy=".0010" iyz="0.0" izz=".0010"/>
    </inertial>
  </link>
  <link name="/r2/right_camera_frame">
    <inertial>
      <mass value=".1"/>
      <inertia ixx=".0010" ixy="0.0" ixz="0.0" iyy=".0010" iyz="0.0" izz=".0010"/>
    </inertial>
  </link>
  <joint name="/r2/fixed/right_camera_frame/right_camera_optical_frame" type="fixed">
    <parent link="/r2/right_camera_frame"/>
    <child link="/r2/right_camera_optical_frame"/>
    <dynamics damping="1.0"/>
    <origin rpy="-1.5708 -1.5708 0" xyz="0 0 0"/>
  </joint>
  <link name="/r2/right_camera_optical_frame">
    <inertial>
      <mass value=".1"/>
      <inertia ixx=".0010" ixy="0.0" ixz="0.0" iyy=".0010" iyz="0.0" izz=".0010"/>
    </inertial>
  </link>
  <joint name="/r2/left_arm/joint0" type="revolute">
    <parent link="/r2/left_arm/shoulder/jr3"/>
    <child link="/r2/left_shoulder_roll"/>
    <origin rpy="0.0 -1.57079 0.0" xyz="0.0054611 0.0 -0.13041"/>
    <axis xyz="0 0 1"/>
    <dynamics damping="10.0" friction="0.0"/>
    <limit effort="100.0" lower="-2.8270" upper="2.8270" velocity="10"/>
  </joint>
  <link name="/r2/left_shoulder_roll">
    <visual>
      <geometry>
        <mesh filename="package://r2_description/meshes/Left_Shoulder_Upper.dae"/>
      </geometry>
      <material name="dirty_white"/>
      <origin rpy="0.0 0.0 3.1416" xyz="0.0 0.0 -0.01274"/>
    </visual>
    <collision>
      <geometry>
        <mesh filename="package://r2_description/meshes/Left_Shoulder_Upper.dae"/>
      </geometry>
      <origin rpy="0.0 0.0 3.1416" xyz="0.0 0.0 -0.01274"/>
    </collision>
    <inertial>
      <origin xyz="0.00017093234 -0.0087284787   -0.10884506"/>
      <mass value="7.070314"/>
      <inertia ixx="0.076584602" ixy="0.000086319951" ixz="0.00054609047" iyy="0.08016999" iyz="0.0066841031" izz="0.02390013"/>
    </inertial>
  </link>
  <joint name="/r2/left_arm/joint1" type="revolute">
    <parent link="/r2/left_shoulder_roll"/>
    <child link="/r2/left_shoulder_pitch"/>
    <origin rpy=" 0.0 -1.5708 1.5708" xyz=" 0.0 -0.0466596 0.215143 "/>
    <axis xyz="0 0 1"/>
    <dynamics damping="10.0" friction="0.0"/>
    <limit effort="100.0" lower="-1.6758" upper="0.4292" velocity="10"/>
  </joint>
  <link name="/r2/left_shoulder_pitch">
    <visual>
      <geometry>
        <mesh filename="package://r2_description/meshes/Left_Shoulder_Lower.dae"/>
      </geometry>
      <material name="dirty_white"/>
      <origin rpy="0.0 0.0 0.0" xyz="0.0 0.0 -0.0466596"/>
    </visual>
    <collision>
      <geometry>
        <mesh filename="package://r2_description/meshes/Left_Shoulder_Lower.dae"/>
      </geometry>
      <origin rpy="0.0 0.0 0.0" xyz="0.0 0.0 -0.0466596"/>
    </collision>
    <inertial>
      <origin xyz="0.034871718 0.00026989995  -0.056391797"/>
      <mass value="4.7275387"/>
      <inertia ixx="0.01281093" ixy="-0.000025211205" ixz="-0.0019887882" iyy="0.026994354" iyz="-0.000056988895" izz="0.028670313"/>
    </inertial>
  </link>
  <joint name="/r2/left_arm/joint2" type="revolute">
    <parent link="/r2/left_shoulder_pitch"/>
    <child link="/r2/left_upper_arm"/>
    <origin rpy="-1.5708 0.0 -1.5708" xyz="0.169324 0 -0.0458976"/>
    <axis xyz="0 0 1"/>
    <dynamics damping="10.0" friction="0.0"/>
    <limit effort="100.0" lower="-4.5028" upper="-0.3318" velocity="10"/>
  </joint>
  <link name="/r2/left_upper_arm">
    <visual>
      <geometry>
        <mesh filename="package://r2_description/meshes/Left_Upper_Arm.dae"/>
      </geometry>
      <material name="dirty_white"/>
      <origin rpy="0.0 0.0 0.0" xyz="0.0 0.0 -0.067724"/>
    </visual>
    <collision>
      <geometry>
        <mesh filename="package://r2_description/meshes/Left_Upper_Arm.dae"/>
      </geometry>
      <origin rpy="0.0 0.0 0.0" xyz="0.0 0.0 -0.067724"/>
    </collision>
    <inertial>
      <origin xyz="0.011979384 -0.0073390714 0.079871897"/>
      <mass value="4.9025709"/>
      <inertia ixx="0.044036190" ixy="0.0013812407" ixz="-0.0068318982" iyy="0.048358309" iyz="0.0035598559" izz="0.016564943"/>
    </inertial>
  </link>
  <joint name="/r2/left_arm/joint3" type="revolute">
    <parent link="/r2/left_upper_arm"/>
    <child link="/r2/left_elbow"/>
    <origin rpy="0.0 -1.5708 1.5708" xyz="0.05334 -0.0313243 0.185006"/>
    <axis xyz="0 0 1"/>
    <dynamics damping="1.0" friction="0.0"/>
    <limit effort="100.0" lower="-2.7930" upper="0.0" velocity="10"/>
  </joint>
  <link name="/r2/left_elbow">
    <visual>
      <geometry>
        <mesh filename="package://r2_description/meshes/Left_Elbow.dae"/>
      </geometry>
      <material name="dirty_white"/>
      <origin rpy="0 0.0 0" xyz="0 0 -0.0313243"/>
    </visual>
    <collision>
      <geometry>
        <mesh filename="package://r2_description/meshes/Left_Elbow.dae"/>
      </geometry>
      <origin rpy="0 0.0 0" xyz="0.0 0.0 -0.0313243"/>
    </collision>
    <inertial>
      <origin xyz="0.035398630 0.025517855  -0.036241795"/>
      <mass value="2.3377006"/>
      <inertia ixx="0.0067529558" ixy="-0.0026092481" ixz="-0.00060380235" iyy="0.0080987220" iyz="-0.00047453566" izz="0.009863562"/>
    </inertial>
  </link>
  <joint name="/r2/fixed/left_lower_arm/left_forearm_jr3" type="fixed">
    <parent link="/r2/left_elbow"/>
    <child link="/r2/left_arm/forearm/jr3"/>
    <origin rpy="-1.5708 0.7854 1.5708" xyz="0.1976 0.0533 -0.0305"/>
  </joint>
  <link name="/r2/left_arm/forearm/jr3">
    <inertial>
      <mass value="0.01"/>
      <inertia ixx="0.0001" ixy="0.0" ixz="0.0" iyy="0.0001" iyz="0.0" izz="0.0001"/>
    </inertial>
  </link>
  <joint name="/r2/left_arm/joint4" type="revolute">
    <parent link="/r2/left_arm/forearm/jr3"/>
    <child link="/r2/left_lower_arm"/>
    <origin rpy="3.1416 0.0 0.7854" xyz="0.0 0.0 0.1435"/>
    <axis xyz="0 0 1"/>
    <dynamics damping="1.0" friction="0.0"/>
    <limit effort="100.0" lower="-1.5360" upper="4.6770" velocity="10"/>
  </joint>
  <link name="/r2/left_lower_arm">
    <visual>
      <geometry>
        <mesh filename="package://r2_description/meshes/Left_Forearm.dae"/>
      </geometry>
      <origin rpy="0 0 1.5708" xyz="0 0.0 0.0458777"/>
      <material name="dirty_white"/>
    </visual>
    <collision>
      <geometry>
        <mesh filename="package://r2_description/meshes/Left_Forearm.dae"/>
      </geometry>
      <origin rpy="0 0 1.5708" xyz="0 0.0 0.0458777"/>
    </collision>
    <inertial>
      <origin xyz="0.0039950818 0.00044312736  0.16275601"/>
      <mass value="8.1525875"/>
      <inertia ixx="0.10706156" ixy="0.00070538028" ixz="-0.0061176777" iyy="0.11007507" iyz="0.0020551081" izz="0.015240452"/>
    </inertial>
  </link>
  <joint name="/r2/left_arm/wrist/pitch" type="revolute">
    <parent link="/r2/left_lower_arm"/>
    <child link="/r2/left_wrist_pitch"/>
    <origin rpy="0 -1.5708 0.0 " xyz="-0.000616510 0 0.301768"/>
    <axis xyz="0 0 1"/>
    <dynamics damping="1.0" friction="0.0"/>
    <limit effort="100.0" lower="-0.9" upper="0.94" velocity="10"/>
  </joint>
  <link name="/r2/left_wrist_pitch">
    <inertial>
      <origin xyz="0.0  0.0  0.0"/>
      <mass value="0.01"/>
      <inertia ixx="0.0001" ixy="0.0" ixz="0.0" iyy="0.0001" iyz="0.0" izz="0.0001"/>
    </inertial>
  </link>
  <joint name="/r2/left_arm/wrist/yaw" type="revolute">
    <parent link="/r2/left_wrist_pitch"/>
    <child link="/r2/left_wrist_yaw"/>
    <origin rpy="1.5708 0.0652 -0.0802" xyz="0.00635 0 -0.00041451"/>
    <axis xyz="0 0 1"/>
    <dynamics damping="1.0" friction="0.0"/>
    <limit effort="100.0" lower="-0.72" upper="0.23" velocity="10"/>
  </joint>
  <link name="/r2/left_wrist_yaw">
    <inertial>
      <origin xyz="0.0  0.0  0.0"/>
      <mass value="0.01"/>
      <inertia ixx="0.0001" ixy="0.0" ixz="0.0" iyy="0.0001" iyz="0.0" izz="0.0001"/>
    </inertial>
  </link>
  <joint name="/r2/fixed/left_wrist_yaw/left_palm" type="fixed">
    <parent link="/r2/left_wrist_yaw"/>
    <child link="/r2/left_palm"/>
    <origin rpy=" 0.0 0.0 0" xyz=" 0.0 0.0 0.0 "/>
  </joint>
  <link name="/r2/left_palm">
    <visual>
      <geometry>
        <mesh filename="package://r2_description/meshes/Left_Palm.dae"/>
      </geometry>
      <origin rpy="3.1416 0 1.5708" xyz="0.0 0.0 0.0"/>
    </visual>
    <collision>
      <geometry>
        <mesh filename="package://r2_description/meshes/Left_Palm.dae"/>
      </geometry>
      <origin rpy="3.1416 0 1.5708" xyz="0.0 0.0 0.0"/>
    </collision>
    <inertial>
      <mass value="0.01"/>
      <inertia ixx="0.0001" ixy="0.0" ixz="0.0" iyy="0.0001" iyz="0.0" izz="0.0001"/>
    </inertial>
  </link>
  <joint name="/r2/left_arm/hand/thumb/roll" type="revolute">
    <parent link="/r2/left_wrist_yaw"/>
    <child link="/r2/left_thumb_base"/>
    <origin rpy=" -1.5708 0.0 1.30899702752 " xyz=" 0.03302 0.03048 0.00635 "/>
    <axis xyz="0 0 1"/>
    <limit effort="10000000.0" lower="-1.2217" upper="0.0" velocity="10"/>
    <dynamics damping="0.1" friction="0.0"/>
  </joint>
  <joint name="/r2/fixed/left_index_base/left_index_base" type="fixed">
    <parent link="/r2/left_wrist_yaw"/>
    <child link="/r2/left_index_base"/>
    <origin rpy=" 0.0 0.0 0.122172725275 " xyz=" 0.0994646728 0.0271119346 -0.0161544 "/>
  </joint>
  <joint name="/r2/left_arm/hand/index/yaw" type="revolute">
    <parent link="/r2/left_index_base"/>
    <child link="/r2/left_index_yaw"/>
    <origin rpy="0.0 0.0 0.0" xyz="0.0 0.0 0.0"/>
    <axis xyz="0 0 1"/>
    <limit effort="10000000.0" lower="-0.3491" upper="0.3491" velocity="10"/>
    <dynamics damping="0.1" friction="0.0"/>
  </joint>
  <joint name="/r2/fixed/left_middle_base/left_middle_base" type="fixed">
    <parent link="/r2/left_wrist_yaw"/>
    <child link="/r2/left_middle_base"/>
    <origin rpy=" 0.0 0.0 0.0 " xyz=" 0.10646537 0.00254 -0.0161544 "/>
  </joint>
  <joint name="/r2/left_arm/hand/middle/yaw" type="revolute">
    <parent link="/r2/left_middle_base"/>
    <child link="/r2/left_middle_yaw"/>
    <origin rpy="0.0 0.0 0.0" xyz="0.0 0.0 0.0"/>
    <axis xyz="0 0 1"/>
    <limit effort="10000000.0" lower="-0.3491" upper="0.3491" velocity="10"/>
    <dynamics damping="0.1" friction="0.0"/>
  </joint>
  <joint name="/r2/left_arm/hand/ringlittle/ring" type="revolute">
    <parent link="/r2/left_wrist_yaw"/>
    <child link="/r2/left_ring_proximal"/>
    <origin rpy=" 1.5708 -0.0 -0.122172725275 " xyz=" 0.1084570602 -0.0197673468 -0.012319 "/>
    <axis xyz="0 0 1"/>
    <limit effort="10000000.0" lower="0" upper="2.9671" velocity="10"/>
    <dynamics damping="0.1" friction="0.0"/>
  </joint>
  <joint name="/r2/left_arm/hand/ringlittle/little" type="revolute">
    <parent link="/r2/left_wrist_yaw"/>
    <child link="/r2/left_little_proximal"/>
    <origin rpy=" 1.60570321374 -0.0872667473393 -0.17453258148 " xyz=" 0.094635701 -0.0403792436 -0.0060878212 "/>
    <axis xyz="0 0 1"/>
    <limit effort="10000000.0" lower="0" upper="2.9671" velocity="10"/>
    <dynamics damping="0.1" friction="0.0"/>
  </joint>
  <link name="/r2/left_thumb_base">
    <inertial>
      <mass value=".05"/>
      <inertia ixx=".0010" ixy="0.0" ixz="0.0" iyy=".0010" iyz="0.0" izz=".0010"/>
    </inertial>
  </link>
  <joint name="/r2/fixed/left_thumb_base/left_thumb_proximal" type="fixed">
    <parent link="/r2/left_thumb_base"/>
    <child link="/r2/left_thumb_proximal"/>
    <origin rpy=" -1.5708 -0.0 0.0 " xyz=" 0.011938 0.0 0.0 "/>
  </joint>
  <link name="/r2/left_thumb_proximal">
    <inertial>
      <mass value=".0010"/>
      <inertia ixx=".0010" ixy="0.0" ixz="0.0" iyy=".0010" iyz="0.0" izz=".0010"/>
    </inertial>
    <visual>
      <geometry>
        <mesh filename="package://r2_description/meshes/Left_Thumb_Carp.dae"/>
      </geometry>
      <origin rpy="-1.5708 0 0" xyz="-0.01 0.0 0.0"/>
    </visual>
    <collision>
      <geometry>
        <mesh filename="package://r2_description/meshes/Left_Thumb_Carp.dae"/>
      </geometry>
      <origin rpy="-1.5708 0 0" xyz="-0.01 0.0 0.0"/>
    </collision>
  </link>
  <joint name="/r2/left_arm/hand/thumb/proximal" type="revolute">
    <parent link="/r2/left_thumb_proximal"/>
    <child link="/r2/left_thumb_medial_prime"/>
    <origin rpy=" 0.0 0.0 0.0 " xyz=" 0.0 0.0 0.0 "/>
    <axis xyz="0 0 1"/>
    <limit effort="10000000.0" lower="0.0" upper="1.3963" velocity="10"/>
    <dynamics damping="0.1" friction="0.0"/>
  </joint>
  <link name="/r2/left_thumb_medial_prime">
    <inertial>
      <mass value=".0010"/>
      <inertia ixx=".0010" ixy="0.0" ixz="0.0" iyy=".0010" iyz="0.0" izz=".0010"/>
    </inertial>
    <visual>
      <geometry>
        <mesh filename="package://r2_description/meshes/Left_Thumb_MtCar.dae"/>
      </geometry>
      <origin rpy="-1.5708 -1.5708 0" xyz="-0.0 0 0.0"/>
    </visual>
    <collision>
      <geometry>
        <mesh filename="package://r2_description/meshes/Left_Thumb_MtCar.dae"/>
      </geometry>
      <origin rpy="-1.5708 -1.5708 0" xyz="0.0 0.0 0.0"/>
    </collision>
  </link>
  <joint name="/r2/left_arm/hand/thumb/medial" type="revolute">
    <parent link="/r2/left_thumb_medial_prime"/>
    <child link="/r2/left_thumb_medial"/>
    <origin rpy=" -0.698132284627 -0.0 0.0 " xyz=" 0.030734 -0.001905 0.00254 "/>
    <axis xyz="0 0 1"/>
    <limit effort="10000000.0" lower="0.0" upper="1.2217" velocity="10"/>
    <dynamics damping="0.1" friction="0.0"/>
  </joint>
  <link name="/r2/left_thumb_medial">
    <inertial>
      <mass value=".0010"/>
      <inertia ixx=".0010" ixy="0.0" ixz="0.0" iyy=".0010" iyz="0.0" izz=".0010"/>
    </inertial>
    <visual>
      <geometry>
        <mesh filename="package://r2_description/meshes/Thumb_Proximal.dae"/>
      </geometry>
      <origin rpy="3.1416 0 1.5708" xyz="0.0 0.0 0.0"/>
    </visual>
    <collision>
      <geometry>
        <mesh filename="package://r2_description/meshes/Thumb_Proximal.dae"/>
      </geometry>
      <origin rpy="3.1416 0 1.5708" xyz="0.0 0.0 0.0"/>
    </collision>
  </link>
  <joint name="/r2/left_arm/hand/thumb/distal" type="revolute">
    <parent link="/r2/left_thumb_medial"/>
    <child link="/r2/left_thumb_distal"/>
    <origin rpy=" 0.0 0.0 0.0 " xyz=" 0.03937 0.0 0.0 "/>
    <axis xyz="0 0 1"/>
    <limit effort="10000000.0" lower="-0.5236" upper="1.5708" velocity="10"/>
    <dynamics damping="0.1" friction="0.0"/>
  </joint>
  <link name="/r2/left_thumb_distal">
    <inertial>
      <mass value=".0010"/>
      <inertia ixx=".0010" ixy="0.0" ixz="0.0" iyy=".0010" iyz="0.0" izz=".0010"/>
    </inertial>
    <visual>
      <geometry>
        <mesh filename="package://r2_description/meshes/Thumb_Dist.dae"/>
      </geometry>
      <origin rpy="3.1416 3.1416 0" xyz="0.0 0.0 0.0"/>
    </visual>
    <collision>
      <geometry>
        <mesh filename="package://r2_description/meshes/Thumb_Dist.dae"/>
      </geometry>
      <origin rpy="3.1416 3.1416 0" xyz="0.0 0.0 0.0"/>
    </collision>
  </link>
  <joint name="/r2/fixed/left_thumb_distal/left_thumb_tip" type="fixed">
    <parent link="/r2/left_thumb_distal"/>
    <child link="/r2/left_thumb_tip"/>
    <origin rpy=" 0.0 0.0 0.0 " xyz=" 0.03302 0.0 0.0 "/>
  </joint>
  <link name="/r2/left_thumb_tip">
    <inertial>
      <mass value=".0010"/>
      <inertia ixx=".0010" ixy="0.0" ixz="0.0" iyy=".0010" iyz="0.0" izz=".0010"/>
    </inertial>
  </link>
  <link name="/r2/left_index_base">
    <inertial>
      <mass value=".0010"/>
      <inertia ixx=".0010" ixy="0.0" ixz="0.0" iyy=".0010" iyz="0.0" izz=".0010"/>
    </inertial>
  </link>
  <link name="/r2/left_index_yaw">
    <inertial>
      <mass value=".0010"/>
      <inertia ixx=".0010" ixy="0.0" ixz="0.0" iyy=".0010" iyz="0.0" izz=".0010"/>
    </inertial>
  </link>
  <joint name="/r2/left_arm/hand/index/proximal" type="revolute">
    <parent link="/r2/left_index_yaw"/>
    <child link="/r2/left_index_proximal"/>
    <origin rpy=" 1.5708 0.0 0.0 " xyz=" 0.009652 0.0 0.0 "/>
    <axis xyz="0 0 1"/>
    <limit effort="10000000.0" lower="0.0" upper="1.5708" velocity="10"/>
    <dynamics damping="0.1" friction="0.0"/>
  </joint>
  <link name="/r2/left_index_proximal">
    <inertial>
      <mass value=".0010"/>
      <inertia ixx=".0010" ixy="0.0" ixz="0.0" iyy=".0010" iyz="0.0" izz=".0010"/>
    </inertial>
    <visual>
      <geometry>
        <mesh filename="package://r2_description/meshes/Finger_Proximal.dae"/>
      </geometry>
      <origin rpy="0 0 1.5708" xyz="0.0 0.0 0.0"/>
    </visual>
    <collision>
      <geometry>
        <mesh filename="package://r2_description/meshes/Finger_Proximal.dae"/>
      </geometry>
      <origin rpy="0 0 1.5708" xyz="0.0 0.0 0.0"/>
    </collision>
  </link>
  <joint name="/r2/left_arm/hand/index/medial" type="revolute">
    <parent link="/r2/left_index_proximal"/>
    <child link="/r2/left_index_medial"/>
    <origin rpy=" 0.0 0.0 0.0 " xyz=" 0.04445 0.0 0.0 "/>
    <axis xyz="0 0 1"/>
    <limit effort="10000000.0" lower="0.0" upper="1.57" velocity="10"/>
    <dynamics damping="0.1" friction="0.0"/>
  </joint>
  <link name="/r2/left_index_medial">
    <inertial>
      <mass value=".0010"/>
      <inertia ixx=".0010" ixy="0.0" ixz="0.0" iyy=".0010" iyz="0.0" izz=".0010"/>
    </inertial>
    <visual>
      <geometry>
        <mesh filename="package://r2_description/meshes/Finger_Mid.dae"/>
      </geometry>
      <origin rpy="3.1416 0 1.5708" xyz="0.0 0.0 0.0"/>
    </visual>
    <collision>
      <geometry>
        <mesh filename="package://r2_description/meshes/Finger_Mid.dae"/>
      </geometry>
      <origin rpy="3.1416 0 1.5708" xyz="0.0 0.0 0.0"/>
    </collision>
  </link>
  <link name="/r2/left_middle_base">
    <inertial>
      <mass value=".0010"/>
      <inertia ixx=".0010" ixy="0.0" ixz="0.0" iyy=".0010" iyz="0.0" izz=".0010"/>
    </inertial>
  </link>
  <link name="/r2/left_middle_yaw">
    <inertial>
      <mass value=".0010"/>
      <inertia ixx=".0010" ixy="0.0" ixz="0.0" iyy=".0010" iyz="0.0" izz=".0010"/>
    </inertial>
  </link>
  <joint name="/r2/left_arm/hand/middle/proximal" type="revolute">
    <parent link="/r2/left_middle_yaw"/>
    <child link="/r2/left_middle_proximal"/>
    <origin rpy=" 1.5708 0.0 0.0 " xyz=" 0.009652 0.0 0.0 "/>
    <axis xyz="0 0 1"/>
    <limit effort="10000000.0" lower="0.0" upper="1.5708" velocity="10"/>
    <dynamics damping="0.1" friction="0.0"/>
  </joint>
  <link name="/r2/left_middle_proximal">
    <inertial>
      <mass value=".0010"/>
      <inertia ixx=".0010" ixy="0.0" ixz="0.0" iyy=".0010" iyz="0.0" izz=".0010"/>
    </inertial>
    <visual>
      <geometry>
        <mesh filename="package://r2_description/meshes/Finger_Proximal.dae"/>
      </geometry>
      <origin rpy="0 0 1.5708" xyz="0.0 0.0 0.0"/>
    </visual>
    <collision>
      <geometry>
        <mesh filename="package://r2_description/meshes/Finger_Proximal.dae"/>
      </geometry>
      <origin rpy="0 0 1.5708" xyz="0.0 0.0 0.0"/>
    </collision>
  </link>
  <joint name="/r2/left_arm/hand/middle/medial" type="revolute">
    <parent link="/r2/left_middle_proximal"/>
    <child link="/r2/left_middle_medial"/>
    <origin rpy=" 0.0 0.0 0.0 " xyz=" 0.04445 0.0 0.0 "/>
    <axis xyz="0 0 1"/>
    <limit effort="10000000.0" lower="0.0" upper="1.5708" velocity="10"/>
    <dynamics damping="0.1" friction="0.0"/>
  </joint>
  <link name="/r2/left_middle_medial">
    <inertial>
      <mass value=".0010"/>
      <inertia ixx=".0010" ixy="0.0" ixz="0.0" iyy=".0010" iyz="0.0" izz=".0010"/>
    </inertial>
    <visual>
      <geometry>
        <mesh filename="package://r2_description/meshes/Finger_Mid.dae"/>
      </geometry>
      <origin rpy="3.1416 0 1.5708" xyz="0.0 0.0 0.0"/>
    </visual>
    <collision>
      <geometry>
        <mesh filename="package://r2_description/meshes/Finger_Mid.dae"/>
      </geometry>
      <origin rpy="3.1416 0 1.5708" xyz="0.0 0.0 0.0"/>
    </collision>
  </link>
  <link name="/r2/left_ring_proximal">
    <inertial>
      <mass value=".0010"/>
      <inertia ixx=".0010" ixy="0.0" ixz="0.0" iyy=".0010" iyz="0.0" izz=".0010"/>
    </inertial>
    <visual>
      <geometry>
        <mesh filename="package://r2_description/meshes/Finger_Proximal.dae"/>
      </geometry>
      <origin rpy="0 0 1.5708" xyz="0.0 0.0 0.0"/>
    </visual>
    <collision>
      <geometry>
        <mesh filename="package://r2_description/meshes/Finger_Proximal.dae"/>
      </geometry>
      <origin rpy="0 0 1.5708" xyz="0.0 0.0 0.0"/>
    </collision>
  </link>
  <link name="/r2/left_little_proximal">
    <inertial>
      <mass value=".0010"/>
      <inertia ixx=".0010" ixy="0.0" ixz="0.0" iyy=".0010" iyz="0.0" izz=".0010"/>
    </inertial>
    <visual>
      <geometry>
        <mesh filename="package://r2_description/meshes/Finger_Proximal.dae"/>
      </geometry>
      <origin rpy="0 0 1.5708" xyz="0.0 0.0 0.0"/>
    </visual>
    <collision>
      <geometry>
        <mesh filename="package://r2_description/meshes/Finger_Proximal.dae"/>
      </geometry>
      <origin rpy="0 0 1.5708" xyz="0.0 0.0 0.0"/>
    </collision>
  </link>
  <joint name="/r2/right_arm/joint0" type="revolute">
    <parent link="/r2/right_arm/shoulder/jr3"/>
    <child link="/r2/right_shoulder_roll"/>
    <origin rpy="0.0 -1.5708 0.0" xyz="0.0054611 0.0 -0.13041"/>
    <axis xyz="0 0 1"/>
    <dynamics damping="10.0" friction="0.0"/>
    <limit effort="100.0" lower="-2.8270" upper="2.8270" velocity="10"/>
  </joint>
  <link name="/r2/right_shoulder_roll">
    <visual>
      <geometry>
        <mesh filename="package://r2_description/meshes/Right_Shoulder_Upper.dae"/>
      </geometry>
      <material name="dirty_white"/>
      <origin rpy="0.0 0.0 -2.4624" xyz="0.0 0.0 -0.07734"/>
    </visual>
    <collision>
      <geometry>
        <mesh filename="package://r2_description/meshes/Right_Shoulder_Upper.dae"/>
      </geometry>
      <origin rpy="0.0 0.0 -2.4624" xyz="0.0 0.0 -0.07234"/>
    </collision>
    <inertial>
      <origin xyz="0.00017093234 -0.0087284787   -0.10884506"/>
      <mass value="7.070314"/>
      <inertia ixx="0.076584602" ixy="0.000086319951" ixz="0.00054609047" iyy="0.08016999" iyz="0.0066841031" izz="0.02390013"/>
    </inertial>
  </link>
  <joint name="/r2/right_arm/joint1" type="revolute">
    <parent link="/r2/right_shoulder_roll"/>
    <child link="/r2/right_shoulder_pitch"/>
    <origin rpy=" 0.0 -1.5708 1.5708" xyz=" 0.0 -0.0466596 0.215143 "/>
    <axis xyz="0 0 1"/>
    <dynamics damping="10.0" friction="0.0"/>
    <limit effort="100.0" lower="-1.6758" upper="0.4292" velocity="10"/>
  </joint>
  <link name="/r2/right_shoulder_pitch">
    <visual>
      <geometry>
        <mesh filename="package://r2_description/meshes/Right_Shoulder_Lower.dae"/>
      </geometry>
      <material name="dirty_white"/>
      <origin rpy="0.0 0.0 0.0" xyz="0.0 0.0 -0.0466596"/>
    </visual>
    <collision>
      <geometry>
        <mesh filename="package://r2_description/meshes/Right_Shoulder_Lower.dae"/>
      </geometry>
      <origin rpy="0.0 0.0 0.0" xyz="0.0 0.0 -0.0466596"/>
    </collision>
    <inertial>
      <origin xyz="0.034871718 0.00026989995  -0.056391797"/>
      <mass value="4.7275387"/>
      <inertia ixx="0.01281093" ixy="-0.000025211205" ixz="-0.0019887882" iyy="0.026994354" iyz="-0.000056988895" izz="0.028670313"/>
    </inertial>
  </link>
  <joint name="/r2/right_arm/joint2" type="revolute">
    <parent link="/r2/right_shoulder_pitch"/>
    <child link="/r2/right_upper_arm"/>
    <origin rpy="-1.5708 0.0 -1.5708" xyz="0.169324 0 -0.0458976"/>
    <axis xyz="0 0 1"/>
    <dynamics damping="10.0" friction="0.0"/>
    <limit effort="100.0" lower="0.3318" upper="4.5028" velocity="10"/>
  </joint>
  <link name="/r2/right_upper_arm">
    <visual>
      <geometry>
        <mesh filename="package://r2_description/meshes/Right_Upper_Arm.dae"/>
      </geometry>
      <material name="dirty_white"/>
      <origin rpy="0.0 0.0 0.0" xyz="0.0 0.0 -0.067724"/>
    </visual>
    <collision>
      <geometry>
        <mesh filename="package://r2_description/meshes/Right_Upper_Arm.dae"/>
      </geometry>
      <origin rpy="0.0 0.0 0.0" xyz="0.0 0.0 -0.067724"/>
    </collision>
    <inertial>
      <origin xyz="0.011979384 -0.0073390714 0.079871897"/>
      <mass value="4.9025709"/>
      <inertia ixx="0.044036190" ixy="0.0013812407" ixz="-0.0068318982" iyy="0.048358309" iyz="0.0035598559" izz="0.016564943"/>
    </inertial>
  </link>
  <joint name="/r2/right_arm/joint3" type="revolute">
    <parent link="/r2/right_upper_arm"/>
    <child link="/r2/right_elbow"/>
    <origin rpy="0.0 -1.5708 1.5708" xyz="0.05334 -0.0313243 0.185006"/>
    <axis xyz="0 0 1"/>
    <dynamics damping="1.0" friction="0.0"/>
    <limit effort="100.0" lower="-2.7930" upper="0.0" velocity="10"/>
  </joint>
  <link name="/r2/right_elbow">
    <visual>
      <geometry>
        <mesh filename="package://r2_description/meshes/Right_Elbow.dae"/>
      </geometry>
      <material name="dirty_white"/>
      <origin rpy="0 0.0 0" xyz="0 0 -0.0313243"/>
    </visual>
    <collision>
      <geometry>
        <mesh filename="package://r2_description/meshes/Right_Elbow.dae"/>
      </geometry>
      <origin rpy="0 0.0 0" xyz="0 0 -0.0313243"/>
    </collision>
    <inertial>
      <origin xyz="0.035398630 0.025517855  -0.036241795"/>
      <mass value="2.3377006"/>
      <inertia ixx="0.0067529558" ixy="-0.0026092481" ixz="-0.00060380235" iyy="0.0080987220" iyz="-0.00047453566" izz="0.009863562"/>
    </inertial>
  </link>
  <joint name="/r2/fixed/right_lower_arm/right_forearm_jr3" type="fixed">
    <parent link="/r2/right_elbow"/>
    <child link="/r2/right_arm/forearm/jr3"/>
    <origin rpy="-1.5708 0.7854 1.5708" xyz="0.1976 0.0533 -0.0305"/>
  </joint>
  <link name="/r2/right_arm/forearm/jr3">
    <inertial>
      <mass value="0.01"/>
      <inertia ixx="0.0001" ixy="0.0" ixz="0.0" iyy="0.0001" iyz="0.0" izz="0.0001"/>
    </inertial>
  </link>
  <joint name="/r2/right_arm/joint4" type="revolute">
    <parent link="/r2/right_arm/forearm/jr3"/>
    <child link="/r2/right_lower_arm"/>
    <origin rpy="3.1416 0.0 0.7854" xyz="0.0 0.0 0.1435"/>
    <axis xyz="0 0 1"/>
    <dynamics damping="1.0" friction="0.0"/>
    <limit effort="100.0" lower="-4.6770" upper="1.5360" velocity="10"/>
  </joint>
  <link name="/r2/right_lower_arm">
    <visual>
      <geometry>
        <mesh filename="package://r2_description/meshes/Right_Forearm.dae"/>
      </geometry>
      <material name="dirty_white"/>
      <origin rpy="0 0 1.5708" xyz="0 0.0 0.0458777"/>
    </visual>
    <collision>
      <geometry>
        <mesh filename="package://r2_description/meshes/Right_Forearm.dae"/>
      </geometry>
      <origin rpy="0 0 1.5708" xyz="0 0.0 0.0458777"/>
    </collision>
    <inertial>
      <origin xyz="0.0039950818 0.00044312736  0.16275601"/>
      <mass value="8.1525875"/>
      <inertia ixx="0.10706156" ixy="0.00070538028" ixz="-0.0061176777" iyy="0.11007507" iyz="0.0020551081" izz="0.015240452"/>
    </inertial>
  </link>
  <joint name="/r2/right_arm/wrist/pitch" type="revolute">
    <parent link="/r2/right_lower_arm"/>
    <child link="/r2/right_wrist_pitch"/>
    <origin rpy="0 -1.5708 0" xyz="-0.000616510 0 0.301768"/>
    <axis xyz="0 0 1"/>
    <dynamics damping="1.0" friction="0.0"/>
    <limit effort="100.0" lower="-0.9" upper="0.94" velocity="10"/>
  </joint>
  <link name="/r2/right_wrist_pitch">
    <inertial>
      <origin xyz="0.0 0.0 0.0"/>
      <mass value="0.01"/>
      <inertia ixx=".0001" ixy="0.0" ixz="0.0" iyy="0.0001" iyz="0.0" izz="0.0001"/>
    </inertial>
  </link>
  <joint name="/r2/right_arm/wrist/yaw" type="revolute">
    <parent link="/r2/right_wrist_pitch"/>
    <child link="/r2/right_wrist_yaw"/>
    <origin rpy="1.5708 0.0652 -0.0802" xyz="0.00635 0 -0.00041451"/>
    <axis xyz="0 0 1"/>
    <dynamics damping="1.0" friction="0.0"/>
    <limit effort="100.0" lower="-0.23" upper="0.72" velocity="10"/>
  </joint>
  <link name="/r2/right_wrist_yaw">
    <inertial>
      <origin xyz="0.0 0.0 0.0"/>
      <mass value="0.01"/>
      <inertia ixx="0.0001" ixy="0.0" ixz="0.0" iyy="0.0001" iyz="0.0" izz="0.0001"/>
    </inertial>
  </link>
  <joint name="/r2/fixed/right_wrist_yaw/right_palm" type="fixed">
    <parent link="/r2/right_wrist_yaw"/>
    <child link="/r2/right_palm"/>
    <origin rpy=" 0.0 0.0 0" xyz=" 0.0 0.0 0.0"/>
  </joint>
  <link name="/r2/right_palm">
    <visual>
      <geometry>
        <mesh filename="package://r2_description/meshes/Right_Palm.dae"/>
      </geometry>
      <origin rpy="3.1416 0 1.5708" xyz="0.0 0.0 0.0"/>
    </visual>
    <collision>
      <geometry>
        <mesh filename="package://r2_description/meshes/Right_Palm.dae"/>
      </geometry>
      <origin rpy="3.1416 0 1.5708" xyz="0.0 0.0 0.0"/>
    </collision>
    <inertial>
      <mass value="0.01"/>
      <inertia ixx="0.0001" ixy="0.0" ixz="0.0" iyy="0.0001" iyz="0.0" izz="0.0001"/>
    </inertial>
  </link>
  <joint name="/r2/right_arm/hand/thumb/roll" type="revolute">
    <parent link="/r2/right_wrist_yaw"/>
    <child link="/r2/right_thumb_base"/>
    <origin rpy=" 1.5708 0.174532791018 -1.30899687745 " xyz="0.03302 -0.03048 0.00635 "/>
    <axis xyz="0 0 1"/>
    <limit effort="10000000.0" lower="0.0" upper="1.2217" velocity="10"/>
    <dynamics damping="0.1" friction="0.0"/>
  </joint>
  <joint name="/r2/fixed/right_index_base/right_index_base" type="fixed">
    <parent link="/r2/right_wrist_yaw"/>
    <child link="/r2/right_index_base"/>
    <origin rpy=" 0.0 0.0 -0.122172725275  " xyz=" 0.0994646728 -0.0271119346 -0.0161544 "/>
  </joint>
  <joint name="/r2/right_arm/hand/index/yaw" type="revolute">
    <parent link="/r2/right_index_base"/>
    <child link="/r2/right_index_yaw"/>
    <origin rpy="0.0 0.0 0.0" xyz="0.0 0.0 0.0"/>
    <axis xyz="0 0 1"/>
    <limit effort="10000000.0" lower="-0.3491" upper="0.3491" velocity="10"/>
    <dynamics damping="0.1" friction="0.0"/>
  </joint>
  <joint name="/r2/fixed/right_middle_base/right_middle_base" type="fixed">
    <parent link="/r2/right_wrist_yaw"/>
    <child link="/r2/right_middle_base"/>
    <origin rpy=" 0.0 0.0 0.0 " xyz="0.10646537 -0.00254 -0.0161544 "/>
  </joint>
  <joint name="/r2/right_arm/hand/middle/yaw" type="revolute">
    <parent link="/r2/right_middle_base"/>
    <child link="/r2/right_middle_yaw"/>
    <origin rpy="0.0 0.0 0.0" xyz="0.0 0.0 0.0"/>
    <axis xyz="0 0 1"/>
    <limit effort="10000000.0" lower="-0.3491" upper="0.3491" velocity="10"/>
    <dynamics damping="0.1" friction="0.0"/>
  </joint>
  <joint name="/r2/right_arm/hand/ringlittle/ring" type="revolute">
    <parent link="/r2/right_wrist_yaw"/>
    <child link="/r2/right_ring_proximal"/>
    <origin rpy=" 1.57079632679 -0.0 0.122172725275  " xyz=" 0.1084539614 0.019792569 -0.012319 "/>
    <axis xyz="0 0 1"/>
    <limit effort="10000000.0" lower="0" upper="2.9671" velocity="10"/>
    <dynamics damping="0.1" friction="0.0"/>
  </joint>
  <joint name="/r2/right_arm/hand/ringlittle/little" type="revolute">
    <parent link="/r2/right_wrist_yaw"/>
    <child link="/r2/right_little_proximal"/>
    <origin rpy=" 1.53588943985 -0.0872667473393 0.17453258148  " xyz=" 0.094635701 0.0403792436 -0.0060878212 "/>
    <axis xyz="0 0 1"/>
    <limit effort="10000000.0" lower="0" upper="2.9671" velocity="10"/>
    <dynamics damping="0.1" friction="0.0"/>
  </joint>
  <link name="/r2/right_thumb_base">
    <inertial>
      <mass value=".05"/>
      <inertia ixx=".0010" ixy="0.0" ixz="0.0" iyy=".0010" iyz="0.0" izz=".0010"/>
    </inertial>
  </link>
  <joint name="/r2/fixed/right_thumb_base/right_thumb_proximal" type="fixed">
    <parent link="/r2/right_thumb_base"/>
    <child link="/r2/right_thumb_proximal"/>
    <origin rpy=" -1.5708 -0.0 0.0 " xyz=" 0.011938 0.0 0.0 "/>
  </joint>
  <link name="/r2/right_thumb_proximal">
    <inertial>
      <mass value=".05"/>
      <inertia ixx=".0010" ixy="0.0" ixz="0.0" iyy=".0010" iyz="0.0" izz=".0010"/>
    </inertial>
    <visual>
      <geometry>
        <mesh filename="package://r2_description/meshes/Left_Thumb_Carp.dae"/>
      </geometry>
      <origin rpy="-1.5708 0 0" xyz="-0.01 0.0 0.0"/>
    </visual>
    <collision>
      <geometry>
        <mesh filename="package://r2_description/meshes/Left_Thumb_Carp.dae" scale="0.9 0.9 0.9"/>
      </geometry>
      <origin rpy="-1.5708 0 0" xyz="-0.01 0.0 0.0"/>
    </collision>
  </link>
  <joint name="/r2/right_arm/hand/thumb/proximal" type="revolute">
    <parent link="/r2/right_thumb_proximal"/>
    <child link="/r2/right_thumb_medial_prime"/>
    <origin rpy=" 0.0 0.0 0.0 " xyz=" 0.0 0.0 0.0 "/>
    <axis xyz="0 0 1"/>
    <limit effort="10000000.0" lower="0.0" upper="1.3963" velocity="10"/>
    <dynamics damping="0.1" friction="0.0"/>
  </joint>
  <link name="/r2/right_thumb_medial_prime">
    <inertial>
      <mass value=".05"/>
      <inertia ixx=".0010" ixy="0.0" ixz="0.0" iyy=".0010" iyz="0.0" izz=".0010"/>
    </inertial>
    <visual>
      <geometry>
        <mesh filename="package://r2_description/meshes/Right_Thumb_MtCar.dae"/>
      </geometry>
      <origin rpy="-1.5708 -1.5708 0 " xyz="-0.0 0 0.0"/>
    </visual>
    <collision>
      <geometry>
        <mesh filename="package://r2_description/meshes/Right_Thumb_MtCar.dae" scale="0.9 0.9 0.9"/>
      </geometry>
      <origin rpy="-1.5708 -1.5708 0 " xyz="-0.0 0 0.0"/>
    </collision>
  </link>
  <joint name="/r2/right_arm/hand/thumb/medial" type="revolute">
    <parent link="/r2/right_thumb_medial_prime"/>
    <child link="/r2/right_thumb_medial"/>
    <origin rpy=" 0.698132284627 0.0 0.0 " xyz=" 0.030734 -0.001905 -0.00254 "/>
    <axis xyz="0 0 1"/>
    <limit effort="10000000.0" lower="0.0" upper="1.2217" velocity="10"/>
    <dynamics damping="0.1" friction="0.0"/>
  </joint>
  <link name="/r2/right_thumb_medial">
    <inertial>
      <mass value=".05"/>
      <inertia ixx=".0010" ixy="0.0" ixz="0.0" iyy=".0010" iyz="0.0" izz=".0010"/>
    </inertial>
    <visual>
      <geometry>
        <mesh filename="package://r2_description/meshes/Thumb_Proximal.dae"/>
      </geometry>
      <origin rpy="3.1416 0 1.5708" xyz="0.0 0.0 0.0"/>
    </visual>
    <collision>
      <geometry>
        <mesh filename="package://r2_description/meshes/Thumb_Proximal.dae"/>
      </geometry>
      <origin rpy="3.1416 0 1.5708" xyz="0.0 0.0 0.0"/>
    </collision>
  </link>
  <joint name="/r2/right_arm/hand/thumb/distal" type="revolute">
    <parent link="/r2/right_thumb_medial"/>
    <child link="/r2/right_thumb_distal"/>
    <origin rpy=" 0.0 0.0 0.0 " xyz=" 0.03937 0.0 0.0 "/>
    <axis xyz="0 0 1"/>
    <limit effort="10000000.0" lower="-0.5236" upper="1.5708" velocity="10"/>
    <dynamics damping="0.1" friction="0.0"/>
  </joint>
  <link name="/r2/right_thumb_distal">
    <inertial>
      <mass value=".05"/>
      <inertia ixx=".0010" ixy="0.0" ixz="0.0" iyy=".0010" iyz="0.0" izz=".0010"/>
    </inertial>
    <visual>
      <geometry>
        <mesh filename="package://r2_description/meshes/Thumb_Dist.dae"/>
      </geometry>
      <origin rpy="3.1416 3.1416 0" xyz="0.0 0.0 0.0"/>
    </visual>
    <collision>
      <geometry>
        <mesh filename="package://r2_description/meshes/Thumb_Dist.dae"/>
      </geometry>
      <origin rpy="3.1416 3.1416 0" xyz="0.0 0.0 0.0"/>
    </collision>
  </link>
  <joint name="/r2/fixed/right_thumb_distal/right_thumb_tip" type="fixed">
    <parent link="/r2/right_thumb_distal"/>
    <child link="/r2/right_thumb_tip"/>
    <origin rpy=" 0.0 0.0 0.0 " xyz=" 0.03302 0.0 0.0 "/>
  </joint>
  <link name="/r2/right_thumb_tip">
    <inertial>
      <mass value=".05"/>
      <inertia ixx=".0010" ixy="0.0" ixz="0.0" iyy=".0010" iyz="0.0" izz=".0010"/>
    </inertial>
  </link>
  <link name="/r2/right_index_base">
    <inertial>
      <mass value=".05"/>
      <inertia ixx=".0010" ixy="0.0" ixz="0.0" iyy=".0010" iyz="0.0" izz=".0010"/>
    </inertial>
  </link>
  <link name="/r2/right_index_yaw">
    <inertial>
      <mass value=".05"/>
      <inertia ixx=".0010" ixy="0.0" ixz="0.0" iyy=".0010" iyz="0.0" izz=".0010"/>
    </inertial>
  </link>
  <joint name="/r2/right_arm/hand/index/proximal" type="revolute">
    <parent link="/r2/right_index_yaw"/>
    <child link="/r2/right_index_proximal"/>
    <origin rpy=" 1.5708 -0.0 0.0 " xyz=" 0.009652 0.0 0.0 "/>
    <axis xyz="0 0 1"/>
    <limit effort="10000000.0" lower="0.0" upper="1.5708" velocity="10"/>
    <dynamics damping="0.1" friction="0.0"/>
  </joint>
  <link name="/r2/right_index_proximal">
    <inertial>
      <mass value=".05"/>
      <inertia ixx=".0010" ixy="0.0" ixz="0.0" iyy=".0010" iyz="0.0" izz=".0010"/>
    </inertial>
    <visual>
      <geometry>
        <mesh filename="package://r2_description/meshes/Finger_Proximal.dae"/>
      </geometry>
      <origin rpy="0 0 1.5708" xyz="0.0 0.0 0.0"/>
    </visual>
    <collision>
      <geometry>
        <mesh filename="package://r2_description/meshes/Finger_Proximal.dae"/>
      </geometry>
      <origin rpy="0 0 1.5708" xyz="0.0 0.0 0.0"/>
    </collision>
  </link>
  <joint name="/r2/right_arm/hand/index/medial" type="revolute">
    <parent link="/r2/right_index_proximal"/>
    <child link="/r2/right_index_medial"/>
    <origin rpy=" 0.0 0.0 0.0 " xyz=" 0.04445 0.0 0.0 "/>
    <axis xyz="0 0 1"/>
    <limit effort="10000000.0" lower="0.0" upper="1.5708" velocity="10"/>
    <dynamics damping="0.1" friction="0.0"/>
  </joint>
  <link name="/r2/right_index_medial">
    <inertial>
      <mass value=".05"/>
      <inertia ixx=".0010" ixy="0.0" ixz="0.0" iyy=".0010" iyz="0.0" izz=".0010"/>
    </inertial>
    <visual>
      <geometry>
        <mesh filename="package://r2_description/meshes/Finger_Mid.dae"/>
      </geometry>
      <origin rpy="3.1416 0 1.5708" xyz="0.0 0.0 0.0"/>
    </visual>
    <collision>
      <geometry>
        <mesh filename="package://r2_description/meshes/Finger_Mid.dae"/>
      </geometry>
      <origin rpy="3.1416 0 1.5708" xyz="0.0 0.0 0.0"/>
    </collision>
  </link>
  <link name="/r2/right_middle_base">
    <inertial>
      <mass value=".0010"/>
      <inertia ixx=".0010" ixy="0.0" ixz="0.0" iyy=".0010" iyz="0.0" izz=".0010"/>
    </inertial>
  </link>
  <link name="/r2/right_middle_yaw">
    <inertial>
      <mass value=".0010"/>
      <inertia ixx=".0010" ixy="0.0" ixz="0.0" iyy=".0010" iyz="0.0" izz=".0010"/>
    </inertial>
  </link>
  <joint name="/r2/right_arm/hand/middle/proximal" type="revolute">
    <parent link="/r2/right_middle_yaw"/>
    <child link="/r2/right_middle_proximal"/>
    <origin rpy=" 1.5708 -0.0 0.0 " xyz=" 0.009652 0.0 0.0 "/>
    <axis xyz="0 0 1"/>
    <limit effort="10000000.0" lower="0.0" upper="1.5708" velocity="10"/>
    <dynamics damping="0.1" friction="0.0"/>
  </joint>
  <link name="/r2/right_middle_proximal">
    <inertial>
      <mass value=".05"/>
      <inertia ixx=".0010" ixy="0.0" ixz="0.0" iyy=".0010" iyz="0.0" izz=".0010"/>
    </inertial>
    <visual>
      <geometry>
        <mesh filename="package://r2_description/meshes/Finger_Proximal.dae"/>
      </geometry>
      <origin rpy="0 0 1.5708" xyz="0.0 0.0 0.0"/>
    </visual>
    <collision>
      <geometry>
        <mesh filename="package://r2_description/meshes/Finger_Proximal.dae" scale="0.9 0.9 0.9"/>
      </geometry>
      <origin rpy="0 0 1.5708" xyz="0.0 0.0 0.0"/>
    </collision>
  </link>
  <joint name="/r2/right_arm/hand/middle/medial" type="revolute">
    <parent link="/r2/right_middle_proximal"/>
    <child link="/r2/right_middle_medial"/>
    <origin rpy=" 0.0 0.0 0.0 " xyz=" 0.04445 0.0 0.0 "/>
    <axis xyz="0 0 1"/>
    <limit effort="10000000.0" lower="0.0" upper="1.57" velocity="10"/>
    <dynamics damping="0.1" friction="0.0"/>
  </joint>
  <link name="/r2/right_middle_medial">
    <inertial>
      <mass value=".05"/>
      <inertia ixx=".0010" ixy="0.0" ixz="0.0" iyy=".0010" iyz="0.0" izz=".0010"/>
    </inertial>
    <visual>
      <geometry>
        <mesh filename="package://r2_description/meshes/Finger_Mid.dae"/>
      </geometry>
      <origin rpy="3.1416 0 1.5708" xyz="0.0 0.0 0.0"/>
    </visual>
    <collision>
      <geometry>
        <mesh filename="package://r2_description/meshes/Finger_Mid.dae" scale="0.9 0.9 0.9"/>
      </geometry>
      <origin rpy="3.1416 0 1.5708" xyz="0.0 0.0 0.0"/>
    </collision>
  </link>
  <link name="/r2/right_ring_proximal">
    <inertial>
      <mass value=".05"/>
      <inertia ixx=".0010" ixy="0.0" ixz="0.0" iyy=".0010" iyz="0.0" izz=".0010"/>
    </inertial>
    <visual>
      <geometry>
        <mesh filename="package://r2_description/meshes/Finger_Proximal.dae"/>
      </geometry>
      <origin rpy="0 0 1.5708" xyz="0.0 0.0 0.0"/>
    </visual>
    <collision>
      <geometry>
        <mesh filename="package://r2_description/meshes/Finger_Proximal.dae" scale="0.9 0.9 0.9"/>
      </geometry>
      <origin rpy="0 0 1.5708" xyz="0.0 0.0 0.0"/>
    </collision>
  </link>
  <link name="/r2/right_little_proximal">
    <inertial>
      <mass value=".05"/>
      <inertia ixx=".0010" ixy="0.0" ixz="0.0" iyy=".0010" iyz="0.0" izz=".0010"/>
    </inertial>
    <visual>
      <geometry>
        <mesh filename="package://r2_description/meshes/Finger_Proximal.dae"/>
      </geometry>
      <origin rpy="0 0 1.5708" xyz="0.0 0.0 0.0"/>
    </visual>
    <collision>
      <geometry>
        <mesh filename="package://r2_description/meshes/Finger_Proximal.dae" scale="0.9 0.9 0.9"/>
      </geometry>
      <origin rpy="0 0 1.5708" xyz="0.0 0.0 0.0"/>
    </collision>
  </link>
  <gazebo reference="/r2/waist_center">
    <selfCollide>false</selfCollide>
    <static>false</static>
    <turnGravityOff>false</turnGravityOff>
  </gazebo>
  <gazebo reference="/r2/waist/joint0">
    <stopKd value="1.0"/>
    <stopKp value="1000000.0"/>
  </gazebo>
  <gazebo reference="/r2/left_shoulder_roll">
    <selfCollide>false</selfCollide>
    <static>false</static>
    <turnGravityOff>false</turnGravityOff>
  </gazebo>
  <gazebo reference="/r2/left_shoulder_pitch">
    <selfCollide>false</selfCollide>
    <static>false</static>
    <turnGravityOff>false</turnGravityOff>
  </gazebo>
  <gazebo reference="/r2/left_upper_arm">
    <selfCollide>false</selfCollide>
    <static>false</static>
    <turnGravityOff>false</turnGravityOff>
  </gazebo>
  <gazebo reference="/r2/left_elbow">
    <selfCollide>false</selfCollide>
    <static>false</static>
    <turnGravityOff>false</turnGravityOff>
  </gazebo>
  <gazebo reference="/r2/left_lower_arm">
    <selfCollide>false</selfCollide>
    <static>false</static>
    <turnGravityOff>false</turnGravityOff>
  </gazebo>
  <gazebo reference="/r2/left_wrist_pitch">
    <selfCollide>false</selfCollide>
    <static>false</static>
    <turnGravityOff>false</turnGravityOff>
  </gazebo>
  <gazebo reference="/r2/left_wrist_yaw">
    <selfCollide>false</selfCollide>
    <static>false</static>
    <turnGravityOff>false</turnGravityOff>
  </gazebo>
  <gazebo reference="/r2/left_palm">
    <selfCollide>false</selfCollide>
    <static>false</static>
    <turnGravityOff>false</turnGravityOff>
  </gazebo>
  <gazebo reference="/r2/left_arm/joint0">
    <stopKd value="1.0"/>
    <stopKp value="1000000.0"/>
  </gazebo>
  <gazebo reference="/r2/left_arm/joint1">
    <stopKd value="1.0"/>
    <stopKp value="1000000.0"/>
  </gazebo>
  <gazebo reference="/r2/left_arm/joint2">
    <stopKd value="1.0"/>
    <stopKp value="1000000.0"/>
  </gazebo>
  <gazebo reference="/r2/left_arm/joint3">
    <stopKd value="1.0"/>
    <stopKp value="1000000.0"/>
  </gazebo>
  <gazebo reference="/r2/left_arm/joint4">
    <stopKd value="1.0"/>
    <stopKp value="1000000.0"/>
  </gazebo>
  <gazebo reference="/r2/left_arm/joint5">
    <stopKd value="1.0"/>
    <stopKp value="1000000.0"/>
  </gazebo>
  <gazebo reference="/r2/left_arm/joint6">
    <stopKd value="1.0"/>
    <stopKp value="1000000.0"/>
  </gazebo>
  <gazebo reference="/r2/left_thumb_base">
    <selfCollide>false</selfCollide>
    <static>false</static>
    <turnGravityOff>false</turnGravityOff>
  </gazebo>
  <gazebo reference="/r2/left_thumb_medial_prime">
    <selfCollide>false</selfCollide>
    <static>false</static>
    <turnGravityOff>false</turnGravityOff>
  </gazebo>
  <gazebo reference="/r2/left_thumb_medial">
    <selfCollide>false</selfCollide>
    <static>false</static>
    <turnGravityOff>false</turnGravityOff>
  </gazebo>
  <gazebo reference="/r2/left_thumb_distal">
    <selfCollide>false</selfCollide>
    <static>false</static>
    <turnGravityOff>false</turnGravityOff>
  </gazebo>
  <gazebo reference="/r2/left_index_base">
    <selfCollide>false</selfCollide>
    <static>false</static>
    <turnGravityOff>false</turnGravityOff>
  </gazebo>
  <gazebo reference="/r2/left_index_proximal">
    <selfCollide>false</selfCollide>
    <static>false</static>
    <turnGravityOff>false</turnGravityOff>
  </gazebo>
  <gazebo reference="/r2/left_index_medial">
    <selfCollide>false</selfCollide>
    <static>false</static>
    <turnGravityOff>false</turnGravityOff>
  </gazebo>
  <gazebo reference="/r2/left_index_distal">
    <selfCollide>false</selfCollide>
    <static>false</static>
    <turnGravityOff>false</turnGravityOff>
  </gazebo>
  <gazebo reference="/r2/left_middle_base">
    <selfCollide>false</selfCollide>
    <static>false</static>
    <turnGravityOff>false</turnGravityOff>
  </gazebo>
  <gazebo reference="/r2/left_middle_proximal">
    <selfCollide>false</selfCollide>
    <static>false</static>
    <turnGravityOff>false</turnGravityOff>
  </gazebo>
  <gazebo reference="/r2/left_middle_medial">
    <selfCollide>false</selfCollide>
    <static>false</static>
    <turnGravityOff>false</turnGravityOff>
  </gazebo>
  <gazebo reference="/r2/left_middle_distal">
    <selfCollide>false</selfCollide>
    <static>false</static>
    <turnGravityOff>false</turnGravityOff>
  </gazebo>
  <gazebo reference="/r2/left_ring_proximal">
    <selfCollide>false</selfCollide>
    <static>false</static>
    <turnGravityOff>false</turnGravityOff>
  </gazebo>
  <gazebo reference="/r2/left_ring_medial">
    <selfCollide>false</selfCollide>
    <static>false</static>
    <turnGravityOff>false</turnGravityOff>
  </gazebo>
  <gazebo reference="/r2/left_ring_distal">
    <selfCollide>false</selfCollide>
    <static>false</static>
    <turnGravityOff>false</turnGravityOff>
  </gazebo>
  <gazebo reference="/r2/left_little_proximal">
    <selfCollide>false</selfCollide>
    <static>false</static>
    <turnGravityOff>false</turnGravityOff>
  </gazebo>
  <gazebo reference="/r2/left_little_medial">
    <selfCollide>false</selfCollide>
    <static>false</static>
    <turnGravityOff>false</turnGravityOff>
  </gazebo>
  <gazebo reference="/r2/left_little_distal">
    <selfCollide>false</selfCollide>
    <static>false</static>
    <turnGravityOff>false</turnGravityOff>
  </gazebo>
  <gazebo reference="/r2/right_shoulder_roll">
    <selfCollide>false</selfCollide>
    <static>false</static>
    <turnGravityOff>false</turnGravityOff>
  </gazebo>
  <gazebo reference="/r2/right_shoulder_pitch">
    <selfCollide>false</selfCollide>
    <static>false</static>
    <turnGravityOff>false</turnGravityOff>
  </gazebo>
  <gazebo reference="/r2/right_upper_arm">
    <selfCollide>false</selfCollide>
    <static>false</static>
    <turnGravityOff>false</turnGravityOff>
  </gazebo>
  <gazebo reference="/r2/right_elbow">
    <selfCollide>false</selfCollide>
    <static>false</static>
    <turnGravityOff>false</turnGravityOff>
  </gazebo>
  <gazebo reference="/r2/right_lower_arm">
    <selfCollide>false</selfCollide>
    <static>false</static>
    <turnGravityOff>false</turnGravityOff>
  </gazebo>
  <gazebo reference="/r2/right_wrist_pitch">
    <selfCollide>false</selfCollide>
    <static>false</static>
    <turnGravityOff>false</turnGravityOff>
  </gazebo>
  <gazebo reference="/r2/right_wrist_yaw">
    <selfCollide>false</selfCollide>
    <static>false</static>
    <turnGravityOff>false</turnGravityOff>
  </gazebo>
  <gazebo reference="/r2/right_palm">
    <selfCollide>false</selfCollide>
    <static>false</static>
    <turnGravityOff>false</turnGravityOff>
  </gazebo>
  <gazebo reference="/r2/right_arm/joint0">
    <stopKd value="1.0"/>
    <stopKp value="1000000.0"/>
  </gazebo>
  <gazebo reference="/r2/right_arm/joint1">
    <stopKd value="1.0"/>
    <stopKp value="1000000.0"/>
  </gazebo>
  <gazebo reference="/r2/right_arm/joint2">
    <stopKd value="1.0"/>
    <stopKp value="1000000.0"/>
  </gazebo>
  <gazebo reference="/r2/right_arm/joint3">
    <stopKd value="1.0"/>
    <stopKp value="1000000.0"/>
  </gazebo>
  <gazebo reference="/r2/right_arm/joint4">
    <stopKd value="1.0"/>
    <stopKp value="1000000.0"/>
  </gazebo>
  <gazebo reference="/r2/right_arm/joint5">
    <stopKd value="1.0"/>
    <stopKp value="1000000.0"/>
  </gazebo>
  <gazebo reference="/r2/right_arm/joint6">
    <stopKd value="1.0"/>
    <stopKp value="1000000.0"/>
  </gazebo>
  <gazebo reference="/r2/right_thumb_base">
    <selfCollide>false</selfCollide>
    <static>false</static>
    <turnGravityOff>false</turnGravityOff>
  </gazebo>
  <gazebo reference="/r2/right_thumb_medial_prime">
    <selfCollide>false</selfCollide>
    <static>false</static>
    <turnGravityOff>false</turnGravityOff>
  </gazebo>
  <gazebo reference="/r2/right_thumb_medial">
    <selfCollide>false</selfCollide>
    <static>false</static>
    <turnGravityOff>false</turnGravityOff>
  </gazebo>
  <gazebo reference="/r2/right_thumb_distal">
    <selfCollide>false</selfCollide>
    <static>false</static>
    <turnGravityOff>false</turnGravityOff>
  </gazebo>
  <gazebo reference="/r2/right_index_base">
    <selfCollide>false</selfCollide>
    <static>false</static>
    <turnGravityOff>false</turnGravityOff>
  </gazebo>
  <gazebo reference="/r2/right_index_proximal">
    <selfCollide>false</selfCollide>
    <static>false</static>
    <turnGravityOff>false</turnGravityOff>
  </gazebo>
  <gazebo reference="/r2/right_index_medial">
    <selfCollide>false</selfCollide>
    <static>false</static>
    <turnGravityOff>false</turnGravityOff>
  </gazebo>
  <gazebo reference="/r2/right_index_distal">
    <selfCollide>false</selfCollide>
    <static>false</static>
    <turnGravityOff>false</turnGravityOff>
  </gazebo>
  <gazebo reference="/r2/right_middle_base">
    <selfCollide>false</selfCollide>
    <static>false</static>
    <turnGravityOff>false</turnGravityOff>
  </gazebo>
  <gazebo reference="/r2/right_middle_proximal">
    <selfCollide>false</selfCollide>
    <static>false</static>
    <turnGravityOff>false</turnGravityOff>
  </gazebo>
  <gazebo reference="/r2/right_middle_medial">
    <selfCollide>false</selfCollide>
    <static>false</static>
    <turnGravityOff>false</turnGravityOff>
  </gazebo>
  <gazebo reference="/r2/right_middle_distal">
    <selfCollide>false</selfCollide>
    <static>false</static>
    <turnGravityOff>false</turnGravityOff>
  </gazebo>
  <gazebo reference="/r2/right_ring_proximal">
    <selfCollide>false</selfCollide>
    <static>false</static>
    <turnGravityOff>false</turnGravityOff>
  </gazebo>
  <gazebo reference="/r2/right_ring_medial">
    <selfCollide>false</selfCollide>
    <static>false</static>
    <turnGravityOff>false</turnGravityOff>
  </gazebo>
  <gazebo reference="/r2/right_ring_distal">
    <selfCollide>false</selfCollide>
    <static>false</static>
    <turnGravityOff>false</turnGravityOff>
  </gazebo>
  <gazebo reference="/r2/right_little_proximal">
    <selfCollide>false</selfCollide>
    <static>false</static>
    <turnGravityOff>false</turnGravityOff>
  </gazebo>
  <gazebo reference="/r2/right_little_medial">
    <selfCollide>false</selfCollide>
    <static>false</static>
    <turnGravityOff>false</turnGravityOff>
  </gazebo>
  <gazebo reference="/r2/right_little_distal">
    <selfCollide>false</selfCollide>
    <static>false</static>
    <turnGravityOff>false</turnGravityOff>
  </gazebo>
  <gazebo reference="/r2/neck_base">
    <selfCollide>false</selfCollide>
    <static>false</static>
    <turnGravityOff>false</turnGravityOff>
  </gazebo>
  <gazebo reference="/r2/neck/joint0">
    <stopKd value="1.0"/>
    <stopKp value="1000000.0"/>
  </gazebo>
  <gazebo reference="/r2/neck_lower_pitch">
    <selfCollide>false</selfCollide>
    <static>false</static>
    <turnGravityOff>false</turnGravityOff>
  </gazebo>
  <gazebo reference="/r2/neck/joint1">
    <stopKd value="1.0"/>
    <stopKp value="1000000.0"/>
  </gazebo>
  <gazebo reference="/r2/neck_roll">
    <selfCollide>false</selfCollide>
    <static>false</static>
    <turnGravityOff>false</turnGravityOff>
  </gazebo>
  <gazebo reference="/r2/neck/joint2">
    <stopKd value="1.0"/>
    <stopKp value="1000000.0"/>
  </gazebo>
  <gazebo reference="/r2/left_camera_optical_frame">
    <sensor:camera name="/r2/neck/head/camera0">
      <imageSize>1600 1200</imageSize>
      <imageFormat>R8G8B8</imageFormat>
      <hfov>90</hfov>
      <nearClip>0.10</nearClip>
      <farClip>50</farClip>
      <updateRate>10.0</updateRate>
      <controller:gazebo_ros_prosilica name="/r2/neck/head/camera0_controller" plugin="libgazebo_ros_prosilica.so">
        <alwaysOn>true</alwaysOn>
        <updateRate>20.0</updateRate>
        <cameraName>/r2/neck/head/camera0</cameraName>
        <imageTopicName>image_raw</imageTopicName>
        <cameraInfoTopicName>camera_info</cameraInfoTopicName>
        <pollServiceName>request_image</pollServiceName>
        <frameName>/r2/left_camera_optical_frame</frameName>
        <CxPrime>1224.5</CxPrime>
        <Cx>802.4</Cx>
        <Cy>603.2</Cy>
        <focalLength>8330</focalLength>
        <distortionK1>0.00000001</distortionK1>
        <distortionK2>0.00000001</distortionK2>
        <distortionK3>0.00000001</distortionK3>
        <distortionT1>0.00000001</distortionT1>
        <distortionT2>0.00000001</distortionT2>
        <interface:camera name="/r2/neck/head/camera0_iface"/>
      </controller:gazebo_ros_prosilica>
    </sensor:camera>
    <turnGravityOff>false</turnGravityOff>
    <material>Gazebo/White</material>
  </gazebo>
  <gazebo reference="/r2/right_camera_optical_frame">
    <sensor:camera name="/r2/neck/head/camera1">
      <imageSize>1600 1200</imageSize>
      <imageFormat>R8G8B8</imageFormat>
      <hfov>90</hfov>
      <nearClip>0.10</nearClip>
      <farClip>50</farClip>
      <updateRate>10.0</updateRate>
      <controller:gazebo_ros_prosilica name="/r2/neck/head/camera1_controller" plugin="libgazebo_ros_prosilica.so">
        <alwaysOn>true</alwaysOn>
        <updateRate>20.0</updateRate>
        <cameraName>/r2/neck/head/camera1</cameraName>
        <imageTopicName>image_raw</imageTopicName>
        <cameraInfoTopicName>camera_info</cameraInfoTopicName>
        <pollServiceName>request_image</pollServiceName>
        <frameName>/r2/right_camera_optical_frame</frameName>
        <CxPrime>1224.5</CxPrime>
        <Cx>802.4</Cx>
        <Cy>603.2</Cy>
        <focalLength>8330</focalLength>
        <distortionK1>0.00000001</distortionK1>
        <distortionK2>0.00000001</distortionK2>
        <distortionK3>0.00000001</distortionK3>
        <distortionT1>0.00000001</distortionT1>
        <distortionT2>0.00000001</distortionT2>
        <interface:camera name="/r2/neck/head/camera1_iface"/>
      </controller:gazebo_ros_prosilica>
    </sensor:camera>
    <turnGravityOff>false</turnGravityOff>
    <material>Gazebo/White</material>
  </gazebo>
  <joint name="asus_ir_joint" type="fixed">
    <!-- <origin xyz="-0.032267 0.0125 0.136453" rpy="0 0 0"/> -->
    <origin rpy="0 0 0" xyz="0 0 0"/>
    <parent link="/r2/simulated_asus_frame"/>
    <child link="asus_ir_link"/>
  </joint>
  <link name="asus_ir_link">
    <inertial>
      <mass value="0.1"/>
      <origin rpy="0 0 0" xyz="0 0 0"/>
      <inertia ixx="0.01" ixy="0.0" ixz="0.0" iyy="0.01" iyz="0.0" izz="0.01"/>
    </inertial>
  </link>
  <joint name="asus_ir_optical_frame_joint" type="fixed">
    <origin rpy="-1.57 0 -1.57" xyz="0 0 0"/>
    <!-- this works for non-rgb 3d data... -->
    <parent link="asus_ir_link"/>
    <child link="asus_ir_optical_frame"/>
  </joint>
  <link name="asus_ir_optical_frame">
    <inertial>
      <mass value=".1"/>
      <inertia ixx=".0010" ixy="0.0" ixz="0.0" iyy=".0010" iyz="0.0" izz=".0010"/>
    </inertial>
  </link>
  <gazebo reference="asus_ir_link">
    <sensor:camera name="asus/ir">
      <imageFormat>L8</imageFormat>
      <imageSize>640 480</imageSize>
      <hfov>57</hfov>
      <nearClip>0.01</nearClip>
      <farClip>5</farClip>
      <updateRate>1.0</updateRate>
      <baseline>0.2</baseline>
      <controller:gazebo_ros_openni_kinect name="asus_ir_link_controller" plugin="libgazebo_ros_openni_kinect.so">
        <alwaysOn>true</alwaysOn>
        <updateRate>1.0</updateRate>
        <cameraName>/r2/neck/head/range_camera0/ir</cameraName>
        <imageTopicName>//r2/neck/head/range_camera0/depth/image_raw</imageTopicName>
        <cameraInfoTopicName>//r2/neck/head/range_camera0/depth/camera_info</cameraInfoTopicName>
        <depthImageTopicName>//r2/neck/head/range_camera0/depth/image_raw</depthImageTopicName>
        <depthImageInfoTopicName>//r2/neck/head/range_camera0/depth/camera_info</depthImageInfoTopicName>
        <pointCloudTopicName>//r2/neck/head/range_camera0/depth/points</pointCloudTopicName>
        <frameName>asus_ir_optical_frame</frameName>
        <pointCloudCutoff>0.5</pointCloudCutoff>
        <distortionK1>0.00000001</distortionK1>
        <distortionK2>0.00000001</distortionK2>
        <distortionK3>0.00000001</distortionK3>
        <distortionT1>0.00000001</distortionT1>
        <distortionT2>0.00000001</distortionT2>
      </controller:gazebo_ros_openni_kinect>
    </sensor:camera>
    <material value="Gazebo/Red"/>
  </gazebo>
  <joint name="asus_rgb_joint" type="fixed">
    <origin rpy="3.14 0 0" xyz="0 -0.03 0"/>
    <parent link="asus_ir_link"/>
    <child link="asus_rgb_link"/>
  </joint>
  <link name="asus_rgb_link">
    <inertial>
      <mass value=".1"/>
      <inertia ixx=".0010" ixy="0.0" ixz="0.0" iyy=".0010" iyz="0.0" izz=".0010"/>
    </inertial>
  </link>
  <joint name="asus_rgb_optical_frame_joint" type="fixed">
    <origin rpy="-1.57 0 -1.57" xyz="0 0 0"/>
    <parent link="asus_rgb_link"/>
    <child link="asus_rgb_optical_frame"/>
  </joint>
  <link name="asus_rgb_optical_frame">
    <inertial>
      <mass value=".1"/>
      <inertia ixx=".0010" ixy="0.0" ixz="0.0" iyy=".0010" iyz="0.0" izz=".0010"/>
    </inertial>
  </link>
  <gazebo reference="asus_rgb_link">
    <sensor:camera name="asus/rgb">
      <imageFormat>R8G8B8</imageFormat>
      <imageSize>640 480</imageSize>
      <hfov>57</hfov>
      <nearClip>0.01</nearClip>
      <farClip>5</farClip>
      <updateRate>1.0</updateRate>
      <baseline>0.2</baseline>
      <controller:gazebo_ros_openni_kinect name="asus_rgb_link_controller" plugin="libgazebo_ros_openni_kinect.so">
        <alwaysOn>true</alwaysOn>
        <updateRate>1.0</updateRate>
        <cameraName>/r2/neck/head/range_camera0/rgb</cameraName>
        <imageTopicName>//r2/neck/head/range_camera0/rgb/image_raw</imageTopicName>
        <cameraInfoTopicName>//r2/neck/head/range_camera0/rgb/camera_info</cameraInfoTopicName>
        <pointCloudTopicName>//r2/neck/head/range_camera0/depth_registered/points</pointCloudTopicName>
        <frameName>asus_rgb_optical_frame</frameName>
        <pointCloudCutoff>0.5</pointCloudCutoff>
        <distortionK1>0.00000001</distortionK1>
        <distortionK2>0.00000001</distortionK2>
        <distortionK3>0.00000001</distortionK3>
        <distortionT1>0.00000001</distortionT1>
        <distortionT2>0.00000001</distortionT2>
      </controller:gazebo_ros_openni_kinect>
    </sensor:camera>
    <material value="Gazebo/Red"/>
  </gazebo>
  <gazebo>
    <controller:gazebo_interface name="gazebo_interface" plugin="libgazebo_interface.so">
      <!--      <robotNamespace>/r2sim</robotNamespace>-->
      <paramsNamespace>r2_sim_params</paramsNamespace>
      <jointCommandsTopic>joint_commands</jointCommandsTopic>
      <jointStatesTopic>joint_states</jointStatesTopic>
      <jointCapabilitiesTopic>joint_capabilities</jointCapabilitiesTopic>
      <jointCommandRefsTopic>joint_command_refs</jointCommandRefsTopic>
      <jointStatesRate>50.0</jointStatesRate>
      <!--Hz, omit for fastest possible-->
      <advancedMode>false</advancedMode>
      <!-- if advancedMode=false, joint brakes, etc are not simulated and the following parameters are ignored -->
      <jointControlTopic>joint_control</jointControlTopic>
      <jointStatusTopic>joint_status</jointStatusTopic>
      <jointStatusRate>5.0</jointStatusRate>
      <!--Hz, omit for fastest possible-->
    </controller:gazebo_interface>
  </gazebo>
</robot>

