<?xml version="1.0" ?>
<!-- =================================================================================== -->
<!-- |    This document was autogenerated by xacro from /home/athackst/catkin_ws/src/nasa_r2_common/r2_description/robots/r2c_legs.sim.urdf.xacro | -->
<!-- |    EDITING THIS FILE BY HAND IS NOT RECOMMENDED                                 | -->
<!-- =================================================================================== -->
<robot name="r2c_legs" xmlns:controller="http://playerstage.sourceforge.net/gazebo/xmlschema/#controller" xmlns:interface="http://playerstage.sourceforge.net/gazebo/xmlschema/#interface" xmlns:sensor="http://playerstage.sourceforge.net/gazebo/xmlschema/#sensor" xmlns:xacro="http://playerstage.sourceforge.net/gazebo/xmlschema/#interface">
  <link name="world"/>
  <link name="/r2/robot_world">
    <inertial>
      <mass value="0.01"/>
      <inertia ixx="0.0001" ixy="0.0" ixz="0.0" iyy="0.0001" iyz="0.0" izz="0.0001"/>
    </inertial>
  </link>
  <joint name="/r2/fixed/world/robot_world" type="fixed">
    <parent link="world"/>
    <child link="/r2/robot_world"/>
    <origin rpy="0.0 0.0 0.0" xyz="0.0 0.0 0.0"/>
  </joint>
  <material name="white">
    <color rgba="1.0 1.0 1.0 1.0"/>
  </material>
  <material name="dirty_white">
    <color rgba="0.322 0.322 0.322 1.0"/>
  </material>
  <material name="gold">
    <color rgba=".878 .49 0.008 1"/>
  </material>
  <material name="steel">
    <color rgba=".7 .7 .7 1"/>
  </material>
  <material name="blue">
    <color rgba="0 0 0.8 1"/>
  </material>
  <link name="/r2/leg_stand_base">
    <inertial>
      <origin xyz="0 0 0"/>
      <mass value="100.0"/>
      <inertia ixx="10.0" ixy="0.0" ixz="0.0" iyy="10.0" iyz="0.0" izz="10.0"/>
    </inertial>
    <visual>
      <origin xyz="0 0 0"/>
      <geometry>
        <box size="1 0.84 0.1"/>
      </geometry>
      <material name="steel"/>
    </visual>
    <collision>
      <origin xyz="0 0 0"/>
      <geometry>
        <box size="1 0.84 0.1"/>
      </geometry>
    </collision>
  </link>
  <link name="/r2/leg_stand_vert1">
    <inertial>
      <mass value="1.0"/>
      <inertia ixx="1.0" ixy="0.0" ixz="0.0" iyy="1.0" iyz="0.0" izz="1.0"/>
    </inertial>
    <visual>
      <origin xyz="0 0 0"/>
      <geometry>
        <box size="0.03 0.03 2"/>
      </geometry>
      <material name="steel"/>
    </visual>
    <collision>
      <origin xyz="0 0 0"/>
      <geometry>
        <box size="0.03 0.03 2"/>
      </geometry>
    </collision>
  </link>
  <link name="/r2/leg_stand_vert2">
    <inertial>
      <mass value="1.0"/>
      <inertia ixx="1.0" ixy="0.0" ixz="0.0" iyy="1.0" iyz="0.0" izz="1.0"/>
    </inertial>
    <visual>
      <origin xyz="0 0 0"/>
      <geometry>
        <box size="0.03 0.03 2"/>
      </geometry>
      <material name="steel"/>
    </visual>
    <collision>
      <origin xyz="0 0 0"/>
      <geometry>
        <box size="0.03 0.03 2"/>
      </geometry>
    </collision>
  </link>
  <link name="/r2/leg_stand_vert3">
    <inertial>
      <mass value="1.0"/>
      <inertia ixx="1.0" ixy="0.0" ixz="0.0" iyy="1.0" iyz="0.0" izz="1.0"/>
    </inertial>
    <visual>
      <origin xyz="0 0 0"/>
      <geometry>
        <box size="0.03 0.03 2"/>
      </geometry>
      <material name="steel"/>
    </visual>
    <collision>
      <origin xyz="0 0 0"/>
      <geometry>
        <box size="0.03 0.03 2"/>
      </geometry>
    </collision>
  </link>
  <link name="/r2/leg_stand_vert4">
    <inertial>
      <mass value="1.0"/>
      <inertia ixx="1.0" ixy="0.0" ixz="0.0" iyy="1.0" iyz="0.0" izz="1.0"/>
    </inertial>
    <visual>
      <origin xyz="0 0 0"/>
      <geometry>
        <box size="0.03 0.03 2"/>
      </geometry>
      <material name="steel"/>
    </visual>
    <collision>
      <origin xyz="0 0 0"/>
      <geometry>
        <box size="0.03 0.03 2"/>
      </geometry>
    </collision>
  </link>
  <link name="/r2/leg_stand_vert5">
    <inertial>
      <mass value="1.0"/>
      <inertia ixx="1.0" ixy="0.0" ixz="0.0" iyy="1.0" iyz="0.0" izz="1.0"/>
    </inertial>
    <visual>
      <origin xyz="0 0 0"/>
      <geometry>
        <box size="0.03 0.03 2"/>
      </geometry>
      <material name="steel"/>
    </visual>
    <collision>
      <origin xyz="0 0 0"/>
      <geometry>
        <box size="0.03 0.03 2"/>
      </geometry>
    </collision>
  </link>
  <link name="/r2/leg_stand_vert6">
    <inertial>
      <mass value="1.0"/>
      <inertia ixx="1.0" ixy="0.0" ixz="0.0" iyy="1.0" iyz="0.0" izz="1.0"/>
    </inertial>
    <visual>
      <origin xyz="0 0 0"/>
      <geometry>
        <box size="0.03 0.03 2"/>
      </geometry>
      <material name="steel"/>
    </visual>
    <collision>
      <origin xyz="0 0 0"/>
      <geometry>
        <box size="0.03 0.03 2"/>
      </geometry>
    </collision>
  </link>
  <link name="/r2/leg_stand_vert7">
    <inertial>
      <mass value="1.0"/>
      <inertia ixx="1.0" ixy="0.0" ixz="0.0" iyy="1.0" iyz="0.0" izz="1.0"/>
    </inertial>
    <visual>
      <origin xyz="0 0 0"/>
      <geometry>
        <box size="0.03 0.03 2"/>
      </geometry>
      <material name="steel"/>
    </visual>
    <collision>
      <origin xyz="0 0 0"/>
      <geometry>
        <box size="0.03 0.03 2"/>
      </geometry>
    </collision>
  </link>
  <link name="/r2/leg_stand_vert8">
    <inertial>
      <mass value="1.0"/>
      <inertia ixx="1.0" ixy="0.0" ixz="0.0" iyy="1.0" iyz="0.0" izz="1.0"/>
    </inertial>
    <visual>
      <origin xyz="0 0 0"/>
      <geometry>
        <box size="0.03 0.03 2"/>
      </geometry>
      <material name="steel"/>
    </visual>
    <collision>
      <origin xyz="0 0 0"/>
      <geometry>
        <box size="0.03 0.03 2"/>
      </geometry>
    </collision>
  </link>
  <link name="/r2/leg_stand_vert9">
    <inertial>
      <mass value="1.0"/>
      <inertia ixx="1.0" ixy="0.0" ixz="0.0" iyy="1.0" iyz="0.0" izz="1.0"/>
    </inertial>
    <visual>
      <origin xyz="0 0 0"/>
      <geometry>
        <box size="0.03 0.03 0.22"/>
      </geometry>
      <material name="steel"/>
    </visual>
    <collision>
      <origin xyz="0 0 0"/>
      <geometry>
        <box size="0.03 0.03 0.22"/>
      </geometry>
    </collision>
  </link>
  <link name="/r2/leg_stand_vert10">
    <inertial>
      <mass value="1.0"/>
      <inertia ixx="1.0" ixy="0.0" ixz="0.0" iyy="1.0" iyz="0.0" izz="1.0"/>
    </inertial>
    <visual>
      <origin xyz="0 0 0"/>
      <geometry>
        <box size="0.03 0.03 0.22"/>
      </geometry>
      <material name="steel"/>
    </visual>
    <collision>
      <origin xyz="0 0 0"/>
      <geometry>
        <box size="0.03 0.03 0.22"/>
      </geometry>
    </collision>
  </link>
  <link name="/r2/leg_stand_vert11">
    <inertial>
      <mass value="1.0"/>
      <inertia ixx="1.0" ixy="0.0" ixz="0.0" iyy="1.0" iyz="0.0" izz="1.0"/>
    </inertial>
    <visual>
      <origin xyz="0 0 0"/>
      <geometry>
        <box size="0.03 0.03 0.22"/>
      </geometry>
      <material name="steel"/>
    </visual>
    <collision>
      <origin xyz="0 0 0"/>
      <geometry>
        <box size="0.03 0.03 0.22"/>
      </geometry>
    </collision>
  </link>
  <link name="/r2/leg_stand_vert12">
    <inertial>
      <mass value="1.0"/>
      <inertia ixx="1.0" ixy="0.0" ixz="0.0" iyy="1.0" iyz="0.0" izz="1.0"/>
    </inertial>
    <visual>
      <origin xyz="0 0 0"/>
      <geometry>
        <box size="0.03 0.03 0.22"/>
      </geometry>
      <material name="steel"/>
    </visual>
    <collision>
      <origin xyz="0 0 0"/>
      <geometry>
        <box size="0.03 0.03 0.22"/>
      </geometry>
    </collision>
  </link>
  <link name="/r2/leg_stand_horz1">
    <inertial>
      <mass value="1.0"/>
      <inertia ixx="1.0" ixy="0.0" ixz="0.0" iyy="1.0" iyz="0.0" izz="1.0"/>
    </inertial>
    <visual>
      <origin xyz="0 0 0"/>
      <geometry>
        <box size="1.0 0.03 0.03"/>
      </geometry>
      <material name="steel"/>
    </visual>
    <collision>
      <origin xyz="0 0 0"/>
      <geometry>
        <box size="1.0 0.03 0.03"/>
      </geometry>
    </collision>
  </link>
  <link name="/r2/leg_stand_horz2">
    <inertial>
      <mass value="1.0"/>
      <inertia ixx="1.0" ixy="0.0" ixz="0.0" iyy="1.0" iyz="0.0" izz="1.0"/>
    </inertial>
    <visual>
      <origin xyz="0 0 0"/>
      <geometry>
        <box size="1.0 0.03 0.03"/>
      </geometry>
      <material name="steel"/>
    </visual>
    <collision>
      <origin xyz="0 0 0"/>
      <geometry>
        <box size="1.0 0.03 0.03"/>
      </geometry>
    </collision>
  </link>
  <link name="/r2/leg_stand_horz3">
    <inertial>
      <mass value="1.0"/>
      <inertia ixx="1.0" ixy="0.0" ixz="0.0" iyy="1.0" iyz="0.0" izz="1.0"/>
    </inertial>
    <visual>
      <origin xyz="0 0 0"/>
      <geometry>
        <box size="1.0 0.03 0.03"/>
      </geometry>
      <material name="steel"/>
    </visual>
    <collision>
      <origin xyz="0 0 0"/>
      <geometry>
        <box size="1.0 0.03 0.03"/>
      </geometry>
    </collision>
  </link>
  <link name="/r2/leg_stand_horz4">
    <inertial>
      <mass value="1.0"/>
      <inertia ixx="1.0" ixy="0.0" ixz="0.0" iyy="1.0" iyz="0.0" izz="1.0"/>
    </inertial>
    <visual>
      <origin xyz="0 0 0"/>
      <geometry>
        <box size="1.0 0.03 0.03"/>
      </geometry>
      <material name="steel"/>
    </visual>
    <collision>
      <origin xyz="0 0 0"/>
      <geometry>
        <box size="1.0 0.03 0.03"/>
      </geometry>
    </collision>
  </link>
  <link name="/r2/leg_stand_cross1">
    <inertial>
      <mass value="0.02"/>
      <inertia ixx="1.0" ixy="0.0" ixz="0.0" iyy="1.0" iyz="0.0" izz="1.0"/>
    </inertial>
    <visual>
      <origin xyz="0 0 0"/>
      <geometry>
        <box size="0.03 0.29 0.03"/>
      </geometry>
      <material name="steel"/>
    </visual>
    <collision>
      <origin xyz="0 0 0"/>
      <geometry>
        <box size="0.03 0.29 0.03"/>
      </geometry>
    </collision>
  </link>
  <link name="/r2/leg_stand_cross2">
    <inertial>
      <mass value="0.02"/>
      <inertia ixx="1.0" ixy="0.0" ixz="0.0" iyy="1.0" iyz="0.0" izz="1.0"/>
    </inertial>
    <visual>
      <origin xyz="0 0 0"/>
      <geometry>
        <box size="0.03 0.29 0.03"/>
      </geometry>
      <material name="steel"/>
    </visual>
    <collision>
      <origin xyz="0 0 0"/>
      <geometry>
        <box size="0.03 0.29 0.03"/>
      </geometry>
    </collision>
  </link>
  <link name="/r2/leg_stand_cross3">
    <inertial>
      <mass value="0.02"/>
      <inertia ixx="1.0" ixy="0.0" ixz="0.0" iyy="1.0" iyz="0.0" izz="1.0"/>
    </inertial>
    <visual>
      <origin xyz="0 0 0"/>
      <geometry>
        <box size="0.03 0.29 0.03"/>
      </geometry>
      <material name="steel"/>
    </visual>
    <collision>
      <origin xyz="0 0 0"/>
      <geometry>
        <box size="0.03 0.29 0.03"/>
      </geometry>
    </collision>
  </link>
  <link name="/r2/leg_stand_cross4">
    <inertial>
      <mass value="0.02"/>
      <inertia ixx="1.0" ixy="0.0" ixz="0.0" iyy="1.0" iyz="0.0" izz="1.0"/>
    </inertial>
    <visual>
      <origin xyz="0 0 0"/>
      <geometry>
        <box size="0.03 0.29 0.03"/>
      </geometry>
      <material name="steel"/>
    </visual>
    <collision>
      <origin xyz="0 0 0"/>
      <geometry>
        <box size="0.03 0.29 0.03"/>
      </geometry>
    </collision>
  </link>
  <link name="/r2/leg_stand_cross5">
    <inertial>
      <mass value="0.02"/>
      <inertia ixx="1.0" ixy="0.0" ixz="0.0" iyy="1.0" iyz="0.0" izz="1.0"/>
    </inertial>
    <visual>
      <origin xyz="0 0 0"/>
      <geometry>
        <box size="0.03 0.84 0.03"/>
      </geometry>
      <material name="steel"/>
    </visual>
    <collision>
      <origin xyz="0 0 0"/>
      <geometry>
        <box size="0.03 0.84 0.03"/>
      </geometry>
    </collision>
  </link>
  <link name="/r2/leg_stand_cross6">
    <inertial>
      <mass value="0.02"/>
      <inertia ixx="1.0" ixy="0.0" ixz="0.0" iyy="1.0" iyz="0.0" izz="1.0"/>
    </inertial>
    <visual>
      <origin xyz="0 0 0"/>
      <geometry>
        <box size="0.03 0.84 0.03"/>
      </geometry>
      <material name="steel"/>
    </visual>
    <collision>
      <origin xyz="0 0 0"/>
      <geometry>
        <box size="0.03 0.84 0.03"/>
      </geometry>
    </collision>
  </link>
  <link name="/r2/leg_stand_cross7">
    <inertial>
      <mass value="0.02"/>
      <inertia ixx="1.0" ixy="0.0" ixz="0.0" iyy="1.0" iyz="0.0" izz="1.0"/>
    </inertial>
    <visual>
      <origin xyz="0 0 0"/>
      <geometry>
        <box size="0.03 0.84 0.03"/>
      </geometry>
      <material name="steel"/>
    </visual>
    <collision>
      <origin xyz="0 0 0"/>
      <geometry>
        <box size="0.03 0.84 0.03"/>
      </geometry>
    </collision>
  </link>
  <link name="/r2/leg_stand_cross8">
    <inertial>
      <mass value="0.02"/>
      <inertia ixx="1.0" ixy="0.0" ixz="0.0" iyy="1.0" iyz="0.0" izz="1.0"/>
    </inertial>
    <visual>
      <origin xyz="0 0 0"/>
      <geometry>
        <box size="0.03 0.84 0.03"/>
      </geometry>
      <material name="steel"/>
    </visual>
    <collision>
      <origin xyz="0 0 0"/>
      <geometry>
        <box size="0.03 0.84 0.03"/>
      </geometry>
    </collision>
  </link>
  <link name="/r2/leg_stand_connection">
    <inertial>
      <origin xyz="0 0 0"/>
      <mass value="0.02"/>
      <inertia ixx="1.0" ixy="0.0" ixz="0.0" iyy="1.0" iyz="0.0" izz="1.0"/>
    </inertial>
    <visual>
      <origin xyz="0 0 0"/>
      <geometry>
        <box size="0.29 0.29 0.003"/>
      </geometry>
      <material name="steel"/>
    </visual>
    <collision>
      <origin xyz="0 0 0"/>
      <geometry>
        <box size="0.29 0.29 0.003"/>
      </geometry>
    </collision>
  </link>
  <joint name="/r2/fixed/robot_world/leg_stand_base" type="fixed">
    <parent link="/r2/robot_world"/>
    <child link="/r2/leg_stand_base"/>
    <origin rpy="0.0 0.0 3.14159" xyz="0.0 0.0 0.05"/>
  </joint>
  <joint name="/r2/fixed/leg_stand_base/leg_stand_vert1" type="fixed">
    <parent link="/r2/leg_stand_base"/>
    <child link="/r2/leg_stand_vert1"/>
    <origin rpy="0 0 0" xyz="0.485 0.13 1"/>
  </joint>
  <joint name="/r2/fixed/leg_stand_base/leg_stand_vert2" type="fixed">
    <parent link="/r2/leg_stand_base"/>
    <child link="/r2/leg_stand_vert2"/>
    <origin rpy="0 0 0" xyz="0.485 -0.13 1"/>
  </joint>
  <joint name="/r2/fixed/leg_stand_base/leg_stand_vert3" type="fixed">
    <parent link="/r2/leg_stand_base"/>
    <child link="/r2/leg_stand_vert3"/>
    <origin rpy="0 0 0" xyz="0.225 0.13 1"/>
  </joint>
  <joint name="/r2/fixed/leg_stand_base/leg_stand_vert4" type="fixed">
    <parent link="/r2/leg_stand_base"/>
    <child link="/r2/leg_stand_vert4"/>
    <origin rpy="0 0 0" xyz="0.225 -0.13 1"/>
  </joint>
  <joint name="/r2/fixed/leg_stand_base/leg_stand_vert5" type="fixed">
    <parent link="/r2/leg_stand_base"/>
    <child link="/r2/leg_stand_vert5"/>
    <origin rpy="0 0 0" xyz="0.485 0.405 1"/>
  </joint>
  <joint name="/r2/fixed/leg_stand_base/leg_stand_vert6" type="fixed">
    <parent link="/r2/leg_stand_base"/>
    <child link="/r2/leg_stand_vert6"/>
    <origin rpy="0 0 0" xyz="0.485 -0.405 1"/>
  </joint>
  <joint name="/r2/fixed/leg_stand_base/leg_stand_vert7" type="fixed">
    <parent link="/r2/leg_stand_base"/>
    <child link="/r2/leg_stand_vert7"/>
    <origin rpy="0 0 0" xyz="0.225 0.405 1"/>
  </joint>
  <joint name="/r2/fixed/leg_stand_base/leg_stand_vert8" type="fixed">
    <parent link="/r2/leg_stand_base"/>
    <child link="/r2/leg_stand_vert8"/>
    <origin rpy="0 0 0" xyz="0.225 -0.405 1"/>
  </joint>
  <joint name="/r2/fixed/leg_stand_horz3/leg_stand_vert9" type="fixed">
    <parent link="/r2/leg_stand_horz3"/>
    <child link="/r2/leg_stand_vert9"/>
    <origin rpy="0 0 0" xyz="-0.225 0.0 0.11"/>
  </joint>
  <joint name="/r2/fixed/leg_stand_horz4/leg_stand_vert11" type="fixed">
    <parent link="/r2/leg_stand_horz4"/>
    <child link="/r2/leg_stand_vert11"/>
    <origin rpy="0 0 0" xyz="-0.225 0.0 0.11"/>
  </joint>
  <joint name="/r2/fixed/leg_stand_horz3/leg_stand_vert0" type="fixed">
    <parent link="/r2/leg_stand_horz3"/>
    <child link="/r2/leg_stand_vert10"/>
    <origin rpy="0 0 0" xyz="-0.485 0.0 0.11"/>
  </joint>
  <joint name="/r2/fixed/leg_stand_horz4/leg_stand_vert12" type="fixed">
    <parent link="/r2/leg_stand_horz4"/>
    <child link="/r2/leg_stand_vert12"/>
    <origin rpy="0 0 0" xyz="-0.485 0.0 0.11"/>
  </joint>
  <joint name="/r2/fixed/leg_stand_vert1/leg_stand_horz1" type="fixed">
    <parent link="/r2/leg_stand_vert1"/>
    <child link="/r2/leg_stand_horz1"/>
    <origin rpy="0 0 0" xyz="-0.485 0.0 1.0"/>
  </joint>
  <joint name="/r2/fixed/leg_stand_vert2/leg_stand_horz2" type="fixed">
    <parent link="/r2/leg_stand_vert2"/>
    <child link="/r2/leg_stand_horz2"/>
    <origin rpy="0 0 0" xyz="-0.485 -0.0 1.0"/>
  </joint>
  <joint name="/r2/fixed/leg_stand_vert1/leg_stand_horz3" type="fixed">
    <parent link="/r2/leg_stand_vert1"/>
    <child link="/r2/leg_stand_horz3"/>
    <origin rpy="0 0 0" xyz="-0.485 0.0 0.78"/>
  </joint>
  <joint name="/r2/fixed/leg_stand_vert2/leg_stand_horz4" type="fixed">
    <parent link="/r2/leg_stand_vert2"/>
    <child link="/r2/leg_stand_horz4"/>
    <origin rpy="0 0 0" xyz="-0.485 -0.0 0.78"/>
  </joint>
  <joint name="/r2/fixed/leg_stand_horz1/leg_stand_cross1" type="fixed">
    <parent link="/r2/leg_stand_horz1"/>
    <child link="/r2/leg_stand_cross1"/>
    <origin rpy="0 0 0" xyz="-0.485 -0.13 0.0"/>
  </joint>
  <joint name="/r2/fixed/leg_stand_horz1/leg_stand_cross2" type="fixed">
    <parent link="/r2/leg_stand_horz1"/>
    <child link="/r2/leg_stand_cross2"/>
    <origin rpy="0 0 0" xyz="-0.225 -0.13 0.0"/>
  </joint>
  <joint name="/r2/fixed/leg_stand_horz3/leg_stand_cross3" type="fixed">
    <parent link="/r2/leg_stand_horz3"/>
    <child link="/r2/leg_stand_cross3"/>
    <origin rpy="0 0 0" xyz="-0.485 -0.13 0.0"/>
  </joint>
  <joint name="/r2/fixed/leg_stand_horz3/leg_stand_cross4" type="fixed">
    <parent link="/r2/leg_stand_horz3"/>
    <child link="/r2/leg_stand_cross4"/>
    <origin rpy="0 0 0" xyz="-0.225 -0.13 0.0"/>
  </joint>
  <joint name="/r2/fixed/leg_stand_horz1/leg_stand_cross5" type="fixed">
    <parent link="/r2/leg_stand_horz1"/>
    <child link="/r2/leg_stand_cross5"/>
    <origin rpy="0 0 0" xyz="0.485 -0.13 0.0"/>
  </joint>
  <joint name="/r2/fixed/leg_stand_horz1/leg_stand_cross6" type="fixed">
    <parent link="/r2/leg_stand_horz1"/>
    <child link="/r2/leg_stand_cross6"/>
    <origin rpy="0 0 0" xyz="0.225 -0.13 0.0"/>
  </joint>
  <joint name="/r2/fixed/leg_stand_horz3/leg_stand_cross7" type="fixed">
    <parent link="/r2/leg_stand_horz3"/>
    <child link="/r2/leg_stand_cross7"/>
    <origin rpy="0 0 0" xyz="0.485 -0.13 0.0"/>
  </joint>
  <joint name="/r2/fixed/leg_stand_horz3/leg_stand_cross8" type="fixed">
    <parent link="/r2/leg_stand_horz3"/>
    <child link="/r2/leg_stand_cross8"/>
    <origin rpy="0 0 0" xyz="0.225 -0.13 0.0"/>
  </joint>
  <joint name="/r2/fixed/leg_stand_horz4/leg_stand_connection" type="fixed">
    <parent link="/r2/leg_stand_cross4"/>
    <child link="/r2/leg_stand_connection"/>
    <origin rpy="0 0 0" xyz="-0.13 -0.0 -0.0152"/>
  </joint>
  <link name="/r2/robot_base">
    <inertial>
      <mass value="0.01"/>
      <inertia ixx="0.0001" ixy="0.0" ixz="0.0" iyy="0.0001" iyz="0.0" izz="0.0001"/>
    </inertial>
  </link>
  <joint name="/r2/fixed/leg_stand_connection/robot_base" type="fixed">
    <parent link="/r2/leg_stand_connection"/>
    <child link="/r2/robot_base"/>
    <origin rpy="0 3.14159 0" xyz="0.0 0.0 0.0"/>
  </joint>
  <link name="/r2/pelvis">
    <inertial>
      <mass value="12.2831"/>
      <inertia ixx="0.10679" ixy="0.00009239" ixz="-0.00002105" iyy="0.05595" iyz="0.0" izz="0.1022"/>
      <origin rpy="0 0 0" xyz="0.00001909 0.0 -0.008524"/>
    </inertial>
    <visual>
      <geometry>
        <mesh filename="package://r2_description/meshes/r2c_legs/r2cl_ext_pelvis.dae"/>
      </geometry>
      <material name="gold"/>
      <origin rpy="0 0 0" xyz="0 0 0"/>
    </visual>
    <collision>
      <geometry>
        <mesh filename="package://r2_description/meshes/r2c_legs/r2cl_ext_pelvis.dae"/>
      </geometry>
      <origin rpy="0 0 0" xyz="0 0 0"/>
    </collision>
  </link>
  <joint name="/r2/fixed/robot_base/pelvis" type="fixed">
    <parent link="/r2/robot_base"/>
    <child link="/r2/pelvis"/>
    <origin rpy="0 3.14159 0" xyz="0 0 0.098"/>
  </joint>
  <joint name="/r2/fixed/pelvis/left_leg_base" type="fixed">
    <parent link="/r2/pelvis"/>
    <child link="/r2/left_leg_base"/>
    <origin rpy="0 0.000000 1.570796" xyz="0.0 0 0.0"/>
  </joint>
  <link name="/r2/left_leg_base">
    <inertial>
      <mass value="0.01"/>
      <inertia ixx="0.0001" ixy="0.0" ixz="0.0" iyy="0.0001" iyz="0.0" izz="0.0001"/>
    </inertial>
  </link>
  <joint name="/r2/fixed/left_leg_base/left_leg_j0_base" type="fixed">
    <parent link="/r2/left_leg_base"/>
    <child link="/r2/left_leg_j0_base"/>
    <origin rpy="0.0 1.8325957 3.14159" xyz="-0.1104900 0.0 -0.0297180"/>
  </joint>
  <link name="/r2/left_leg_j0_base">
    <inertial>
      <mass value="0.01"/>
      <inertia ixx="0.0001" ixy="0.0" ixz="0.0" iyy="0.0001" iyz="0.0" izz="0.0001"/>
    </inertial>
  </link>
  <joint name="/r2/left_leg/joint0" type="revolute">
    <parent link="/r2/left_leg_j0_base"/>
    <child link="/r2/left_hip_roll"/>
    <origin rpy="0.0 0 0" xyz="0 0 0"/>
    <axis xyz="0 0 1"/>
    <dynamics damping="10.0" friction="0.0"/>
    <limit effort="330.0" lower="-3.14159" upper="3.14159" velocity="1.0"/>
    <traits spring_k="2.5"/>
  </joint>
  <link name="/r2/left_hip_roll">
    <inertial>
      <mass value="2.5410"/>
      <inertia ixx="0.006434" ixy="0.0007087" ixz="-0.001543" iyy="0.009325" iyz="0.0008694" izz="0.006904"/>
      <origin rpy="0.0 0.0 0.0" xyz="0.03372 -0.02428 0.07903"/>
    </inertial>
    <visual>
      <geometry>
        <mesh filename="package://r2_description/meshes/r2c_legs/r2cl_ext_bone3.dae"/>
      </geometry>
      <origin rpy="0 0 0" xyz="0.0 0.0 0.0"/>
    </visual>
    <collision>
      <geometry>
        <mesh filename="package://r2_description/meshes/r2c_legs/r2cl_ext_bone3.dae"/>
      </geometry>
      <origin rpy="0 0 0" xyz="0.0 0.0 0.0"/>
    </collision>
  </link>
  <joint name="/r2/left_leg/joint1" type="revolute">
    <parent link="/r2/left_hip_roll"/>
    <child link="/r2/left_hip_pitch"/>
    <origin rpy="-1.570796  -0.2617994 0.0000000" xyz="0.050629765 +0.0022860 0.103498576"/>
    <axis xyz="0 0 1"/>
    <dynamics damping="5.0" friction="0.0"/>
    <limit effort="330.0" lower="-1.42244" upper="1.20427" velocity="1.0"/>
    <traits spring_k="2.5"/>
  </joint>
  <link name="/r2/left_hip_pitch">
    <inertial>
      <mass value="4.6734"/>
      <inertia ixx="0.01002" ixy="0.007194" ixz="0.002041" iyy="0.03307" iyz="-0.0007281" izz="0.03728"/>
      <origin rpy="0 0 0" xyz="0.09450 -0.03354 0.008185"/>
    </inertial>
    <visual>
      <geometry>
        <mesh filename="package://r2_description/meshes/r2c_legs/r2cl_ext_bone1.dae"/>
      </geometry>
      <origin rpy="0 0 0" xyz="0 0 0"/>
    </visual>
    <collision>
      <geometry>
        <mesh filename="package://r2_description/meshes/r2c_legs/r2cl_ext_bone1.dae"/>
      </geometry>
      <origin rpy="0 0 0" xyz="0 0 0"/>
    </collision>
  </link>
  <joint name="/r2/left_leg/joint2" type="revolute">
    <parent link="/r2/left_hip_pitch"/>
    <child link="/r2/left_upper_leg"/>
    <origin rpy=" 1.570796 0.0 1.570796" xyz="0.200 -0.050 0.004"/>
    <axis xyz="0 0 1"/>
    <dynamics damping="5.0" friction="0.0"/>
    <limit effort="330.0" lower="-3.14159" upper="3.14159" velocity="1.0"/>
    <traits spring_k="2.5"/>
  </joint>
  <link name="/r2/left_upper_leg">
    <inertial>
      <mass value="3.7745"/>
      <inertia ixx="0.02163" ixy="-0.001453" ixz="0.003137" iyy="0.01832" iyz="0.004738" izz="0.009798"/>
      <origin rpy="0 0 0" xyz="-0.01485 -0.02188 0.09676"/>
    </inertial>
    <visual>
      <geometry>
        <mesh filename="package://r2_description/meshes/r2c_legs/r2cl_ext_bone2.dae"/>
      </geometry>
      <origin rpy="0 0 0" xyz="0 0 0"/>
    </visual>
    <collision>
      <geometry>
        <mesh filename="package://r2_description/meshes/r2c_legs/r2cl_ext_bone2.dae"/>
      </geometry>
      <origin rpy="0 0 0" xyz="0 0 0"/>
    </collision>
  </link>
  <joint name="/r2/left_leg/joint3" type="revolute">
    <parent link="/r2/left_upper_leg"/>
    <child link="/r2/left_knee"/>
    <origin rpy="0.0 -1.570796 3.14159" xyz="-0.002 -0.050 0.157"/>
    <axis xyz="0 0 1"/>
    <dynamics damping="5.0" friction="0.0"/>
    <limit effort="330.0" lower="-0.10472" upper="2.68781" velocity="1.0"/>
    <traits spring_k="2.5"/>
  </joint>
  <link name="/r2/left_knee">
    <inertial>
      <mass value="4.6734"/>
      <inertia ixx="0.01002" ixy="0.007194" ixz="0.002041" iyy="0.03307" iyz="-0.0007281" izz="0.03728"/>
      <origin rpy="0 0 0" xyz="0.09450 -0.03354 0.008185"/>
    </inertial>
    <visual>
      <geometry>
        <mesh filename="package://r2_description/meshes/r2c_legs/r2cl_ext_bone1.dae"/>
      </geometry>
      <origin rpy="0 0 0" xyz="0 0 0"/>
    </visual>
    <collision>
      <geometry>
        <mesh filename="package://r2_description/meshes/r2c_legs/r2cl_ext_bone1.dae"/>
      </geometry>
      <material name="gold"/>
      <origin rpy="0 0 0" xyz="0 0 0"/>
    </collision>
  </link>
  <joint name="/r2/left_leg/joint4" type="revolute">
    <parent link="/r2/left_knee"/>
    <child link="/r2/left_lower_leg"/>
    <origin rpy="0 1.570796 0" xyz="0.200 -0.050 0.004"/>
    <axis xyz="0 0 1"/>
    <dynamics damping="5.0" friction="0.0"/>
    <limit effort="330.0" lower="-3.14159" upper="3.14159" velocity="1.0"/>
    <traits spring_k="2.5"/>
  </joint>
  <link name="/r2/left_lower_leg">
    <inertial>
      <mass value="3.7745"/>
      <inertia ixx="0.02163" ixy="-0.001453" ixz="0.003137" iyy="0.01832" iyz="0.004738" izz="0.009798"/>
      <origin rpy="0 0 0" xyz="-0.01485 -0.02188 0.09676"/>
    </inertial>
    <visual>
      <geometry>
        <mesh filename="package://r2_description/meshes/r2c_legs/r2cl_ext_bone2.dae"/>
      </geometry>
      <origin rpy="0 0 0" xyz="0 0 0"/>
    </visual>
    <collision>
      <geometry>
        <mesh filename="package://r2_description/meshes/r2c_legs/r2cl_ext_bone2.dae"/>
      </geometry>
      <origin rpy="0 0 0" xyz="0 0 0"/>
    </collision>
  </link>
  <joint name="/r2/left_leg/joint5" type="revolute">
    <parent link="/r2/left_lower_leg"/>
    <child link="/r2/left_ankle_pitch"/>
    <origin rpy="0.0 -1.570796 3.14159" xyz="-0.002 -0.050 0.157"/>
    <axis xyz="0 0 1"/>
    <dynamics damping="5.0" friction="0.0"/>
    <limit effort="330.0" lower="-0.10472" upper="2.68781" velocity="1.0"/>
    <traits spring_k="2.5"/>
  </joint>
  <link name="/r2/left_ankle_pitch">
    <inertial>
      <mass value="4.6734"/>
      <inertia ixx="0.01002" ixy="0.007194" ixz="0.002041" iyy="0.03307" iyz="-0.0007281" izz="0.03728"/>
      <origin rpy="0 0 0" xyz="0.09450 -0.03354 0.008185"/>
    </inertial>
    <visual>
      <geometry>
        <mesh filename="package://r2_description/meshes/r2c_legs/r2cl_ext_bone1.dae"/>
      </geometry>
      <origin rpy="0 0 0" xyz="0 0 0"/>
    </visual>
    <collision>
      <geometry>
        <mesh filename="package://r2_description/meshes/r2c_legs/r2cl_ext_bone1.dae"/>
      </geometry>
      <origin rpy="0 0 0" xyz="0 0 0"/>
    </collision>
  </link>
  <joint name="/r2/left_leg/joint6" type="revolute">
    <parent link="/r2/left_ankle_pitch"/>
    <child link="/r2/left_ankle_roll"/>
    <origin rpy="3.14159 -1.570796 0" xyz="0.199643 -0.0508 0.00325"/>
    <axis xyz="0 0 1"/>
    <dynamics damping="5.0" friction="0.0"/>
    <limit effort="330.0" lower="-3.14159" upper="3.14159" velocity="1.0"/>
    <traits spring_k="2.5"/>
  </joint>
  <link name="/r2/left_ankle_roll">
    <inertial>
      <mass value="1.4461"/>
      <inertia ixx="0.001780" ixy="0.00001801" ixz="0.0000002218" iyy="0.001767" iyz="0.0000006717" izz="0.002949"/>
      <origin rpy="0 0 0" xyz="-0.00004402 0.0001052 0.02940"/>
    </inertial>
    <visual>
      <geometry>
        <cylinder length=".06" radius=".066"/>
      </geometry>
      <material name="dirty_white"/>
      <origin rpy="0 0 0" xyz="0 0 0.025"/>
    </visual>
    <collision>
      <geometry>
        <cylinder length=".06" radius=".066"/>
      </geometry>
      <origin rpy="0 0 0" xyz="0 0 0.025"/>
    </collision>
  </link>
  <joint name="/r2/fixed/left_ankle_roll/left_leg_ati" type="fixed">
    <parent link="/r2/left_ankle_roll"/>
    <child link="/r2/left_leg/ati"/>
    <origin rpy="3.1416 0.0 -1.5708" xyz="0.0 0.0 0.070182"/>
  </joint>
  <link name="/r2/left_leg/ati">
    <inertial>
      <mass value="0.01"/>
      <inertia ixx="0.0001" ixy="0.0" ixz="0.0" iyy="0.0001" iyz="0.0" izz="0.0001"/>
    </inertial>
  </link>
  <joint name="/r2/fixed/left_leg_ati/left_leg_foot" type="fixed">
    <parent link="/r2/left_leg/ati"/>
    <child link="/r2/left_leg_foot"/>
    <origin rpy="3.1416 0.0 -1.5708" xyz="0.0 0.0 0.0206502"/>
  </joint>
  <link name="/r2/left_leg_foot">
    <inertial>
      <mass value="4.4308"/>
      <inertia ixx="0.01928" ixy="-0.0003391" ixz="-0.0001325" iyy="0.01765" iyz="-0.0006598" izz="0.009944"/>
      <origin rpy="0 0 0" xyz="-0.001903 0.0002149 0.08495"/>
    </inertial>
    <visual>
      <geometry>
        <mesh filename="package://r2_description/meshes/r2c_legs/r2cl_foot.dae"/>
      </geometry>
      <origin rpy="0 0 0" xyz="0 0 0"/>
    </visual>
    <collision>
      <geometry>
        <mesh filename="package://r2_description/meshes/r2c_legs/r2cl_foot.dae"/>
      </geometry>
      <origin rpy="0 0 0" xyz="0 0 0"/>
    </collision>
  </link>
  <joint name="/r2/fixed/left_leg_foot/left_hr_tip" type="fixed">
    <parent link="/r2/left_leg_foot"/>
    <child link="/r2/left_leg/gripper/tip"/>
    <origin rpy="0.0 0 0" xyz="0 0 0.19451"/>
  </joint>
  <link name="/r2/left_leg/gripper/tip">
    <inertial>
      <mass value="0.01"/>
      <inertia ixx="0.0001" ixy="0.0" ixz="0.0" iyy="0.0001" iyz="0.0" izz="0.0001"/>
    </inertial>
  </link>
  <joint name="/r2/left_leg/gripper/joint0" type="revolute">
    <parent link="/r2/left_leg_foot"/>
    <child link="/r2/left_leg/gripper/link0"/>
    <origin rpy="0.0 0 0" xyz="0 0 0"/>
    <axis xyz="0 0 1"/>
    <dynamics damping="1.0" friction="0.0"/>
    <limit effort="330.0" lower="-.1" upper=".75" velocity="1.0"/>
  </joint>
  <joint name="/r2/left_leg/gripper/joint1" type="revolute">
    <parent link="/r2/left_leg_foot"/>
    <child link="/r2/left_leg_jaw0"/>
    <origin rpy="0.0 -0.087266 0.0" xyz="0.01905 0 0.17546"/>
    <axis xyz="0 1 0"/>
    <dynamics damping="1.0" friction="0.0"/>
    <limit effort="330.0" lower="-.1" upper=".75" velocity="1.0"/>
  </joint>
  <joint name="/r2/left_leg/gripper/joint2" type="revolute">
    <parent link="/r2/left_leg_foot"/>
    <child link="/r2/left_leg_jaw1"/>
    <origin rpy="0.0 0.087266 0.0" xyz="-0.01905 0 0.17546"/>
    <axis xyz="0 -1 0"/>
    <dynamics damping="1.0" friction="0.0"/>
    <limit effort="330.0" lower="-.1" upper=".75" velocity="1.0"/>
  </joint>
  <joint name="/r2/fixed/left_leg_foot/left_leg_camera0_physical" type="fixed">
    <parent link="/r2/left_leg_foot"/>
    <child link="/r2/left_leg_camera0_physical"/>
    <origin rpy="0 0 0" xyz="-0.025 .07 0.13"/>
  </joint>
  <joint name="/r2/fixed/left_leg_foot/left_leg_camera1_physical" type="fixed">
    <parent link="/r2/left_leg_foot"/>
    <child link="/r2/left_leg_camera1_physical"/>
    <origin rpy="0.0 0 0" xyz="0.025 .07 0.13"/>
  </joint>
  <link name="/r2/left_leg/gripper/link0">
    <inertial>
      <mass value="0.01"/>
      <inertia ixx="0.0001" ixy="0.0" ixz="0.0" iyy="0.0001" iyz="0.0" izz="0.0001"/>
    </inertial>
  </link>
  <link name="/r2/left_leg_jaw0">
    <inertial>
      <mass value="0.01"/>
      <inertia ixx="0.0001" ixy="0.0" ixz="0.0" iyy="0.0001" iyz="0.0" izz="0.0001"/>
      <origin rpy="0 0 0" xyz="0.00236 0 0.02395"/>
    </inertial>
    <visual>
      <geometry>
        <mesh filename="package://r2_description/meshes/r2c_legs/r2cl_foot_jaw1.dae"/>
      </geometry>
      <origin rpy="0 0 0" xyz="0 0 0"/>
    </visual>
    <collision>
      <geometry>
        <mesh filename="package://r2_description/meshes/r2c_legs/r2cl_foot_jaw1.dae"/>
      </geometry>
      <origin rpy="0 0 0" xyz="0 0 0"/>
    </collision>
  </link>
  <link name="/r2/left_leg_jaw1">
    <inertial>
      <mass value="0.01"/>
      <inertia ixx="0.0001" ixy="0.0" ixz="0.0" iyy="0.0001" iyz="0.0" izz="0.0001"/>
      <origin rpy="0 0 0" xyz="0.00236 0 0.02395"/>
    </inertial>
    <visual>
      <geometry>
        <mesh filename="package://r2_description/meshes/r2c_legs/r2cl_foot_jaw2.dae"/>
      </geometry>
      <origin rpy="0 0 0" xyz="0 0 0"/>
    </visual>
    <collision>
      <geometry>
        <mesh filename="package://r2_description/meshes/r2c_legs/r2cl_foot_jaw2.dae"/>
      </geometry>
      <origin rpy="0 0 0" xyz="0 0 0"/>
    </collision>
  </link>
  <link name="/r2/left_leg_camera0_physical">
    <inertial>
      <mass value="0.01"/>
      <inertia ixx="0.0001" ixy="0.0" ixz="0.0" iyy="0.0001" iyz="0.0" izz="0.0001"/>
    </inertial>
  </link>
  <joint name="/r2/fixed/left_leg_camera0_physical/left_leg_camera0_optical" type="fixed">
    <parent link="/r2/left_leg_camera0_physical"/>
    <child link="/r2/left_leg_camera0_optical"/>
    <origin rpy="0 -1.5708 -1.5708" xyz="0 0 .03"/>
  </joint>
  <link name="/r2/left_leg_camera0_optical">
    <inertial>
      <mass value="0.01"/>
      <inertia ixx="0.0001" ixy="0.0" ixz="0.0" iyy="0.0001" iyz="0.0" izz="0.0001"/>
    </inertial>
  </link>
  <link name="/r2/left_leg_camera1_physical">
    <inertial>
      <mass value="0.01"/>
      <inertia ixx="0.0001" ixy="0.0" ixz="0.0" iyy="0.0001" iyz="0.0" izz="0.0001"/>
    </inertial>
  </link>
  <joint name="/r2/fixed/left_leg_camera1_physical/left_leg_camera1_optical" type="fixed">
    <parent link="/r2/left_leg_camera1_physical"/>
    <child link="/r2/left_leg_camera1_optical"/>
    <origin rpy="0 -1.5708 -1.5708" xyz="0 0 0.03"/>
  </joint>
  <link name="/r2/left_leg_camera1_optical">
    <inertial>
      <mass value="0.01"/>
      <inertia ixx="0.0001" ixy="0.0" ixz="0.0" iyy="0.0001" iyz="0.0" izz="0.0001"/>
    </inertial>
  </link>
  <joint name="/r2/fixed/pelvis/right_leg_base" type="fixed">
    <parent link="/r2/pelvis"/>
    <child link="/r2/right_leg_base"/>
    <origin rpy="0 0.000000 1.570796" xyz="0.0 0 0.0"/>
  </joint>
  <link name="/r2/right_leg_base">
    <inertial>
      <mass value="0.01"/>
      <inertia ixx="0.0001" ixy="0.0" ixz="0.0" iyy="0.0001" iyz="0.0" izz="0.0001"/>
    </inertial>
  </link>
  <joint name="/r2/fixed/right_leg_base/right_leg_j0_base" type="fixed">
    <parent link="/r2/right_leg_base"/>
    <child link="/r2/right_leg_j0_base"/>
    <origin rpy="0.0 1.8325957 0" xyz="0.1104900 0.0 -0.0297180"/>
  </joint>
  <link name="/r2/right_leg_j0_base">
    <inertial>
      <mass value="0.01"/>
      <inertia ixx="0.0001" ixy="0.0" ixz="0.0" iyy="0.0001" iyz="0.0" izz="0.0001"/>
    </inertial>
  </link>
  <joint name="/r2/right_leg/joint0" type="revolute">
    <parent link="/r2/right_leg_j0_base"/>
    <child link="/r2/right_hip_roll"/>
    <origin rpy=" 0.000000 0 0.000000" xyz="0 0 0"/>
    <axis xyz="0 0 1"/>
    <dynamics damping="10.0" friction="0.0"/>
    <limit effort="330.0" lower="-3.14159" upper="3.14159" velocity="1.0"/>
    <traits spring_k="2.5"/>
  </joint>
  <link name="/r2/right_hip_roll">
    <inertial>
      <mass value="2.5410"/>
      <inertia ixx="0.006434" ixy="0.0007087" ixz="-0.001543" iyy="0.009325" iyz="0.0008694" izz="0.006904"/>
      <origin rpy="0.0 0.0 0.0" xyz="0.03372 -0.02428 0.07903"/>
    </inertial>
    <visual>
      <geometry>
        <mesh filename="package://r2_description/meshes/r2c_legs/r2cl_ext_bone3.dae"/>
      </geometry>
      <origin rpy="0 0 0" xyz="0.0 0.0 0.0"/>
    </visual>
    <collision>
      <geometry>
        <mesh filename="package://r2_description/meshes/r2c_legs/r2cl_ext_bone3.dae"/>
      </geometry>
      <origin rpy="0 0 0" xyz="0.0 0.0 0.0"/>
    </collision>
  </link>
  <joint name="/r2/right_leg/joint1" type="revolute">
    <parent link="/r2/right_hip_roll"/>
    <child link="/r2/right_hip_pitch"/>
    <origin rpy="-1.570796  -0.2617994 0.0000000" xyz="0.050629765 -0.0022860 0.103498576"/>
    <axis xyz="0 0 1"/>
    <dynamics damping="5.0" friction="0.0"/>
    <limit effort="330.0" lower="-1.42244" upper="1.20428" velocity="1.0"/>
    <traits spring_k="2.5"/>
  </joint>
  <link name="/r2/right_hip_pitch">
    <inertial>
      <mass value="4.6734"/>
      <inertia ixx="0.01002" ixy="0.007194" ixz="0.002041" iyy="0.03307" iyz="-0.0007281" izz="0.03728"/>
      <origin rpy="0 0 0" xyz="0.09450 -0.03354 0.008185"/>
    </inertial>
    <visual>
      <geometry>
        <mesh filename="package://r2_description/meshes/r2c_legs/r2cl_ext_bone1.dae"/>
      </geometry>
      <origin rpy="0 0 0" xyz="0 0 0"/>
    </visual>
    <collision>
      <geometry>
        <mesh filename="package://r2_description/meshes/r2c_legs/r2cl_ext_bone1.dae"/>
      </geometry>
      <origin rpy="0 0 0" xyz="0 0 0"/>
    </collision>
  </link>
  <joint name="/r2/right_leg/joint2" type="revolute">
    <parent link="/r2/right_hip_pitch"/>
    <child link="/r2/right_upper_leg"/>
    <origin rpy="-1.570796 0.0 -1.570796" xyz="0.200 -0.050 0.004"/>
    <axis xyz="0 0 1"/>
    <dynamics damping="5.0" friction="0.0"/>
    <limit effort="330.0" lower="-3.14159" upper="3.14159" velocity="1.0"/>
    <traits spring_k="2.5"/>
  </joint>
  <link name="/r2/right_upper_leg">
    <inertial>
      <mass value="3.5701"/>
      <inertia ixx="0.02163" ixy="-0.001453" ixz="0.003137" iyy="0.01832" iyz="0.004738" izz="0.009798"/>
      <origin rpy="0 0 0" xyz="-0.01485 -0.02188 0.09676"/>
    </inertial>
    <visual>
      <geometry>
        <mesh filename="package://r2_description/meshes/r2c_legs/r2cl_ext_bone2.dae"/>
      </geometry>
      <origin rpy="0 0 0" xyz="0 0 0"/>
    </visual>
    <collision>
      <geometry>
        <mesh filename="package://r2_description/meshes/r2c_legs/r2cl_ext_bone2.dae"/>
      </geometry>
      <origin rpy="0 0 0" xyz="0 0 0.0"/>
    </collision>
  </link>
  <joint name="/r2/right_leg/joint3" type="revolute">
    <parent link="/r2/right_upper_leg"/>
    <child link="/r2/right_knee"/>
    <origin rpy="0.0 -1.570796 3.14159" xyz="-0.00200 -0.050  0.157"/>
    <axis xyz="0 0 1"/>
    <dynamics damping="5.0" friction="0.0"/>
    <limit effort="330.0" lower="-0.10472" upper="2.68781" velocity="1.0"/>
    <traits spring_k="2.5"/>
  </joint>
  <link name="/r2/right_knee">
    <inertial>
      <mass value="4.6734"/>
      <inertia ixx="0.01002" ixy="0.007194" ixz="0.002041" iyy="0.03307" iyz="-0.0007281" izz="0.03728"/>
      <origin rpy="0 0 0" xyz="0.09450 -0.03354 0.008185"/>
    </inertial>
    <visual>
      <geometry>
        <mesh filename="package://r2_description/meshes/r2c_legs/r2cl_ext_bone1.dae"/>
      </geometry>
      <origin rpy="0 0 0" xyz="0 0 0"/>
    </visual>
    <collision>
      <geometry>
        <mesh filename="package://r2_description/meshes/r2c_legs/r2cl_ext_bone1.dae"/>
      </geometry>
      <material name="gold"/>
      <origin rpy="0 0 0" xyz="0 0 0"/>
    </collision>
  </link>
  <joint name="/r2/right_leg/joint4" type="revolute">
    <parent link="/r2/right_knee"/>
    <child link="/r2/right_lower_leg"/>
    <origin rpy="0 1.570796 0" xyz="0.200 -0.050 0.004"/>
    <axis xyz="0 0 1"/>
    <dynamics damping="5.0" friction="0.0"/>
    <limit effort="330.0" lower="-3.14159" upper="3.14159" velocity="1.0"/>
    <traits spring_k="2.5"/>
  </joint>
  <link name="/r2/right_lower_leg">
    <inertial>
      <mass value="3.7745"/>
      <inertia ixx="0.02163" ixy="-0.001453" ixz="0.003137" iyy="0.01832" iyz="0.004738" izz="0.009798"/>
      <origin rpy="0 0 0" xyz="-0.01485 -0.02188 0.09676"/>
    </inertial>
    <visual>
      <geometry>
        <mesh filename="package://r2_description/meshes/r2c_legs/r2cl_ext_bone2.dae"/>
      </geometry>
      <origin rpy="0 0 0" xyz="0 0 0"/>
    </visual>
    <collision>
      <geometry>
        <mesh filename="package://r2_description/meshes/r2c_legs/r2cl_ext_bone2.dae"/>
      </geometry>
      <origin rpy="0 0 0" xyz="0 0 0.0"/>
    </collision>
  </link>
  <joint name="/r2/right_leg/joint5" type="revolute">
    <parent link="/r2/right_lower_leg"/>
    <child link="/r2/right_ankle_pitch"/>
    <origin rpy="0.0 -1.570796 3.14159" xyz="-0.002 -0.050 0.157"/>
    <axis xyz="0 0 1"/>
    <dynamics damping="5.0" friction="0.0"/>
    <limit effort="330.0" lower="-0.10472" upper="2.68781" velocity="1.0"/>
    <traits spring_k="2.5"/>
  </joint>
  <link name="/r2/right_ankle_pitch">
    <inertial>
      <mass value="4.6734"/>
      <inertia ixx="0.01002" ixy="0.007194" ixz="0.002041" iyy="0.03307" iyz="-0.0007281" izz="0.03728"/>
      <origin rpy="0 0 0" xyz="0.09450 -0.03354 0.008185"/>
    </inertial>
    <visual>
      <geometry>
        <mesh filename="package://r2_description/meshes/r2c_legs/r2cl_ext_bone1.dae"/>
      </geometry>
      <origin rpy="0 0 0" xyz="0 0 0"/>
    </visual>
    <collision>
      <geometry>
        <mesh filename="package://r2_description/meshes/r2c_legs/r2cl_ext_bone1.dae"/>
      </geometry>
      <origin rpy="0 0 0" xyz="0 0 0"/>
    </collision>
  </link>
  <joint name="/r2/right_leg/joint6" type="revolute">
    <parent link="/r2/right_ankle_pitch"/>
    <child link="/r2/right_ankle_roll"/>
    <origin rpy="3.14159 -1.570796 0 " xyz="0.199643 -0.0508 0.00325"/>
    <axis xyz="0 0 1"/>
    <dynamics damping="5.0" friction="0.0"/>
    <limit effort="330.0" lower="-3.14159" upper="3.14159" velocity="1.0"/>
    <traits spring_k="2.5"/>
  </joint>
  <link name="/r2/right_ankle_roll">
    <inertial>
      <mass value="1.446"/>
      <inertia ixx="0.001780" ixy="0.00001801" ixz="0.0000002218" iyy="0.001767" iyz="0.0000006717" izz="0.002949"/>
      <origin rpy="0 0 0" xyz="-0.00004402 0.0001052 0.02940"/>
    </inertial>
    <visual>
      <geometry>
        <cylinder length=".06" radius=".066"/>
      </geometry>
      <material name="dirty_white"/>
      <origin rpy="0 0 0" xyz="0 0 0.025"/>
    </visual>
    <collision>
      <geometry>
        <cylinder length=".06" radius=".066"/>
      </geometry>
      <material name="gold"/>
      <origin rpy="0 0 0" xyz="0 0 0.025"/>
    </collision>
  </link>
  <joint name="/r2/fixed/right_ankle_roll/right_leg_ati" type="fixed">
    <parent link="/r2/right_ankle_roll"/>
    <child link="/r2/right_leg/ati"/>
    <origin rpy="3.1416 0.0 -1.5708" xyz="0.0 0.0 0.070182"/>
  </joint>
  <link name="/r2/right_leg/ati">
    <inertial>
      <mass value="0.01"/>
      <inertia ixx="0.0001" ixy="0.0" ixz="0.0" iyy="0.0001" iyz="0.0" izz="0.0001"/>
    </inertial>
  </link>
  <joint name="/r2/fixed/right_leg_ati/right_leg_foot" type="fixed">
    <parent link="/r2/right_leg/ati"/>
    <child link="/r2/right_leg_foot"/>
    <origin rpy="3.1416 0.0 -1.5708" xyz="0.0 0.0 0.0206502"/>
  </joint>
  <link name="/r2/right_leg_foot">
    <inertial>
      <mass value="4.4308"/>
      <inertia ixx="0.01928" ixy="-0.0003391" ixz="-0.0001325" iyy="0.01765" iyz="-0.0006598" izz="0.009944"/>
      <origin rpy="0 0 0" xyz="-0.001903 0.0002149 0.08495"/>
    </inertial>
    <visual>
      <geometry>
        <mesh filename="package://r2_description/meshes/r2c_legs/r2cl_foot.dae"/>
      </geometry>
      <material name="gold"/>
      <origin rpy="0 0 0" xyz="0 0 0"/>
    </visual>
    <collision>
      <geometry>
        <mesh filename="package://r2_description/meshes/r2c_legs/r2cl_foot.dae"/>
      </geometry>
      <origin rpy="0 0 0" xyz="0 0 0"/>
    </collision>
  </link>
  <link name="/r2/right_leg/gripper/tip">
    <inertial>
      <mass value="0.01"/>
      <inertia ixx="0.0001" ixy="0.0" ixz="0.0" iyy="0.0001" iyz="0.0" izz="0.0001"/>
    </inertial>
  </link>
  <joint name="/r2/fixed/right_leg_foot/right_hr_tip" type="fixed">
    <parent link="/r2/right_leg_foot"/>
    <child link="/r2/right_leg/gripper/tip"/>
    <origin rpy="0.0 0 0" xyz="0 0 0.19451"/>
  </joint>
  <joint name="/r2/right_leg/gripper/joint0" type="prismatic">
    <parent link="/r2/right_leg_foot"/>
    <child link="/r2/right_leg/gripper/link0"/>
    <origin rpy="0.0 0 0" xyz="0 0 0"/>
    <axis xyz="0 0 1"/>
    <dynamics damping="1.0" friction="0.0"/>
    <limit effort="330.0" lower="-.1" upper=".75" velocity="1.0"/>
  </joint>
  <joint name="/r2/right_leg/gripper/joint1" type="revolute">
    <parent link="/r2/right_leg_foot"/>
    <child link="/r2/right_leg_jaw0"/>
    <origin rpy="0.0 -0.087266 0.0 " xyz="0.01905 0 0.17546"/>
    <axis xyz="0 1 0"/>
    <dynamics damping="1.0" friction="0.0"/>
    <limit effort="330.0" lower="-.1" upper=".75" velocity="1.0"/>
    <traits spring_k="2.5"/>
  </joint>
  <joint name="/r2/right_leg/gripper/joint2" type="revolute">
    <parent link="/r2/right_leg_foot"/>
    <child link="/r2/right_leg_jaw1"/>
    <origin rpy="0.0 0.087266 0.0 " xyz="-0.01905 0 0.17546"/>
    <axis xyz="0 -1 0"/>
    <dynamics damping="1.0" friction="0.0"/>
    <limit effort="330.0" lower="-.1" upper=".75" velocity="1.0"/>
    <traits spring_k="2.5"/>
  </joint>
  <joint name="/r2/fixed/right_leg_foot/right_leg_camera0_physical" type="fixed">
    <parent link="/r2/right_leg_foot"/>
    <child link="/r2/right_leg_camera0_physical"/>
    <origin rpy="0.0 0  0" xyz="-0.025 .07 0.13"/>
  </joint>
  <joint name="/r2/fixed/right_leg_foot/right_leg_camera1_physical" type="fixed">
    <parent link="/r2/right_leg_foot"/>
    <child link="/r2/right_leg_camera1_physical"/>
    <origin rpy="0.0 0  0" xyz="0.025 .07 0.13"/>
  </joint>
  <link name="/r2/right_leg/gripper/link0">
    <inertial>
      <mass value="0.01"/>
      <inertia ixx="0.0001" ixy="0.0" ixz="0.0" iyy="0.0001" iyz="0.0" izz="0.0001"/>
    </inertial>
  </link>
  <link name="/r2/right_leg_jaw0">
    <inertial>
      <mass value="0.01"/>
      <inertia ixx="0.0001" ixy="0.0" ixz="0.0" iyy="0.0001" iyz="0.0" izz="0.0001"/>
      <origin rpy="0 0 0" xyz="0.00236 0 0.02395"/>
    </inertial>
    <visual>
      <geometry>
        <mesh filename="package://r2_description/meshes/r2c_legs/r2cl_foot_jaw1.dae"/>
      </geometry>
      <origin rpy="0 0 0" xyz="0 0 0"/>
    </visual>
    <collision>
      <geometry>
        <mesh filename="package://r2_description/meshes/r2c_legs/r2cl_foot_jaw1.dae"/>
      </geometry>
      <origin rpy="0 0 0" xyz="0 0 0"/>
    </collision>
  </link>
  <link name="/r2/right_leg_jaw1">
    <inertial>
      <mass value="0.01"/>
      <inertia ixx="0.0001" ixy="0.0" ixz="0.0" iyy="0.0001" iyz="0.0" izz="0.0001"/>
      <origin rpy="0 0 0" xyz="0.00236 0 0.02395"/>
    </inertial>
    <visual>
      <geometry>
        <mesh filename="package://r2_description/meshes/r2c_legs/r2cl_foot_jaw2.dae"/>
      </geometry>
      <origin rpy="0 0 0" xyz="0 0 0"/>
    </visual>
    <collision>
      <geometry>
        <mesh filename="package://r2_description/meshes/r2c_legs/r2cl_foot_jaw2.dae"/>
      </geometry>
      <origin rpy="0 0 0" xyz="0 0 0"/>
    </collision>
  </link>
  <link name="/r2/right_leg_camera0_physical">
    <inertial>
      <mass value="0.01"/>
      <inertia ixx="0.0001" ixy="0.0" ixz="0.0" iyy="0.0001" iyz="0.0" izz="0.0001"/>
    </inertial>
  </link>
  <joint name="/r2/fixed/right_leg_camera0_physical/right_leg_camera0_optical" type="fixed">
    <parent link="/r2/right_leg_camera0_physical"/>
    <child link="/r2/right_leg_camera0_optical"/>
    <origin rpy="0 -1.5708 -1.5708" xyz="0 0 0.03"/>
  </joint>
  <link name="/r2/right_leg_camera0_optical">
    <inertial>
      <mass value="0.01"/>
      <inertia ixx="0.0001" ixy="0.0" ixz="0.0" iyy="0.0001" iyz="0.0" izz="0.0001"/>
    </inertial>
  </link>
  <link name="/r2/right_leg_camera1_physical">
    <inertial>
      <mass value="0.01"/>
      <inertia ixx="0.0001" ixy="0.0" ixz="0.0" iyy="0.0001" iyz="0.0" izz="0.0001"/>
    </inertial>
  </link>
  <joint name="/r2/fixed/right_leg_camera1_physical/right_leg_camera1_optical" type="fixed">
    <parent link="/r2/right_leg_camera1_physical"/>
    <child link="/r2/right_leg_camera1_optical"/>
    <origin rpy="0 -1.5708 -1.5708" xyz="0 0 .03"/>
  </joint>
  <link name="/r2/right_leg_camera1_optical">
    <inertial>
      <mass value="0.01"/>
      <inertia ixx="0.0001" ixy="0.0" ixz="0.0" iyy="0.0001" iyz="0.0" izz="0.0001"/>
    </inertial>
  </link>
  <gazebo reference="/r2/pelvis">
    <selfCollide>false</selfCollide>
    <static>false</static>
    <turnGravityOff>false</turnGravityOff>
    <material></material>
  </gazebo>
  <gazebo reference="/r2/left_leg">
    <selfCollide>false</selfCollide>
    <static>false</static>
    <turnGravityOff>false</turnGravityOff>
    <material></material>
  </gazebo>
  <gazebo reference="/r2/left_hip_roll">
    <selfCollide>false</selfCollide>
    <static>false</static>
    <turnGravityOff>false</turnGravityOff>
    <material></material>
  </gazebo>
  <gazebo reference="/r2/left_hip_pitch">
    <selfCollide>false</selfCollide>
    <static>false</static>
    <turnGravityOff>false</turnGravityOff>
    <material></material>
  </gazebo>
  <gazebo reference="/r2/left_upper_leg">
    <selfCollide>false</selfCollide>
    <static>false</static>
    <turnGravityOff>false</turnGravityOff>
    <material></material>
  </gazebo>
  <gazebo reference="/r2/left_knee">
    <selfCollide>false</selfCollide>
    <static>false</static>
    <turnGravityOff>false</turnGravityOff>
    <material></material>
  </gazebo>
  <gazebo reference="/r2/left_lower_leg">
    <selfCollide>false</selfCollide>
    <static>false</static>
    <turnGravityOff>false</turnGravityOff>
    <material></material>
  </gazebo>
  <gazebo reference="/r2/left_ankle_pitch">
    <selfCollide>false</selfCollide>
    <static>false</static>
    <turnGravityOff>false</turnGravityOff>
    <material></material>
  </gazebo>
  <gazebo reference="/r2/left_ankle_roll">
    <selfCollide>false</selfCollide>
    <static>false</static>
    <turnGravityOff>false</turnGravityOff>
    <material>Gazebo/DirtyWhite</material>
  </gazebo>
  <gazebo reference="/r2/left_leg_foot">
    <selfCollide>false</selfCollide>
    <static>false</static>
    <turnGravityOff>false</turnGravityOff>
    <material></material>
  </gazebo>
  <gazebo reference="/r2/left_leg/gripper/link0">
    <selfCollide>false</selfCollide>
    <static>false</static>
    <turnGravityOff>false</turnGravityOff>
    <material></material>
  </gazebo>
  <gazebo reference="/r2/left_leg_jaw1">
    <selfCollide>false</selfCollide>
    <static>false</static>
    <turnGravityOff>false</turnGravityOff>
    <material></material>
  </gazebo>
  <gazebo reference="/r2/left_leg_jaw2">
    <selfCollide>false</selfCollide>
    <static>false</static>
    <turnGravityOff>false</turnGravityOff>
    <material></material>
  </gazebo>
  <gazebo reference="/r2/right_hip_roll">
    <selfCollide>false</selfCollide>
    <static>false</static>
    <turnGravityOff>false</turnGravityOff>
    <material></material>
  </gazebo>
  <gazebo reference="/r2/right_hip_pitch">
    <selfCollide>false</selfCollide>
    <static>false</static>
    <turnGravityOff>false</turnGravityOff>
    <material></material>
  </gazebo>
  <gazebo reference="/r2/right_upper_leg">
    <selfCollide>false</selfCollide>
    <static>false</static>
    <turnGravityOff>false</turnGravityOff>
    <material></material>
  </gazebo>
  <gazebo reference="/r2/right_knee">
    <selfCollide>false</selfCollide>
    <static>false</static>
    <turnGravityOff>false</turnGravityOff>
    <material></material>
  </gazebo>
  <gazebo reference="/r2/right_lower_leg">
    <selfCollide>false</selfCollide>
    <static>false</static>
    <turnGravityOff>false</turnGravityOff>
    <material></material>
  </gazebo>
  <gazebo reference="/r2/right_ankle_pitch">
    <selfCollide>false</selfCollide>
    <static>false</static>
    <turnGravityOff>false</turnGravityOff>
    <material></material>
  </gazebo>
  <gazebo reference="/r2/right_ankle_roll">
    <selfCollide>false</selfCollide>
    <static>false</static>
    <turnGravityOff>false</turnGravityOff>
    <material>Gazebo/DirtyWhite</material>
  </gazebo>
  <gazebo reference="/r2/right_leg_foot">
    <selfCollide>false</selfCollide>
    <static>false</static>
    <turnGravityOff>false</turnGravityOff>
    <material></material>
  </gazebo>
  <gazebo reference="/r2/right_leg/gripper/link0">
    <selfCollide>false</selfCollide>
    <static>false</static>
    <turnGravityOff>false</turnGravityOff>
    <material></material>
  </gazebo>
  <gazebo reference="/r2/right_leg_jaw1">
    <selfCollide>false</selfCollide>
    <static>false</static>
    <turnGravityOff>false</turnGravityOff>
    <material></material>
  </gazebo>
  <gazebo reference="/r2/right_leg_jaw2">
    <selfCollide>false</selfCollide>
    <static>false</static>
    <turnGravityOff>false</turnGravityOff>
    <material></material>
  </gazebo>
  <gazebo reference="/r2/left_leg/joint0">
    <stopKd value="1.0"/>
    <stopKp value="1000000.0"/>
  </gazebo>
  <gazebo reference="/r2/left_leg/joint1">
    <stopKd value="1.0"/>
    <stopKp value="1000000.0"/>
  </gazebo>
  <gazebo reference="/r2/left_leg/joint2">
    <stopKd value="1.0"/>
    <stopKp value="1000000.0"/>
  </gazebo>
  <gazebo reference="/r2/left_leg/joint3">
    <stopKd value="1.0"/>
    <stopKp value="1000000.0"/>
  </gazebo>
  <gazebo reference="/r2/left_leg/joint4">
    <stopKd value="1.0"/>
    <stopKp value="1000000.0"/>
  </gazebo>
  <gazebo reference="/r2/left_leg/joint5">
    <stopKd value="1.0"/>
    <stopKp value="1000000.0"/>
  </gazebo>
  <gazebo reference="/r2/left_leg/joint6">
    <stopKd value="1.0"/>
    <stopKp value="1000000.0"/>
  </gazebo>
  <gazebo reference="/r2/left_leg/gripper/joint0">
    <stopKd value="1.0"/>
    <stopKp value="1000000.0"/>
  </gazebo>
  <gazebo reference="/r2/left_leg/gripper/joint1">
    <stopKd value="1.0"/>
    <stopKp value="1000000.0"/>
  </gazebo>
  <gazebo reference="/r2/left_leg/gripper/joint2">
    <stopKd value="1.0"/>
    <stopKp value="1000000.0"/>
  </gazebo>
  <gazebo reference="/r2/right_leg/joint0">
    <stopKd value="1.0"/>
    <stopKp value="1000000.0"/>
  </gazebo>
  <gazebo reference="/r2/right_leg/joint1">
    <stopKd value="1.0"/>
    <stopKp value="1000000.0"/>
  </gazebo>
  <gazebo reference="/r2/right_leg/joint2">
    <stopKd value="1.0"/>
    <stopKp value="1000000.0"/>
  </gazebo>
  <gazebo reference="/r2/right_leg/joint3">
    <stopKd value="1.0"/>
    <stopKp value="1000000.0"/>
  </gazebo>
  <gazebo reference="/r2/right_leg/joint4">
    <stopKd value="1.0"/>
    <stopKp value="1000000.0"/>
  </gazebo>
  <gazebo reference="/r2/right_leg/joint5">
    <stopKd value="1.0"/>
    <stopKp value="1000000.0"/>
  </gazebo>
  <gazebo reference="/r2/right_leg/joint6">
    <stopKd value="1.0"/>
    <stopKp value="1000000.0"/>
  </gazebo>
  <gazebo reference="/r2/right_leg/gripper/joint0">
    <stopKd value="1.0"/>
    <stopKp value="1000000.0"/>
  </gazebo>
  <gazebo reference="/r2/right_leg/gripper/joint1">
    <stopKd value="1.0"/>
    <stopKp value="1000000.0"/>
  </gazebo>
  <gazebo reference="/r2/right_leg/gripper/joint2">
    <stopKd value="1.0"/>
    <stopKp value="1000000.0"/>
  </gazebo>
  <gazebo reference="/r2/left_leg_camera0_optical">
    <sensor:camera name="/r2/left_leg/gripper/camera0">
      <imageSize>1600 1200</imageSize>
      <imageFormat>R8G8B8</imageFormat>
      <hfov>90</hfov>
      <nearClip>0.10</nearClip>
      <farClip>50</farClip>
      <updateRate>10.0</updateRate>
      <controller:gazebo_ros_prosilica name="/r2/left_leg/gripper/camera0_controller" plugin="libgazebo_ros_prosilica.so">
        <alwaysOn>true</alwaysOn>
        <updateRate>20.0</updateRate>
        <cameraName>/r2/left_leg/gripper/camera0</cameraName>
        <imageTopicName>image_raw</imageTopicName>
        <cameraInfoTopicName>camera_info</cameraInfoTopicName>
        <pollServiceName>request_image</pollServiceName>
        <frameName>/r2/left_leg_camera0_optical</frameName>
        <CxPrime>1224.5</CxPrime>
        <Cx>802.4</Cx>
        <Cy>603.2</Cy>
        <focalLength>8330</focalLength>
        <distortionK1>0.00000001</distortionK1>
        <distortionK2>0.00000001</distortionK2>
        <distortionK3>0.00000001</distortionK3>
        <distortionT1>0.00000001</distortionT1>
        <distortionT2>0.00000001</distortionT2>
        <interface:camera name="/r2/left_leg/gripper/camera0_iface"/>
      </controller:gazebo_ros_prosilica>
    </sensor:camera>
    <turnGravityOff>false</turnGravityOff>
    <material>Gazebo/White</material>
  </gazebo>
  <gazebo reference="/r2/left_leg_camera1_optical">
    <sensor:camera name="/r2/left_leg/gripper/camera1">
      <imageSize>1600 1200</imageSize>
      <imageFormat>R8G8B8</imageFormat>
      <hfov>90</hfov>
      <nearClip>0.10</nearClip>
      <farClip>50</farClip>
      <updateRate>10.0</updateRate>
      <controller:gazebo_ros_prosilica name="/r2/left_leg/gripper/camera1_controller" plugin="libgazebo_ros_prosilica.so">
        <alwaysOn>true</alwaysOn>
        <updateRate>20.0</updateRate>
        <cameraName>/r2/left_leg/gripper/camera1</cameraName>
        <imageTopicName>image_raw</imageTopicName>
        <cameraInfoTopicName>camera_info</cameraInfoTopicName>
        <pollServiceName>request_image</pollServiceName>
        <frameName>/r2/left_leg_camera1_optical</frameName>
        <CxPrime>1224.5</CxPrime>
        <Cx>802.4</Cx>
        <Cy>603.2</Cy>
        <focalLength>8330</focalLength>
        <distortionK1>0.00000001</distortionK1>
        <distortionK2>0.00000001</distortionK2>
        <distortionK3>0.00000001</distortionK3>
        <distortionT1>0.00000001</distortionT1>
        <distortionT2>0.00000001</distortionT2>
        <interface:camera name="/r2/left_leg/gripper/camera1_iface"/>
      </controller:gazebo_ros_prosilica>
    </sensor:camera>
    <turnGravityOff>false</turnGravityOff>
    <material>Gazebo/White</material>
  </gazebo>
  <gazebo reference="/r2/right_leg_camera0_optical">
    <sensor:camera name="/r2/right_leg/gripper/camera0">
      <imageSize>1600 1200</imageSize>
      <imageFormat>R8G8B8</imageFormat>
      <hfov>90</hfov>
      <nearClip>0.10</nearClip>
      <farClip>50</farClip>
      <updateRate>10.0</updateRate>
      <controller:gazebo_ros_prosilica name="/r2/right_leg/gripper/camera0_controller" plugin="libgazebo_ros_prosilica.so">
        <alwaysOn>true</alwaysOn>
        <updateRate>20.0</updateRate>
        <cameraName>/r2/right_leg/gripper/camera0</cameraName>
        <imageTopicName>image_raw</imageTopicName>
        <cameraInfoTopicName>camera_info</cameraInfoTopicName>
        <pollServiceName>request_image</pollServiceName>
        <frameName>/r2/right_leg_camera0_optical</frameName>
        <CxPrime>1224.5</CxPrime>
        <Cx>802.4</Cx>
        <Cy>603.2</Cy>
        <focalLength>8330</focalLength>
        <distortionK1>0.00000001</distortionK1>
        <distortionK2>0.00000001</distortionK2>
        <distortionK3>0.00000001</distortionK3>
        <distortionT1>0.00000001</distortionT1>
        <distortionT2>0.00000001</distortionT2>
        <interface:camera name="/r2/right_leg/gripper/camera0_iface"/>
      </controller:gazebo_ros_prosilica>
    </sensor:camera>
    <turnGravityOff>false</turnGravityOff>
    <material>Gazebo/White</material>
  </gazebo>
  <gazebo reference="/r2/right_leg_camera1_optical">
    <sensor:camera name="/r2/right_leg/gripper/camera1">
      <imageSize>1600 1200</imageSize>
      <imageFormat>R8G8B8</imageFormat>
      <hfov>90</hfov>
      <nearClip>0.10</nearClip>
      <farClip>50</farClip>
      <updateRate>10.0</updateRate>
      <controller:gazebo_ros_prosilica name="/r2/right_leg/gripper/camera1_controller" plugin="libgazebo_ros_prosilica.so">
        <alwaysOn>true</alwaysOn>
        <updateRate>20.0</updateRate>
        <cameraName>/r2/right_leg/gripper/camera1</cameraName>
        <imageTopicName>image_raw</imageTopicName>
        <cameraInfoTopicName>camera_info</cameraInfoTopicName>
        <pollServiceName>request_image</pollServiceName>
        <frameName>/r2/right_leg_camera1_optical</frameName>
        <CxPrime>1224.5</CxPrime>
        <Cx>802.4</Cx>
        <Cy>603.2</Cy>
        <focalLength>8330</focalLength>
        <distortionK1>0.00000001</distortionK1>
        <distortionK2>0.00000001</distortionK2>
        <distortionK3>0.00000001</distortionK3>
        <distortionT1>0.00000001</distortionT1>
        <distortionT2>0.00000001</distortionT2>
        <interface:camera name="/r2/right_leg/gripper/camera1_iface"/>
      </controller:gazebo_ros_prosilica>
    </sensor:camera>
    <turnGravityOff>false</turnGravityOff>
    <material>Gazebo/White</material>
  </gazebo>
  <joint name="/r2//left_leg_laser_joint" type="revolute">
    <axis xyz="1 0 0"/>
    <limit effort="0" lower="0" upper="0" velocity="0"/>
    <origin rpy="-1.57 -1.57 3.14" xyz="0 0.1 0.15"/>
    <parent link="/r2/left_leg_foot"/>
    <child link="/r2//left_leg_laser_link"/>
  </joint>
  <link name="/r2//left_leg_laser_link" type="laser">
    <inertial>
      <mass value="0.001"/>
      <origin rpy="0 0 0" xyz="0 0 0"/>
      <inertia ixx="0.0001" ixy="0" ixz="0" iyy="0.000001" iyz="0" izz="0.0001"/>
    </inertial>
  </link>
  <gazebo reference="/r2//left_leg_laser_link">
    <sensor:ray name="/r2//left_leg_laser">
      <rayCount>640</rayCount>
      <rangeCount>640</rangeCount>
      <laserCount>1</laserCount>
      <origin>0.0 0.0 0.0</origin>
      <displayRays>false</displayRays>
      <minAngle>-80.2141590723</minAngle>
      <maxAngle>80.2141590723</maxAngle>
      <minRange>0.08</minRange>
      <maxRange>10.0</maxRange>
      <resRange>0.01</resRange>
      <updateRate>20</updateRate>
      <controller:gazebo_ros_laser name="gazebo_ros_/r2//left_leg_laser_controller" plugin="libgazebo_ros_laser.so">
        <gaussianNoise>0.005</gaussianNoise>
        <alwaysOn>true</alwaysOn>
        <updateRate>20</updateRate>
        <topicName>/r2//left_leg/gripper/line_scanner0</topicName>
        <frameName>/r2//left_leg_laser_link</frameName>
        <interface:laser name="gazebo_ros_/r2//left_leg_laser_iface"/>
      </controller:gazebo_ros_laser>
    </sensor:ray>
  </gazebo>
  <joint name="/r2//right_leg_laser_joint" type="revolute">
    <axis xyz="1 0 0"/>
    <limit effort="0" lower="0" upper="0" velocity="0"/>
    <origin rpy="-1.57 -1.57 3.14" xyz="0 0.1 0.15"/>
    <parent link="/r2/right_leg_foot"/>
    <child link="/r2//right_leg_laser_link"/>
  </joint>
  <link name="/r2//right_leg_laser_link" type="laser">
    <inertial>
      <mass value="0.001"/>
      <origin rpy="0 0 0" xyz="0 0 0"/>
      <inertia ixx="0.0001" ixy="0" ixz="0" iyy="0.000001" iyz="0" izz="0.0001"/>
    </inertial>
  </link>
  <gazebo reference="/r2//right_leg_laser_link">
    <sensor:ray name="/r2//right_leg_laser">
      <rayCount>640</rayCount>
      <rangeCount>640</rangeCount>
      <laserCount>1</laserCount>
      <origin>0.0 0.0 0.0</origin>
      <displayRays>false</displayRays>
      <minAngle>-80.2141590723</minAngle>
      <maxAngle>80.2141590723</maxAngle>
      <minRange>0.08</minRange>
      <maxRange>10.0</maxRange>
      <resRange>0.01</resRange>
      <updateRate>20</updateRate>
      <controller:gazebo_ros_laser name="gazebo_ros_/r2//right_leg_laser_controller" plugin="libgazebo_ros_laser.so">
        <gaussianNoise>0.005</gaussianNoise>
        <alwaysOn>true</alwaysOn>
        <updateRate>20</updateRate>
        <topicName>/r2//right_leg/gripper/line_scanner0</topicName>
        <frameName>/r2//right_leg_laser_link</frameName>
        <interface:laser name="gazebo_ros_/r2//right_leg_laser_iface"/>
      </controller:gazebo_ros_laser>
    </sensor:ray>
  </gazebo>
  <gazebo>
    <controller:gazebo_interface name="gazebo_interface" plugin="libgazebo_interface.so">
      <!--      <robotNamespace>/r2sim</robotNamespace>-->
      <paramsNamespace>r2_sim_params</paramsNamespace>
      <jointCommandsTopic>joint_commands</jointCommandsTopic>
      <jointStatesTopic>joint_states</jointStatesTopic>
      <jointCapabilitiesTopic>joint_capabilities</jointCapabilitiesTopic>
      <jointCommandRefsTopic>joint_command_refs</jointCommandRefsTopic>
      <jointStatesRate>50.0</jointStatesRate>
      <!--Hz, omit for fastest possible-->
      <advancedMode>false</advancedMode>
      <!-- if advancedMode=false, joint brakes, etc are not simulated and the following parameters are ignored -->
      <jointControlTopic>joint_control</jointControlTopic>
      <jointStatusTopic>joint_status</jointStatusTopic>
      <jointStatusRate>5.0</jointStatusRate>
      <!--Hz, omit for fastest possible-->
    </controller:gazebo_interface>
  </gazebo>
  <gazebo>
    <controller:gazebo_gripper name="left_gazebo_gripper" plugin="libgazebo_gripper.so">
      <updateRate>10.0</updateRate>
      <!--Hz-->
      <gripperAttachLink>/r2/left_ankle_roll</gripperAttachLink>
      <!--      <gripperAttachLink>/r2/waist_center</gripperAttachLink>-->
      <gripperLink>/r2/left_leg_jaw0</gripperLink>
      <gripperLink>/r2/left_leg_jaw1</gripperLink>
      <maxRelativeMotionRate>0.0001</maxRelativeMotionRate>
      <!--units/second-->
      <attachWait>2.0</attachWait>
      <!--seconds-->
      <detachWait>0.0</detachWait>
      <!--seconds-->
    </controller:gazebo_gripper>
  </gazebo>
  <gazebo>
    <controller:gazebo_gripper name="right_gazebo_gripper" plugin="libgazebo_gripper.so">
      <updateRate>10.0</updateRate>
      <!--Hz-->
      <gripperAttachLink>/r2/right_ankle_roll</gripperAttachLink>
      <gripperLink>/r2/right_leg_jaw0</gripperLink>
      <gripperLink>/r2/right_leg_jaw1</gripperLink>
      <maxRelativeMotionRate>0.0001</maxRelativeMotionRate>
      <!--units/second-->
      <attachWait>2.0</attachWait>
      <!--seconds-->
      <detachWait>0.0</detachWait>
      <!--seconds-->
    </controller:gazebo_gripper>
  </gazebo>
</robot>

