<?xml version="1.0"?>
<robot xmlns:controller="http://playerstage.sourceforge.net/gazebo/xmlschema/#controller">
  <link name="world"/>
  <link name="dummy">
    <inertial>
      <mass value="1"/>
      <inertia ixx="1" ixy="0.0" ixz="0.0" iyy="1" iyz="0.0" izz="1"/>
    </inertial>
  </link>
  <link name="taskboard_lower">
    <visual>
      <geometry>
        <mesh filename="package://r2_gazebo/Media/models/taskboard/tskbd_lower_assembly_robonaut.dae"/>
      </geometry>
      <origin xyz="0.0 0.0 0.0" rpy="0 0 0"/>
    </visual>
    <collision>
      <geometry>
        <mesh filename="package://r2_gazebo/Media/models/taskboard/tskbd_lower_assembly_robonaut.dae" scale="0 0 0"/>
      </geometry>
      <origin xyz="0.0 0.0 0.0" rpy="0 0 0"/>
    </collision>
    <inertial>
      <mass value="5"/>
      <inertia ixx="1" ixy="0.0" ixz="0.0" iyy="1" iyz="0.0" izz="1"/>
    </inertial>
  </link>

  <link name="taskboard_lower_labels">
    <visual>
      <geometry>
        <mesh filename="package://r2_gazebo/Media/models/taskboard/tskbd_lower_assembly_labels.dae"/>
      </geometry>
      <origin xyz="0.0 0.0 0.0" rpy="0 0 0"/>
    </visual>
    <collision>
      <geometry>
        <mesh filename="package://r2_gazebo/Media/models/taskboard/tskbd_lower_assembly_labels.dae" scale="0 0 0"/>
      </geometry>
      <origin xyz="0.0 0.0 0.0" rpy="0 0 0"/>
    </collision>
    <inertial>
      <mass value="5"/>
      <inertia ixx="1" ixy="0.0" ixz="0.0" iyy="1" iyz="0.0" izz="1"/>
    </inertial>
  </link>

  <link name="taskboard_slot3">
    <visual>
      <geometry>
        <mesh filename="package://r2_gazebo/Media/models/taskboard/tskbd_panel_assembly_eva_slot3.dae"/>
      </geometry>
      <origin xyz="0.0 0.0 0.0" rpy="0 0 0"/>
    </visual>
    <collision>
      <geometry>
        <mesh filename="package://r2_gazebo/Media/models/taskboard/tskbd_panel_assembly_eva_slot3.dae" scale="1 1 1"/>
      </geometry>
      <origin xyz="0.0 0.0 0.0" rpy="0 0 0"/>
    </collision>
    <inertial>
      <mass value="5"/>
      <inertia ixx="1" ixy="0.0" ixz="0.0" iyy="1" iyz="0.0" izz="1"/>
    </inertial>
  </link>

  <link name="taskboard_slot3_panel">
    <visual>
      <geometry>
        <mesh filename="package://r2_gazebo/Media/models/taskboard/tskbd_panel_assembly_slot1_panel.dae"/>
      </geometry>
      <origin xyz="0.0 0.0 0.0" rpy="0 0 0"/>
    </visual>
    <collision>
      <geometry>
        <mesh filename="package://r2_gazebo/Media/models/taskboard/tskbd_panel_assembly_slot1_panel.dae" scale="1 1 1"/>
      </geometry>
      <origin xyz="0.0 0.0 0.0" rpy="0 0 0"/>
    </collision>
    <inertial>
      <mass value="5"/>
      <inertia ixx="1" ixy="0.0" ixz="0.0" iyy="1" iyz="0.0" izz="1"/>
    </inertial>
  </link>

  <link name="taskboard_slot3_labels">
    <visual>
      <geometry>
        <mesh filename="package://r2_gazebo/Media/models/taskboard/tskbd_panel_assembly_eva_slot3_labels.dae"/>
      </geometry>
      <origin xyz="0.0 0.0 0.0" rpy="0 0 0"/>
    </visual>
    <collision>
      <geometry>
        <mesh filename="package://r2_gazebo/Media/models/taskboard/tskbd_panel_assembly_eva_slot3_labels.dae" scale="1 1 1"/>
      </geometry>
      <origin xyz="0.0 0.0 0.0" rpy="0 0 0"/>
    </collision>
    <inertial>
      <mass value="5"/>
      <inertia ixx="1" ixy="0.0" ixz="0.0" iyy="1" iyz="0.0" izz="1"/>
    </inertial>
  </link>

  <link name="taskboard_slot4">
    <visual>
      <geometry>
        <mesh filename="package://r2_gazebo/Media/models/taskboard/tskbd_panel_assembly_slot4.dae"/>
      </geometry>
      <origin xyz="0.0 0.0 0.0" rpy="0 0 0"/>
    </visual>
    <collision>
      <geometry>
        <mesh filename="package://r2_gazebo/Media/models/taskboard/tskbd_panel_assembly_slot4.dae" scale="1 1 1"/>
      </geometry>
      <origin xyz="0.0 0.0 0.0" rpy="0 0 0"/>
    </collision>
    <inertial>
      <mass value="5"/>
      <inertia ixx="1" ixy="0.0" ixz="0.0" iyy="1" iyz="0.0" izz="1"/>
    </inertial>
  </link>

  <link name="taskboard_slot4_panel">
    <visual>
      <geometry>
        <mesh filename="package://r2_gazebo/Media/models/taskboard/tskbd_panel_assembly_slot4_panel.dae"/>
      </geometry>
      <origin xyz="0.0 0.0 0.0" rpy="0 0 0"/>
    </visual>
    <collision>
      <geometry>
        <mesh filename="package://r2_gazebo/Media/models/taskboard/tskbd_panel_assembly_slot4_panel.dae" scale="1 1 1"/>
      </geometry>
      <origin xyz="0.0 0.0 0.0" rpy="0 0 0"/>
    </collision>
    <inertial>
      <mass value="5"/>
      <inertia ixx="1" ixy="0.0" ixz="0.0" iyy="1" iyz="0.0" izz="1"/>
    </inertial>
  </link>

  <link name="taskboard_slot4_labels">
    <visual>
      <geometry>
        <mesh filename="package://r2_gazebo/Media/models/taskboard/tskbd_panel_assembly_slot4_labels.dae"/>
      </geometry>
      <origin xyz="0.0 0.0 0.0" rpy="0 0 0"/>
    </visual>
    <collision>
      <geometry>
        <mesh filename="package://r2_gazebo/Media/models/taskboard/tskbd_panel_assembly_slot4_labels.dae" scale="1 1 1"/>
      </geometry>
      <origin xyz="0.0 0.0 0.0" rpy="0 0 0"/>
    </collision>
    <inertial>
      <mass value="5"/>
      <inertia ixx="1" ixy="0.0" ixz="0.0" iyy="1" iyz="0.0" izz="1"/>
    </inertial>
  </link>

  <link name="taskboard_slot1">
    <visual>
      <geometry>
        <mesh filename="package://r2_gazebo/Media/models/taskboard/tskbd_panel_assembly_slot1.dae"/>
      </geometry>
      <origin xyz="0.0 0.0 0.0" rpy="0 0 0"/>
    </visual>
    <collision>
      <geometry>
        <mesh filename="package://r2_gazebo/Media/models/taskboard/tskbd_panel_assembly_slot1.dae" scale="1 1 1"/>
      </geometry>
      <origin xyz="0.0 0.0 0.0" rpy="0 0 0"/>
    </collision>
    <inertial>
      <mass value="5"/>
      <inertia ixx="1" ixy="0.0" ixz="0.0" iyy="1" iyz="0.0" izz="1"/>
    </inertial>
  </link>

  <link name="taskboard_slot1_panel">
    <visual>
      <geometry>
        <mesh filename="package://r2_gazebo/Media/models/taskboard/tskbd_panel_assembly_slot1_panel.dae"/>
      </geometry>
      <origin xyz="0.0 0.0 0.0" rpy="0 0 0"/>
    </visual>
    <collision>
      <geometry>
        <mesh filename="package://r2_gazebo/Media/models/taskboard/tskbd_panel_assembly_slot1_panel.dae" scale="1 1 1"/>
      </geometry>
      <origin xyz="0.0 0.0 0.0" rpy="0 0 0"/>
    </collision>
    <inertial>
      <mass value="5"/>
      <inertia ixx="1" ixy="0.0" ixz="0.0" iyy="1" iyz="0.0" izz="1"/>
    </inertial>
  </link>

  <link name="taskboard_slot1_labels">
    <visual>
      <geometry>
        <mesh filename="package://r2_gazebo/Media/models/taskboard/tskbd_panel_assembly_slot1_labels.dae"/>
      </geometry>
      <origin xyz="0.0 0.0 0.0" rpy="0 0 0"/>
    </visual>
    <collision>
      <geometry>
        <mesh filename="package://r2_gazebo/Media/models/taskboard/tskbd_panel_assembly_slot1_labels.dae" scale="1 1 1"/>
      </geometry>
      <origin xyz="0.0 0.0 0.0" rpy="0 0 0"/>
    </collision>
    <inertial>
      <mass value="5"/>
      <inertia ixx="1" ixy="0.0" ixz="0.0" iyy="1" iyz="0.0" izz="1"/>
    </inertial>
  </link>

  <link name="taskboard_slot1_switch1">
    <visual>
      <geometry>
        <mesh filename="package://r2_gazebo/Media/models/taskboard/tskbd_panel_assembly_slot1_switch1.dae"/>
      </geometry>
      <origin xyz="0.0 0.0 0.0" rpy="0 0 0"/>
    </visual>
    <collision>
      <geometry>
        <mesh filename="package://r2_gazebo/Media/models/taskboard/tskbd_panel_assembly_slot1_switch1.dae" scale="1 1 1"/>
      </geometry>
      <origin xyz="0.0 0.0 0.0" rpy="0 0 0"/>
    </collision>
    <inertial>
      <mass value="0.5"/>
      <inertia ixx="1" ixy="0.0" ixz="0.0" iyy="1" iyz="0.0" izz="1"/>
    </inertial>
  </link>

  <link name="taskboard_slot1_switch2_pullout">
    <inertial>
      <mass value=".01"/>
      <inertia ixx="1" ixy="0.0" ixz="0.0" iyy="1" iyz="0.0" izz="1"/>
    </inertial>
  </link>

  <link name="taskboard_slot1_switch2">
    <visual>
      <geometry>
        <mesh filename="package://r2_gazebo/Media/models/taskboard/tskbd_panel_assembly_slot1_switch2.dae"/>
      </geometry>
      <origin xyz="0.0 0.0 0.0" rpy="0 0 0"/>
    </visual>
    <collision>
      <geometry>
        <mesh filename="package://r2_gazebo/Media/models/taskboard/tskbd_panel_assembly_slot1_switch2.dae" scale="1 1 1"/>
      </geometry>
      <origin xyz="0.0 0.0 0.0" rpy="0 0 0"/>
    </collision>
    <inertial>
      <mass value="0.5"/>
      <inertia ixx="1" ixy="0.0" ixz="0.0" iyy="1" iyz="0.0" izz="1"/>
    </inertial>
  </link>

  <link name="taskboard_slot1_switch3_pullout">
    <inertial>
      <mass value=".01"/>
      <inertia ixx="1" ixy="0.0" ixz="0.0" iyy="1" iyz="0.0" izz="1"/>
    </inertial>
  </link>

  <link name="taskboard_slot1_switch3">
    <visual>
      <geometry>
        <mesh filename="package://r2_gazebo/Media/models/taskboard/tskbd_panel_assembly_slot1_switch3.dae"/>
      </geometry>
      <origin xyz="0.0 0.0 0.0" rpy="0 0 0"/>
    </visual>
    <collision>
      <geometry>
        <mesh filename="package://r2_gazebo/Media/models/taskboard/tskbd_panel_assembly_slot1_switch3.dae" scale="1 1 1"/>
      </geometry>
      <origin xyz="0.0 0.0 0.0" rpy="0 0 0"/>
    </collision>
    <inertial>
      <mass value="0.5"/>
      <inertia ixx="1" ixy="0.0" ixz="0.0" iyy="1" iyz="0.0" izz="1"/>
    </inertial>
  </link>

  <link name="taskboard_slot1_switch4_pullout">
    <inertial>
      <mass value=".01"/>
      <inertia ixx="1" ixy="0.0" ixz="0.0" iyy="1" iyz="0.0" izz="1"/>
    </inertial>
  </link>

  <link name="taskboard_slot1_switch4">
    <visual>
      <geometry>
        <mesh filename="package://r2_gazebo/Media/models/taskboard/tskbd_panel_assembly_slot1_switch4.dae"/>
      </geometry>
      <origin xyz="0.0 0.0 0.0" rpy="0 0 0"/>
    </visual>
    <collision>
      <geometry>
        <mesh filename="package://r2_gazebo/Media/models/taskboard/tskbd_panel_assembly_slot1_switch4.dae" scale="1 1 1"/>
      </geometry>
      <origin xyz="0.0 0.0 0.0" rpy="0 0 0"/>
    </collision>
    <inertial>
      <mass value="0.5"/>
      <inertia ixx="1" ixy="0.0" ixz="0.0" iyy="1" iyz="0.0" izz="1"/>
    </inertial>
  </link>

  <link name="taskboard_slot1_switch1_cover">
    <visual>
      <geometry>
        <mesh filename="package://r2_gazebo/Media/models/taskboard/tskbd_panel_assembly_slot1_switch1_cover.dae"/>
      </geometry>
      <origin xyz="0.0 0.0 0.0" rpy="0 0 0"/>
    </visual>
    <collision>
      <geometry>
        <mesh filename="package://r2_gazebo/Media/models/taskboard/tskbd_panel_assembly_slot1_switch1_cover.dae" scale="1 1 1"/>
      </geometry>
      <origin xyz="0.0 0.0 0.0" rpy="0 0 0"/>
    </collision>
    <inertial>
      <mass value="0.5"/>
      <inertia ixx="1" ixy="0.0" ixz="0.0" iyy="1" iyz="0.0" izz="1"/>
    </inertial>
  </link>

  <link name="taskboard_slot1_guard">
    <visual>
      <geometry>
        <mesh filename="package://r2_gazebo/Media/models/taskboard/tskbd_panel_assembly_slot1_guard.dae"/>
      </geometry>
      <origin xyz="0.0 0.0 0.0" rpy="0 0 0"/>
    </visual>
    <collision>
      <geometry>
        <mesh filename="package://r2_gazebo/Media/models/taskboard/tskbd_panel_assembly_slot1_guard.dae" scale="1 1 1"/>
      </geometry>
      <origin xyz="0.0 0.0 0.0" rpy="0 0 0"/>
    </collision>
    <inertial>
      <mass value="5"/>
      <inertia ixx="1" ixy="0.0" ixz="0.0" iyy="1" iyz="0.0" izz="1"/>
    </inertial>
  </link>

  <link name="taskboard_slot1_A1">
    <visual>
      <geometry>
        <mesh filename="package://r2_gazebo/Media/models/taskboard/tskbd_panel_assembly_slot1_a1.dae"/>
      </geometry>
      <origin xyz="0.0 0.0 0.0" rpy="0 0 0"/>
    </visual>
    <collision>
      <geometry>
        <mesh filename="package://r2_gazebo/Media/models/taskboard/tskbd_panel_assembly_slot1_a1.dae" scale="1 1 1"/>
      </geometry>
      <origin xyz="0.0 0.0 0.0" rpy="0 0 0"/>
    </collision>
    <inertial>
      <mass value="0.5"/>
      <inertia ixx="1" ixy="0.0" ixz="0.0" iyy="1" iyz="0.0" izz="1"/>
    </inertial>
  </link>

  <link name="taskboard_slot1_A2">
    <visual>
      <geometry>
        <mesh filename="package://r2_gazebo/Media/models/taskboard/tskbd_panel_assembly_slot1_a2.dae"/>
      </geometry>
      <origin xyz="0.0 0.0 0.0" rpy="0 0 0"/>
    </visual>
    <collision>
      <geometry>
        <mesh filename="package://r2_gazebo/Media/models/taskboard/tskbd_panel_assembly_slot1_a2.dae" scale="1 1 1"/>
      </geometry>
      <origin xyz="0.0 0.0 0.0" rpy="0 0 0"/>
    </collision>
    <inertial>
      <mass value="0.5"/>
      <inertia ixx="1" ixy="0.0" ixz="0.0" iyy="1" iyz="0.0" izz="1"/>
    </inertial>
  </link>

  <link name="taskboard_slot1_A3">
    <visual>
      <geometry>
        <mesh filename="package://r2_gazebo/Media/models/taskboard/tskbd_panel_assembly_slot1_a3.dae"/>
      </geometry>
      <origin xyz="0.0 0.0 0.0" rpy="0 0 0"/>
    </visual>
    <collision>
      <geometry>
        <mesh filename="package://r2_gazebo/Media/models/taskboard/tskbd_panel_assembly_slot1_a3.dae" scale="1 1 1"/>
      </geometry>
      <origin xyz="0.0 0.0 0.0" rpy="0 0 0"/>
    </collision>
    <inertial>
      <mass value="0.5"/>
      <inertia ixx="1" ixy="0.0" ixz="0.0" iyy="1" iyz="0.0" izz="1"/>
    </inertial>
  </link>

  <link name="taskboard_slot1_B1">
    <visual>
      <geometry>
        <mesh filename="package://r2_gazebo/Media/models/taskboard/tskbd_panel_assembly_slot1_b1.dae"/>
      </geometry>
      <origin xyz="0.0 0.0 0.0" rpy="0 0 0"/>
    </visual>
    <collision>
      <geometry>
        <mesh filename="package://r2_gazebo/Media/models/taskboard/tskbd_panel_assembly_slot1_b1.dae" scale="1 1 1"/>
      </geometry>
      <origin xyz="0.0 0.0 0.0" rpy="0 0 0"/>
    </collision>
    <inertial>
      <mass value="0.5"/>
      <inertia ixx="1" ixy="0.0" ixz="0.0" iyy="1" iyz="0.0" izz="1"/>
    </inertial>
  </link>

  <link name="taskboard_slot1_B2">
    <visual>
      <geometry>
        <mesh filename="package://r2_gazebo/Media/models/taskboard/tskbd_panel_assembly_slot1_b2.dae"/>
      </geometry>
      <origin xyz="0.0 0.0 0.0" rpy="0 0 0"/>
    </visual>
    <collision>
      <geometry>
        <mesh filename="package://r2_gazebo/Media/models/taskboard/tskbd_panel_assembly_slot1_b2.dae" scale="1 1 1"/>
      </geometry>
      <origin xyz="0.0 0.0 0.0" rpy="0 0 0"/>
    </collision>
    <inertial>
      <mass value="0.5"/>
      <inertia ixx="1" ixy="0.0" ixz="0.0" iyy="1" iyz="0.0" izz="1"/>
    </inertial>
  </link>

  <link name="taskboard_slot1_B3">
    <visual>
      <geometry>
        <mesh filename="package://r2_gazebo/Media/models/taskboard/tskbd_panel_assembly_slot1_b3.dae"/>
      </geometry>
      <origin xyz="0.0 0.0 0.0" rpy="0 0 0"/>
    </visual>
    <collision>
      <geometry>
        <mesh filename="package://r2_gazebo/Media/models/taskboard/tskbd_panel_assembly_slot1_b3.dae" scale="1 1 1"/>
      </geometry>
      <origin xyz="0.0 0.0 0.0" rpy="0 0 0"/>
    </collision>
    <inertial>
      <mass value="0.5"/>
      <inertia ixx="1" ixy="0.0" ixz="0.0" iyy="1" iyz="0.0" izz="1"/>
    </inertial>
  </link>

  <link name="taskboard_slot1_C1">
    <visual>
      <geometry>
        <mesh filename="package://r2_gazebo/Media/models/taskboard/tskbd_panel_assembly_slot1_c1.dae"/>
      </geometry>
      <origin xyz="0.0 0.0 0.0" rpy="0 0 0"/>
    </visual>
    <collision>
      <geometry>
        <mesh filename="package://r2_gazebo/Media/models/taskboard/tskbd_panel_assembly_slot1_c1.dae" scale="1 1 1"/>
      </geometry>
      <origin xyz="0.0 0.0 0.0" rpy="0 0 0"/>
    </collision>
    <inertial>
      <mass value="0.5"/>
      <inertia ixx="1" ixy="0.0" ixz="0.0" iyy="1" iyz="0.0" izz="1"/>
    </inertial>
  </link>

  <link name="taskboard_slot1_C2">
    <visual>
      <geometry>
        <mesh filename="package://r2_gazebo/Media/models/taskboard/tskbd_panel_assembly_slot1_c2.dae"/>
      </geometry>
      <origin xyz="0.0 0.0 0.0" rpy="0 0 0"/>
    </visual>
    <collision>
      <geometry>
        <mesh filename="package://r2_gazebo/Media/models/taskboard/tskbd_panel_assembly_slot1_c2.dae" scale="1 1 1"/>
      </geometry>
      <origin xyz="0.0 0.0 0.0" rpy="0 0 0"/>
    </collision>
    <inertial>
      <mass value="0.5"/>
      <inertia ixx="1" ixy="0.0" ixz="0.0" iyy="1" iyz="0.0" izz="1"/>
    </inertial>
  </link>

  <link name="taskboard_slot1_C3">
    <visual>
      <geometry>
        <mesh filename="package://r2_gazebo/Media/models/taskboard/tskbd_panel_assembly_slot1_c3.dae"/>
      </geometry>
      <origin xyz="0.0 0.0 0.0" rpy="0 0 0"/>
    </visual>
    <collision>
      <geometry>
        <mesh filename="package://r2_gazebo/Media/models/taskboard/tskbd_panel_assembly_slot1_c3.dae" scale="1 1 1"/>
      </geometry>
      <origin xyz="0.0 0.0 0.0" rpy="0 0 0"/>
    </collision>
    <inertial>
      <mass value="0.5"/>
      <inertia ixx="1" ixy="0.0" ixz="0.0" iyy="1" iyz="0.0" izz="1"/>
    </inertial>
  </link>

  <link name="taskboard_slot1_blackplate">
    <visual>
      <geometry>
        <mesh filename="package://r2_gazebo/Media/models/taskboard/tskbd_panel_assembly_slot1_blackplate.dae"/>
      </geometry>
      <origin xyz="0.0 0.0 0.0" rpy="0 0 0"/>
    </visual>
    <collision>
      <geometry>
        <mesh filename="package://r2_gazebo/Media/models/taskboard/tskbd_panel_assembly_slot1_blackplate.dae" scale="1 1 1"/>
      </geometry>
      <origin xyz="0.0 0.0 0.0" rpy="0 0 0"/>
    </collision>
    <inertial>
      <mass value="5"/>
      <inertia ixx="1" ixy="0.0" ixz="0.0" iyy="1" iyz="0.0" izz="1"/>
    </inertial>
  </link>

  <link name="taskboard_slot1_switch">
    <visual>
      <geometry>
        <mesh filename="package://r2_gazebo/Media/models/taskboard/tskbd_panel_assembly_slot1_switch.dae"/>
      </geometry>
      <origin xyz="0.0 0.0 0.0" rpy="0 0 0"/>
    </visual>
    <collision>
      <geometry>
        <mesh filename="package://r2_gazebo/Media/models/taskboard/tskbd_panel_assembly_slot1_switch.dae" scale="1 1 1"/>
      </geometry>
      <origin xyz="0.0 0.0 0.0" rpy="0 0 0"/>
    </collision>
    <inertial>
      <mass value="0.5"/>
      <inertia ixx="1" ixy="0.0" ixz="0.0" iyy="1" iyz="0.0" izz="1"/>
    </inertial>
  </link>

  <link name="taskboard_slot2">
    <visual>
      <geometry>
        <mesh filename="package://r2_gazebo/Media/models/taskboard/tskbd_panel_assembly_slot2.dae"/>
      </geometry>
      <origin xyz="0.0 0.0 0.0" rpy="0 0 0"/>
    </visual>
    <collision>
      <geometry>
        <mesh filename="package://r2_gazebo/Media/models/taskboard/tskbd_panel_assembly_slot2.dae" scale="1 1 1"/>
      </geometry>
      <origin xyz="0.0 0.0 0.0" rpy="0 0 0"/>
    </collision>
    <inertial>
      <mass value="5"/>
      <inertia ixx="1" ixy="0.0" ixz="0.0" iyy="1" iyz="0.0" izz="1"/>
    </inertial>
  </link>

  <link name="taskboard_slot2_panel">
    <visual>
      <geometry>
        <mesh filename="package://r2_gazebo/Media/models/taskboard/tskbd_panel_assembly_slot1_panel.dae"/>
      </geometry>
      <origin xyz="0.0 0.0 0.0" rpy="0 0 0"/>
    </visual>
    <collision>
      <geometry>
        <mesh filename="package://r2_gazebo/Media/models/taskboard/tskbd_panel_assembly_slot1_panel.dae" scale="1 1 1"/>
      </geometry>
      <origin xyz="0.0 0.0 0.0" rpy="0 0 0"/>
    </collision>
    <inertial>
      <mass value="5"/>
      <inertia ixx="1" ixy="0.0" ixz="0.0" iyy="1" iyz="0.0" izz="1"/>
    </inertial>
  </link>

  <link name="taskboard_slot2_labels1">
    <visual>
      <geometry>
        <mesh filename="package://r2_gazebo/Media/models/taskboard/tskbd_panel_assembly_slot2_labels1.dae"/>
      </geometry>
      <origin xyz="0.0 0.0 0.0" rpy="0 0 0"/>
    </visual>
    <collision>
      <geometry>
        <mesh filename="package://r2_gazebo/Media/models/taskboard/tskbd_panel_assembly_slot2_labels1.dae" scale="1 1 1"/>
      </geometry>
      <origin xyz="0.0 0.0 0.0" rpy="0 0 0"/>
    </collision>
    <inertial>
      <mass value="5"/>
      <inertia ixx="1" ixy="0.0" ixz="0.0" iyy="1" iyz="0.0" izz="1"/>
    </inertial>
  </link>

  <link name="taskboard_slot2_labels2">
    <visual>
      <geometry>
        <mesh filename="package://r2_gazebo/Media/models/taskboard/tskbd_panel_assembly_slot2_labels2.dae"/>
      </geometry>
      <origin xyz="0.0 0.0 0.0" rpy="0 0 0"/>
    </visual>
    <collision>
      <geometry>
        <mesh filename="package://r2_gazebo/Media/models/taskboard/tskbd_panel_assembly_slot2_labels2.dae" scale="1 1 1"/>
      </geometry>
      <origin xyz="0.0 0.0 0.0" rpy="0 0 0"/>
    </collision>
    <inertial>
      <mass value="5"/>
      <inertia ixx="1" ixy="0.0" ixz="0.0" iyy="1" iyz="0.0" izz="1"/>
    </inertial>
  </link>

  <link name="taskboard_slot2_B06">
    <visual>
      <geometry>
        <mesh filename="package://r2_gazebo/Media/models/taskboard/tskbd_panel_assembly_slot2_b06.dae"/>
      </geometry>
      <origin xyz="0.0 0.0 0.0" rpy="0 0 0"/>
    </visual>
    <collision>
      <geometry>
        <mesh filename="package://r2_gazebo/Media/models/taskboard/tskbd_panel_assembly_slot2_b06.dae" scale="1 1 1"/>
      </geometry>
      <origin xyz="0.0 0.0 0.0" rpy="0 0 0"/>
    </collision>
    <inertial>
      <mass value="5"/>
      <inertia ixx="1" ixy="0.0" ixz="0.0" iyy="1" iyz="0.0" izz="1"/>
    </inertial>
  </link>

  <link name="taskboard_slot2_B06_Base">
    <visual>
      <geometry>
        <mesh filename="package://r2_gazebo/Media/models/taskboard/tskbd_panel_assembly_slot2_b06_base.dae"/>
      </geometry>
      <origin xyz="0.0 0.0 0.0" rpy="0 0 0"/>
    </visual>
    <collision>
      <geometry>
        <mesh filename="package://r2_gazebo/Media/models/taskboard/tskbd_panel_assembly_slot2_b06_base.dae" scale="1 1 1"/>
      </geometry>
      <origin xyz="0.0 0.0 0.0" rpy="0 0 0"/>
    </collision>
    <inertial>
      <mass value="5"/>
      <inertia ixx="1" ixy="0.0" ixz="0.0" iyy="1" iyz="0.0" izz="1"/>
    </inertial>
  </link>

  <link name="taskboard_slot2_B04">
    <visual>
      <geometry>
        <mesh filename="package://r2_gazebo/Media/models/taskboard/tskbd_panel_assembly_slot2_b04.dae"/>
      </geometry>
      <origin xyz="0.0 0.0 0.0" rpy="0 0 0"/>
    </visual>
    <collision>
      <geometry>
        <mesh filename="package://r2_gazebo/Media/models/taskboard/tskbd_panel_assembly_slot2_b04.dae" scale="1 1 1"/>
      </geometry>
      <origin xyz="0.0 0.0 0.0" rpy="0 0 0"/>
    </collision>
    <inertial>
      <mass value="5"/>
      <inertia ixx="1" ixy="0.0" ixz="0.0" iyy="1" iyz="0.0" izz="1"/>
    </inertial>
  </link>

  <link name="taskboard_slot2_B04_Base">
    <visual>
      <geometry>
        <mesh filename="package://r2_gazebo/Media/models/taskboard/tskbd_panel_assembly_slot2_b04_base.dae"/>
      </geometry>
      <origin xyz="0.0 0.0 0.0" rpy="0 0 0"/>
    </visual>
    <collision>
      <geometry>
        <mesh filename="package://r2_gazebo/Media/models/taskboard/tskbd_panel_assembly_slot2_b04_base.dae" scale="1 1 1"/>
      </geometry>
      <origin xyz="0.0 0.0 0.0" rpy="0 0 0"/>
    </collision>
    <inertial>
      <mass value="5"/>
      <inertia ixx="1" ixy="0.0" ixz="0.0" iyy="1" iyz="0.0" izz="1"/>
    </inertial>
  </link>

  <link name="taskboard_slot2_B04_Cap">
    <visual>
      <geometry>
        <mesh filename="package://r2_gazebo/Media/models/taskboard/tskbd_panel_assembly_slot2_b04_cap.dae"/>
      </geometry>
      <origin xyz="0.0 0.0 0.0" rpy="0 0 0"/>
    </visual>
    <collision>
      <geometry>
        <mesh filename="package://r2_gazebo/Media/models/taskboard/tskbd_panel_assembly_slot2_b04_cap.dae" scale="1 1 1"/>
      </geometry>
      <origin xyz="0.0 0.0 0.0" rpy="0 0 0"/>
    </collision>
    <inertial>
      <mass value="5"/>
      <inertia ixx="1" ixy="0.0" ixz="0.0" iyy="1" iyz="0.0" izz="1"/>
    </inertial>
  </link>

  <link name="taskboard_slot2_B02">
    <visual>
      <geometry>
        <mesh filename="package://r2_gazebo/Media/models/taskboard/tskbd_panel_assembly_slot2_b02.dae"/>
      </geometry>
      <origin xyz="0.0 0.0 0.0" rpy="0 0 0"/>
    </visual>
    <collision>
      <geometry>
        <mesh filename="package://r2_gazebo/Media/models/taskboard/tskbd_panel_assembly_slot2_b02.dae" scale="1 1 1"/>
      </geometry>
      <origin xyz="0.0 0.0 0.0" rpy="0 0 0"/>
    </collision>
    <inertial>
      <mass value="5"/>
      <inertia ixx="1" ixy="0.0" ixz="0.0" iyy="1" iyz="0.0" izz="1"/>
    </inertial>
  </link>

  <link name="taskboard_slot2_B02_Revolute">
    <inertial>
      <mass value="1"/>
      <inertia ixx="1" ixy="0.0" ixz="0.0" iyy="1" iyz="0.0" izz="1"/>
    </inertial>
  </link>

  <link name="taskboard_slot2_B02_Base">
    <visual>
      <geometry>
        <mesh filename="package://r2_gazebo/Media/models/taskboard/tskbd_panel_assembly_slot2_b02_base.dae"/>
      </geometry>
      <origin xyz="0.0 0.0 0.0" rpy="0 0 0"/>
    </visual>
    <collision>
      <geometry>
        <mesh filename="package://r2_gazebo/Media/models/taskboard/tskbd_panel_assembly_slot2_b02_base.dae" scale="0 0 0"/>
      </geometry>
      <origin xyz="0.0 0.0 0.0" rpy="0 0 0"/>
    </collision>
    <inertial>
      <mass value="5"/>
      <inertia ixx="1" ixy="0.0" ixz="0.0" iyy="1" iyz="0.0" izz="1"/>
    </inertial>
  </link>

  <link name="taskboard_slot2_B01_Base">
    <visual>
      <geometry>
        <mesh filename="package://r2_gazebo/Media/models/taskboard/tskbd_panel_assembly_slot2_b01_base.dae"/>
      </geometry>
      <origin xyz="0.0 0.0 0.0" rpy="0 0 0"/>
    </visual>
    <collision>
      <geometry>
        <mesh filename="package://r2_gazebo/Media/models/taskboard/tskbd_panel_assembly_slot2_b01_base.dae" scale="1 1 1"/>
      </geometry>
      <origin xyz="0.0 0.0 0.0" rpy="0 0 0"/>
    </collision>
    <inertial>
      <mass value="5"/>
      <inertia ixx="1" ixy="0.0" ixz="0.0" iyy="1" iyz="0.0" izz="1"/>
    </inertial>
  </link>

  <link name="taskboard_slot2_B05_Base">
    <visual>
      <geometry>
        <mesh filename="package://r2_gazebo/Media/models/taskboard/tskbd_panel_assembly_slot2_b05_base.dae"/>
      </geometry>
      <origin xyz="0.0 0.0 0.0" rpy="0 0 0"/>
    </visual>
    <collision>
      <geometry>
        <mesh filename="package://r2_gazebo/Media/models/taskboard/tskbd_panel_assembly_slot2_b05_base.dae" scale="1 1 1"/>
      </geometry>
      <origin xyz="0.0 0.0 0.0" rpy="0 0 0"/>
    </collision>
    <inertial>
      <mass value="5"/>
      <inertia ixx="1" ixy="0.0" ixz="0.0" iyy="1" iyz="0.0" izz="1"/>
    </inertial>
  </link>

  <link name="taskboard_slot2_B03">
    <visual>
      <geometry>
        <mesh filename="package://r2_gazebo/Media/models/taskboard/tskbd_panel_assembly_slot2_b03.dae"/>
      </geometry>
      <origin xyz="0.0 0.0 0.0" rpy="0 0 0"/>
    </visual>
    <collision>
      <geometry>
        <mesh filename="package://r2_gazebo/Media/models/taskboard/tskbd_panel_assembly_slot2_b03.dae" scale="1 1 1"/>
      </geometry>
      <origin xyz="0.0 0.0 0.0" rpy="0 0 0"/>
    </collision>
    <inertial>
      <mass value=".1"/>
      <inertia ixx="1" ixy="0.0" ixz="0.0" iyy="1" iyz="0.0" izz="1"/>
    </inertial>
  </link>

  <link name="taskboard_slot2_B03_Base">
    <visual>
      <geometry>
        <mesh filename="package://r2_gazebo/Media/models/taskboard/tskbd_panel_assembly_slot2_b03_base.dae"/>
      </geometry>
      <origin xyz="0.0 0.0 0.0" rpy="0 0 0"/>
    </visual>
    <collision>
      <geometry>
        <mesh filename="package://r2_gazebo/Media/models/taskboard/tskbd_panel_assembly_slot2_b03_base.dae" scale="0 0 0"/>
      </geometry>
      <origin xyz="0.0 0.0 0.0" rpy="0 0 0"/>
    </collision>
    <inertial>
      <mass value="5"/>
      <inertia ixx="1" ixy="0.0" ixz="0.0" iyy="1" iyz="0.0" izz="1"/>
    </inertial>
  </link>

  <link name="taskboard_slot2_B03_Prismatic">
    <inertial>
      <mass value=".01"/>
      <inertia ixx="1" ixy="0.0" ixz="0.0" iyy="1" iyz="0.0" izz="1"/>
    </inertial>
  </link>

  <link name="taskboard_slot2_B03_Strip">
    <visual>
      <geometry>
        <mesh filename="package://r2_gazebo/Media/models/taskboard/tskbd_panel_assembly_slot2_b03_strip.dae"/>
      </geometry>
      <origin xyz="0.0 0.0 0.0" rpy="0 0 0"/>
    </visual>
    <collision>
      <geometry>
        <mesh filename="package://r2_gazebo/Media/models/taskboard/tskbd_panel_assembly_slot2_b03_strip.dae" scale="0 0 0"/>
      </geometry>
      <origin xyz="0.0 0.0 0.0" rpy="0 0 0"/>
    </collision>
    <inertial>
      <mass value=".0001"/>
      <inertia ixx="1" ixy="0.0" ixz="0.0" iyy="1" iyz="0.0" izz="1"/>
    </inertial>
  </link>

  <joint name="world/dummy" type="fixed">
    <parent link="world"/>
    <child link="dummy"/>
    <origin rpy="0.0 0 0" xyz="0.0 0.0 0.0"/>
  </joint>

  <joint name="dummy/taskboard_lower" type="fixed">
    <parent link="dummy"/>
    <child link="taskboard_lower"/>
    <origin rpy="1.57 0 3.14" xyz=".02 -.48 1.3"/>
  </joint>

  <joint name="dummy/taskboard_lower_labels" type="fixed">
    <parent link="taskboard_lower"/>
    <child link="taskboard_lower_labels"/>
    <origin rpy="0 0 0" xyz="0.0 0.0 0"/>
  </joint>

  <joint name="taskboard_lower/taskboard_slot3" type="fixed">
    <parent link="taskboard_lower"/>
    <child link="taskboard_slot3"/>
    <origin rpy="0 0 0" xyz=".121 0.0 0"/>
  </joint>

  <joint name="taskboard_lower/taskboard_slot3_panel" type="fixed">
    <parent link="taskboard_lower"/>
    <child link="taskboard_slot3_panel"/>
    <origin rpy="0 0 0" xyz=".121 0.0 0"/>
  </joint>

  <joint name="taskboard_lower/taskboard_slot3_labels" type="fixed">
    <parent link="taskboard_lower"/>
    <child link="taskboard_slot3_labels"/>
    <origin rpy="0 0 0" xyz=".121 0.0 0"/>
  </joint>

  <joint name="taskboard_lower/taskboard_slot4" type="fixed">
    <parent link="taskboard_lower"/>
    <child link="taskboard_slot4"/>
    <origin rpy="0 0 0" xyz=".362 0.0 0"/>
  </joint>

  <joint name="taskboard_lower/taskboard_slot4_panel" type="fixed">
    <parent link="taskboard_lower"/>
    <child link="taskboard_slot4_panel"/>
    <origin rpy="0 0 0" xyz=".362 0.0 0"/>
  </joint>

  <joint name="taskboard_lower/taskboard_slot4_labels" type="fixed">
    <parent link="taskboard_lower"/>
    <child link="taskboard_slot4_labels"/>
    <origin rpy="0 0 0" xyz=".362 0.0 0"/>
  </joint>

  <joint name="taskboard_lower/taskboard_slot1" type="fixed">
    <parent link="taskboard_lower"/>
    <child link="taskboard_slot1"/>
    <origin rpy="0 0 0" xyz="-.362 0.0 0"/>
  </joint>


  <joint name="taskboard_lower/taskboard_slot1_panel" type="fixed">
    <parent link="taskboard_lower"/>
    <child link="taskboard_slot1_panel"/>
    <origin rpy="0 0 0" xyz="-.362 0.0 0"/>
  </joint>

  <joint name="taskboard_lower/taskboard_slot1_labels" type="fixed">
    <parent link="taskboard_lower"/>
    <child link="taskboard_slot1_labels"/>
    <origin rpy="0 0 0" xyz="-.362 0.0 0"/>
  </joint>

  <joint name="taskboard_lower/taskboard_slot1_switch1" type="revolute">
    <parent link="taskboard_slot1"/>
    <child link="taskboard_slot1_switch1"/>
    <origin rpy="0.419 0 0" xyz=".037 .111 0.005"/>
    <axis xyz="1 0 0"/>
    <limit effort="10000000.0" lower="-0.84" upper="0" velocity="1000"/>
  </joint>

  <joint name="taskboard_lower/taskboard_slot1_switch2" type="revolute">
    <parent link="taskboard_slot1"/>
    <child link="taskboard_slot1_switch2_pullout"/>
    <origin rpy=".47 0 0" xyz="-.0635 -.089 0.009"/>
    <axis xyz="1 0 0"/>
    <limit effort="10000000.0" lower="-.94" upper="0" velocity="1000"/>
  </joint>

  <joint name="taskboard_lower/taskboard_slot1_switch2_pullout" type="prismatic">
    <parent link="taskboard_slot1_switch2_pullout"/>
    <child link="taskboard_slot1_switch2"/>
    <origin rpy="0 0 0" xyz="0 0 0"/>
    <axis xyz="0 0 1" />
    <limit lower="-.002" upper="0.00" effort="100" velocity="100" />
  </joint>

  <joint name="taskboard_lower/taskboard_slot1_switch3" type="revolute">
    <parent link="taskboard_slot1"/>
    <child link="taskboard_slot1_switch3_pullout"/>
    <origin rpy=".47 0 0" xyz=".0005 -.089 0.009"/>
    <axis xyz="1 0 0"/>
    <limit effort="10000000.0" lower="-.94" upper="0" velocity="1000"/>
  </joint>

  <joint name="taskboard_lower/taskboard_slot1_switch3_pullout" type="prismatic">
    <parent link="taskboard_slot1_switch3_pullout"/>
    <child link="taskboard_slot1_switch3"/>
    <origin rpy="0 0 0" xyz="0 0 0"/>
    <axis xyz="0 0 1" />
    <limit lower="-.002" upper="0" effort="100" velocity="100" />
  </joint>

  <joint name="taskboard_lower/taskboard_slot1_switch4" type="revolute">
    <parent link="taskboard_slot1"/>
    <child link="taskboard_slot1_switch4_pullout"/>
    <origin rpy=".47 0 0" xyz=".0635 -.089 0.009"/>
    <axis xyz="1 0 0"/>
    <limit effort="10000000.0" lower="-.94" upper="0" velocity="1000"/>
  </joint>

  <joint name="taskboard_lower/taskboard_slot1_switch4_pullout" type="prismatic">
    <parent link="taskboard_slot1_switch4_pullout"/>
    <child link="taskboard_slot1_switch4"/>
    <origin rpy="0 0 0" xyz="0 0 0"/>
    <axis xyz="0 0 1" />
    <limit lower="-.002" upper="0" effort="100" velocity="100" />
  </joint>

  <joint name="taskboard_lower/taskboard_slot1_switch1_cover" type="revolute">
    <parent link="taskboard_slot1"/>
    <child link="taskboard_slot1_switch1_cover"/>
    <origin rpy="0 0 0" xyz="0.037 0.124 0.011"/>
    <axis xyz="1 0 0"/>
    <limit effort="10000000.0" lower="-1.57" upper="0" velocity="1000"/>
  </joint>

  <joint name="taskboard_lower/taskboard_slot1_guard" type="fixed">
    <parent link="taskboard_slot1"/>
    <child link="taskboard_slot1_guard"/>
    <origin rpy="0 0 0" xyz="0.037 0.124 0.011"/>
  </joint>

  <joint name="taskboard_lower/taskboard_slot1_A1" type="prismatic">
    <parent link="taskboard_slot1"/>
    <child link="taskboard_slot1_A1"/>
    <origin rpy="0 0 0" xyz="0 0 0"/>
    <axis xyz="0 0 1" />
    <limit lower="-0.0005" upper="0.001" effort="100" velocity="100" />
  </joint>

  <joint name="taskboard_lower/taskboard_slot1_A2" type="prismatic">
    <parent link="taskboard_slot1"/>
    <child link="taskboard_slot1_A2"/>
    <origin rpy="0 0 0" xyz="0 0 0"/>
    <axis xyz="0 0 1" />
    <limit lower="-.0005" upper="0.001" effort="100" velocity="100" />
  </joint>

  <joint name="taskboard_lower/taskboard_slot1_A3" type="prismatic">
    <parent link="taskboard_slot1"/>
    <child link="taskboard_slot1_A3"/>
    <origin rpy="0 0 0" xyz="0 0 0"/>
    <axis xyz="0 0 1" />
    <limit lower="-.0005" upper="0.001" effort="100" velocity="100" />
  </joint>

  <joint name="taskboard_lower/taskboard_slot1_B1" type="prismatic">
    <parent link="taskboard_slot1"/>
    <child link="taskboard_slot1_B1"/>
    <origin rpy="0 0 0" xyz="0 0 0"/>
    <axis xyz="0 0 1" />
    <limit lower="-.0005" upper="0.001" effort="100" velocity="100" />
  </joint>

  <joint name="taskboard_lower/taskboard_slot1_B2" type="prismatic">
    <parent link="taskboard_slot1"/>
    <child link="taskboard_slot1_B2"/>
    <origin rpy="0 0 0" xyz="0 0 0"/>
    <axis xyz="0 0 1" />
    <limit lower="-.0005" upper="0.001" effort="100" velocity="100" />
  </joint>

  <joint name="taskboard_lower/taskboard_slot1_B3" type="prismatic">
    <parent link="taskboard_slot1"/>
    <child link="taskboard_slot1_B3"/>
    <origin rpy="0 0 0" xyz="0 0 0"/>
    <axis xyz="0 0 1" />
    <limit lower="-.0005" upper="0.001" effort="100" velocity="100" />
  </joint>

  <joint name="taskboard_lower/taskboard_slot1_C1" type="prismatic">
    <parent link="taskboard_slot1"/>
    <child link="taskboard_slot1_C1"/>
    <origin rpy="0 0 0" xyz="0 0 0"/>
    <axis xyz="0 0 1" />
    <limit lower="-.0005" upper="0.001" effort="100" velocity="100" />
  </joint>

  <joint name="taskboard_lower/taskboard_slot1_C2" type="prismatic">
    <parent link="taskboard_slot1"/>
    <child link="taskboard_slot1_C2"/>
    <origin rpy="0 0 0" xyz="0 0 0"/>
    <axis xyz="0 0 1" />
    <limit lower="-.0005" upper="0.001" effort="100" velocity="100" />
  </joint>

  <joint name="taskboard_lower/taskboard_slot1_C3" type="prismatic">
    <parent link="taskboard_slot1"/>
    <child link="taskboard_slot1_C3"/>
    <origin rpy="0 0 0" xyz="0 0 0"/>
    <axis xyz="0 0 1" />
    <limit lower="-.0005" upper="0.001" effort="100" velocity="100" />
  </joint>

  <joint name="taskboard_lower/taskboard_slot1_blackplate" type="fixed">
    <parent link="taskboard_slot1"/>
    <child link="taskboard_slot1_blackplate"/>
    <origin rpy="0 0 0" xyz="0 0 0"/>
  </joint>

  <joint name="taskboard_lower/taskboard_slot1_switch" type="revolute">
    <parent link="taskboard_slot1"/>
    <child link="taskboard_slot1_switch"/>
    <origin rpy="0 0 0" xyz=".05 .01 .011"/>
    <axis xyz="1 0 0"/>
    <limit lower="-.5" upper=".5" effort="100" velocity="100" />
  </joint>

  <joint name="taskboard_lower/taskboard_slot2" type="fixed">
    <parent link="taskboard_lower"/>
    <child link="taskboard_slot2"/>
    <origin rpy="0 0 0" xyz="-0.121 0 0"/>
  </joint>

  <joint name="taskboard_lower/taskboard_slot2_panel" type="fixed">
    <parent link="taskboard_lower"/>
    <child link="taskboard_slot2_panel"/>
    <origin rpy="0 0 0" xyz="-0.121 0 0"/>
  </joint>

  <joint name="taskboard_lower/taskboard_slot2_labels1" type="fixed">
    <parent link="taskboard_lower"/>
    <child link="taskboard_slot2_labels1"/>
    <origin rpy="0 0 0" xyz="-0.121 0 0.005"/>
  </joint>

  <joint name="taskboard_lower/taskboard_slot2_labels2" type="fixed">
    <parent link="taskboard_lower"/>
    <child link="taskboard_slot2_labels2"/>
    <origin rpy="0 0 0" xyz="-0.121 .002 0.000"/>
  </joint>

  <joint name="taskboard_lower/taskboard_slot2_B06" type="revolute">
    <parent link="taskboard_slot2"/>
    <child link="taskboard_slot2_B06"/>
    <origin rpy="0 0 0" xyz=".057 -0.095 0.0145"/>
    <axis xyz="0 0 1"/>
    <limit lower="-1.57" upper="0" effort="100" velocity="100" />
  </joint>

  <joint name="taskboard_lower/taskboard_slot2_B06_Base" type="fixed">
    <parent link="taskboard_slot2"/>
    <child link="taskboard_slot2_B06_Base"/>
    <origin rpy="0 0 0" xyz=".057 -0.095 0.0"/>
  </joint>

  <joint name="taskboard_lower/taskboard_slot2_B04" type="revolute">
    <parent link="taskboard_slot2"/>
    <child link="taskboard_slot2_B04"/>
    <origin rpy="0 0 0" xyz="0.057 0 0.0198"/>
    <axis xyz="0 0 1"/>
    <limit lower="-3.14" upper="3.14" effort="100" velocity="100" />
  </joint>

  <joint name="taskboard_lower/taskboard_slot2_B04_Base" type="fixed">
    <parent link="taskboard_slot2"/>
    <child link="taskboard_slot2_B04_Base"/>
    <origin rpy="0 0 0" xyz=".057 0 0.0"/>
  </joint>

  <joint name="taskboard_lower/taskboard_slot2_B04_Cap" type="fixed">
    <parent link="taskboard_slot2"/>
    <child link="taskboard_slot2_B04_Cap"/>
    <origin rpy="0 0 0" xyz=".057 0 0.0198"/>
  </joint>

  <joint name="taskboard_lower/taskboard_slot2_B02_Base" type="fixed">
    <parent link="taskboard_slot2"/>
    <child link="taskboard_slot2_B02_Base"/>
    <origin rpy="0 0 0" xyz=".057 0.095 0"/>
  </joint>

  <joint name="taskboard_lower/taskboard_slot2_B02_Revolute" type="revolute">
    <parent link="taskboard_slot2"/>
    <child link="taskboard_slot2_B02_Revolute"/>
    <origin rpy="0 0 0" xyz=".057 0.095 0.011"/>
    <axis xyz="0 0 1"/>
    <limit lower="-3.14" upper="3.14" effort="100" velocity="100" />
  </joint>

  <joint name="taskboard_lower/taskboard_slot2_B02" type="revolute">
    <parent link="taskboard_slot2_B02_Revolute"/>
    <child link="taskboard_slot2_B02"/>
    <origin rpy="0 0 0" xyz="0 0 0"/>
    <axis xyz="0 1 0"/>
    <limit lower="0" upper="1.57" effort="100" velocity="100" />
  </joint>

  <joint name="taskboard_lower/taskboard_slot2_B01_Base" type="fixed">
    <parent link="taskboard_slot2"/>
    <child link="taskboard_slot2_B01_Base"/>
    <origin rpy="0 0 0" xyz="-.057 0.095 0"/>
  </joint>

  <joint name="taskboard_lower/taskboard_slot2_B05_Base" type="fixed">
    <parent link="taskboard_slot2"/>
    <child link="taskboard_slot2_B05_Base"/>
    <origin rpy="0 0 0" xyz="-.057 -0.0953 .0008"/>
  </joint>

  <joint name="taskboard_lower/taskboard_slot2_B03_Base" type="fixed">
    <parent link="taskboard_slot2"/>
    <child link="taskboard_slot2_B03_Base"/>
    <origin rpy="0 0 0" xyz="-0.0571 0 0"/>
  </joint>

  <joint name="taskboard_slot2_B03_Base/taskboard_slot2_B03_Prismatic" type="prismatic">
    <parent link="taskboard_slot2_B03_Base"/>
    <child link="taskboard_slot2_B03_Prismatic"/>
    <origin rpy="0 0 0" xyz="0 0 0.0267"/>
    <axis xyz="0 0 1"/>
    <limit lower="-.02" upper="0" effort="100" velocity="100"/>
  </joint>

  <joint name="taskboard_slot2_B03_Prismatic/taskboard_slot2_B03" type="revolute">
    <parent link="taskboard_slot2_B03_Prismatic"/>
    <child link="taskboard_slot2_B03"/>
    <origin rpy="0 0 0" xyz="0 0 0"/>
    <axis xyz="0 0 1"/>
    <limit lower="-3.14" upper="3.14" effort="100" velocity="100"/>
  </joint>

  <joint name="taskboard_slot2_B03/taskboard_slot2_B03_Strip" type="fixed">
    <parent link="taskboard_slot2_B03"/>
    <child link="taskboard_slot2_B03_Strip"/>
    <origin rpy="0 0 0" xyz="0 0 0"/>
  </joint>

  <gazebo reference="taskboard_lower">
    <material value="Gazebo/Black" />
  </gazebo>

  <gazebo reference="taskboard_slot3_labels">
    <material value="Gazebo/Black" />
  </gazebo>
<!--
  <gazebo reference="taskboard_slot4_panel">
    <material value="Gazebo/Grey" />
  </gazebo>

  <gazebo reference="taskboard_slot3_panel">
    <material value="Gazebo/Grey" />
  </gazebo>

  <gazebo reference="taskboard_slot2_panel">
    <material value="Gazebo/Grey" />
  </gazebo>

  <gazebo reference="taskboard_slot1_panel">
    <material value="Gazebo/Grey" />
  </gazebo>
-->
  <gazebo reference="taskboard_slot4_labels">
    <material value="Gazebo/Black" />
  </gazebo>

  <gazebo reference="taskboard_slot1">
    <material value="Gazebo/Grey" />
  </gazebo>

  <gazebo reference="taskboard_slot1_labels">
    <material value="Gazebo/Black" />
  </gazebo>

  <gazebo reference="taskboard_slot1_switch1_cover">
    <material value="Gazebo/Red" />
  </gazebo>

  <gazebo reference="taskboard_slot1_guard">
    <material value="Gazebo/Black" />
  </gazebo>

  <gazebo reference="taskboard_slot1_blackplate">
    <material value="Gazebo/Black" />
  </gazebo>

  <gazebo reference="taskboard_slot1_switch">
    <material value="Gazebo/Black" />
  </gazebo>

  <gazebo reference="taskboard_slot2_labels1">
    <material value="Gazebo/Black" />
  </gazebo>

  <gazebo reference="taskboard_slot2_labels2">
    <material value="Gazebo/Black" />
  </gazebo>
<!--
  <gazebo reference="taskboard_slot2_B06">
    <material value="Gazebo/Grey" />
  </gazebo>

  <gazebo reference="taskboard_slot2_B06_Base">
    <material value="Gazebo/Grey" />
  </gazebo>

  <gazebo reference="taskboard_slot2_B04">
    <material value="Gazebo/Grey" />
  </gazebo>

  <gazebo reference="taskboard_slot2_B04_Base">
    <material value="Gazebo/Grey" />
  </gazebo>
-->
  <gazebo reference="taskboard_slot2_B04_Cap">
    <material value="Gazebo/Black" />
  </gazebo>
<!--
  <gazebo reference="taskboard_slot2_B02_Base">
    <material value="Gazebo/Grey" />
  </gazebo>
-->
  <gazebo reference="taskboard_slot2_B02">
    <material value="Gazebo/Black" />
  </gazebo>
<!--
  <gazebo reference="taskboard_slot2_B01_Base">
    <material value="Gazebo/Grey" />
  </gazebo>

  <gazebo reference="taskboard_slot2_B05_Base">
    <material value="Gazebo/Grey" />
  </gazebo>

  <gazebo reference="taskboard_slot2_B03_Base">
    <material value="Gazebo/Grey" />
  </gazebo>
-->
  <gazebo reference="taskboard_slot2_B03">
    <material value="Gazebo/Black" />
  </gazebo>

  <gazebo reference="taskboard_slot2_B03_Strip">
    <material value="Gazebo/White" />
  </gazebo>

<!--   <gazebo>
    <controller:gazebo_taskboard name="gazebo_taskboard" plugin="libgazebo_taskboard.so">
    </controller:gazebo_taskboard>
  </gazebo> -->

  <gazebo>
    <plugin name="gazebo_taskboard" filename="libgazebo_taskboard.so"/>
  </gazebo>


</robot>
