<?xml version="1.0"?>
<robot>
  
  <link name="world"/>
  <link name="dummy">
    <inertial>
      <mass value="1"/>
      <inertia ixx="1" ixy="0.0" ixz="0.0" iyy="1" iyz="0.0" izz="1"/>
    </inertial>
  </link>

  <link name="Taskboard">
    <inertial>
      <mass value="1"/>
      <inertia ixx="1" ixy="0.0" ixz="0.0" iyy="1" iyz="0.0" izz="1"/>
    </inertial>
  </link>

  <link name="Taskboard_Slot2">
    <inertial>
      <mass value="1"/>
      <inertia ixx="1" ixy="0.0" ixz="0.0" iyy="1" iyz="0.0" izz="1"/>
    </inertial>
  </link>
<!--
  <link name="Link1_X">
    <inertial>
      <mass value=".01"/>
      <inertia ixx="1" ixy="0.0" ixz="0.0" iyy="1" iyz="0.0" izz="1"/>
    </inertial>
  </link>

  <link name="Link1_Y">
    <inertial>
      <mass value=".01"/>
      <inertia ixx="1" ixy="0.0" ixz="0.0" iyy="1" iyz="0.0" izz="1"/>
    </inertial>
  </link>
-->
  <link name="Link1">
    <visual>
      <geometry>
        <mesh filename="package://r2_gazebo/Media/models/taskboard/cable_link1.dae"/> 
      </geometry>
      <origin xyz="0.0 0.0 0.0" rpy="0 0 0"/>
    </visual> 
    <collision>
      <geometry>
        <mesh filename="package://r2_gazebo/Media/models/taskboard/cable_link1.dae" scale="0 0 0"/> 
      </geometry>
      <origin xyz="0.0 0.0 0.0" rpy="0 0 0"/>
    </collision>
    <inertial>
      <mass value=".01"/>
      <inertia ixx="1" ixy="0.0" ixz="0.0" iyy="1" iyz="0.0" izz="1"/>
    </inertial>
  </link>

  <link name="Link2_X">
    <inertial>
      <mass value=".01"/>
      <inertia ixx="1" ixy="0.0" ixz="0.0" iyy="1" iyz="0.0" izz="1"/>
    </inertial>
  </link>

  <link name="Link2_Y">
    <inertial>
      <mass value=".01"/>
      <inertia ixx="1" ixy="0.0" ixz="0.0" iyy="1" iyz="0.0" izz="1"/>
    </inertial>
  </link>

  <link name="Link2">
    <visual>
      <geometry>
        <mesh filename="package://r2_gazebo/Media/models/taskboard/cable_link2.dae"/> 
      </geometry>
      <origin xyz="0.0 0.0 0.0" rpy="0 0 0"/>
    </visual> 
    <collision>
      <geometry>
        <mesh filename="package://r2_gazebo/Media/models/taskboard/cable_link2.dae" scale="0 0 0"/> 
      </geometry>
      <origin xyz="0.0 0.0 0.0" rpy="0 0 0"/>
    </collision>
    <inertial>
      <mass value=".01"/>
      <inertia ixx="1" ixy="0.0" ixz="0.0" iyy="1" iyz="0.0" izz="1"/>
    </inertial>
  </link>

  <link name="Link3_X">
    <inertial>
      <mass value=".01"/>
      <inertia ixx="1" ixy="0.0" ixz="0.0" iyy="1" iyz="0.0" izz="1"/>
    </inertial>
  </link>

  <link name="Link3_Y">
    <inertial>
      <mass value=".01"/>
      <inertia ixx="1" ixy="0.0" ixz="0.0" iyy="1" iyz="0.0" izz="1"/>
    </inertial>
  </link>

  <link name="Link3">
    <visual>
      <geometry>
        <mesh filename="package://r2_gazebo/Media/models/taskboard/cable_link3.dae"/> 
      </geometry>
      <origin xyz="0.0 0.0 0.0" rpy="0 0 0"/>
    </visual> 
    <collision>
      <geometry>
        <mesh filename="package://r2_gazebo/Media/models/taskboard/cable_link3.dae" scale="0 0 0"/> 
      </geometry>
      <origin xyz="0.0 0.0 0.0" rpy="0 0 0"/>
    </collision>
    <inertial>
      <mass value=".01"/>
      <inertia ixx="1" ixy="0.0" ixz="0.0" iyy="1" iyz="0.0" izz="1"/>
    </inertial>
  </link>

  <link name="Link4_X">
    <inertial>
      <mass value=".01"/>
      <inertia ixx="1" ixy="0.0" ixz="0.0" iyy="1" iyz="0.0" izz="1"/>
    </inertial>
  </link>

  <link name="Link4_Y">
    <inertial>
      <mass value=".01"/>
      <inertia ixx="1" ixy="0.0" ixz="0.0" iyy="1" iyz="0.0" izz="1"/>
    </inertial>
  </link>

  <link name="Link4">
    <visual>
      <geometry>
        <mesh filename="package://r2_gazebo/Media/models/taskboard/cable_link5.dae"/> 
      </geometry>
      <origin xyz="0.0 0.0 0.0" rpy="0 0 0"/>
    </visual> 
    <collision>
      <geometry>
        <mesh filename="package://r2_gazebo/Media/models/taskboard/cable_link5.dae" scale="0 0 0"/> 
      </geometry>
      <origin xyz="0.0 0.0 0.0" rpy="0 0 0"/>
    </collision>
    <inertial>
      <mass value=".01"/>
      <inertia ixx="1" ixy="0.0" ixz="0.0" iyy="1" iyz="0.0" izz="1"/>
    </inertial>
  </link>

  <link name="Link5_X">
    <inertial>
      <mass value=".01"/>
      <inertia ixx="1" ixy="0.0" ixz="0.0" iyy="1" iyz="0.0" izz="1"/>
    </inertial>
  </link>

  <link name="Link5_Y">
    <inertial>
      <mass value=".01"/>
      <inertia ixx="1" ixy="0.0" ixz="0.0" iyy="1" iyz="0.0" izz="1"/>
    </inertial>
  </link>

  <link name="Link5">
    <visual>
      <geometry>
        <mesh filename="package://r2_gazebo/Media/models/taskboard/cable_link4.dae"/> 
      </geometry>
      <origin xyz="0.0 0.0 0.0" rpy="0 0 0"/>
    </visual> 
    <collision>
      <geometry>
        <mesh filename="package://r2_gazebo/Media/models/taskboard/cable_link4.dae" scale="0 0 0"/> 
      </geometry>
      <origin xyz="0.0 0.0 0.0" rpy="0 0 0"/>
    </collision>
    <inertial>
      <mass value=".01"/>
      <inertia ixx="1" ixy="0.0" ixz="0.0" iyy="1" iyz="0.0" izz="1"/>
    </inertial>
  </link>

  <link name="Taskboard_Slot2_B05_X">
    <inertial>
      <mass value=".01"/>
      <inertia ixx="1" ixy="0.0" ixz="0.0" iyy="1" iyz="0.0" izz="1"/>
    </inertial>
  </link>

  <link name="Taskboard_Slot2_B05_Y">
    <inertial>
      <mass value=".01"/>
      <inertia ixx="1" ixy="0.0" ixz="0.0" iyy="1" iyz="0.0" izz="1"/>
    </inertial>
  </link>

  <link name="Taskboard_Slot2_B05">
    <visual>
      <geometry>
        <mesh filename="package://r2_gazebo/Media/models/taskboard/tskbd_panel_assembly_slot2_b05.dae"/> 
      </geometry>
      <origin xyz="0.0 0.0 0.0" rpy="0 0 0"/>
    </visual> 
    <collision>
      <geometry>
        <mesh filename="package://r2_gazebo/Media/models/taskboard/tskbd_panel_assembly_slot2_b05.dae" scale="1 1 1"/> 
      </geometry>
      <origin xyz="0.0 0.0 0.0" rpy="0 0 0"/>
    </collision>
    <inertial>
      <mass value=".01"/>
      <inertia ixx="1" ixy="0.0" ixz="0.0" iyy="1" iyz="0.0" izz="1"/>
    </inertial>
  </link>

  <joint name="world/dummy" type="fixed">
    <parent link="world"/>
    <child link="dummy"/>
    <origin rpy="0.0 0 0" xyz="0.0 0.0 0.0"/>
  </joint>

  <joint name="dummy/Taskboard" type="fixed">
    <parent link="dummy"/>
    <child link="Taskboard"/>
    <origin rpy="1.57 0 3.14" xyz=".02 -.48 1.3"/>
  </joint>
    
  <joint name="Taskboard/Taskboard_slot2" type="fixed">
    <parent link="Taskboard"/>
    <child link="Taskboard_Slot2"/>
    <origin rpy="0 0 0" xyz="-0.121 0 0"/>
  </joint>
<!--
  <joint name="Taskboard_Slot2/Link1_X" type="continuous">
    <parent link="Taskboard_Slot2"/>
    <child link="Link1_X"/>
    <origin rpy="0 0 0" xyz="0 0.09195 0.01746"/>
    <axis xyz="1 0 0"/>
    <limit effort="100" velocity="100"/>
    <dynamics damping=".1" friction=".1" />
  </joint>

  <joint name="Link1_X/Link1_Y" type="continuous">
    <parent link="Link1_X"/>
    <child link="Link1_Y"/>
    <origin rpy="0 0 0" xyz="0 0 0"/>
    <axis xyz="0 1 0"/>
    <limit effort="100" velocity="100"/>
    <dynamics damping=".1" friction=".1" />
  </joint>
-->
  <joint name="Taskboard_Slot2/Link1" type="continuous">
    <parent link="Taskboard_Slot2"/>
    <child link="Link1"/>
    <origin rpy="0 0 0" xyz="0 -0.1236 0.01746"/>
    <axis xyz="0 0 1"/>
    <limit effort="100" velocity="100"/>
    <dynamics damping=".1" friction=".1" />
  </joint>

  <joint name="Link1/Link2_X" type="continuous">
    <parent link="Link1"/>
    <child link="Link2_X"/>
    <origin rpy="0 0 0" xyz="0 0 0.066"/>
    <axis xyz="1 0 0"/>
    <limit effort="100" velocity="100"/>
    <dynamics damping=".1" friction=".1" />
  </joint>

  <joint name="Link2_X/Link2_Y" type="continuous">
    <parent link="Link2_X"/>
    <child link="Link2_Y"/>
    <origin rpy="0 0 0" xyz="0 0 0"/>
    <axis xyz="0 1 0"/>
    <limit effort="100" velocity="100"/>
    <dynamics damping=".1" friction=".1" />
  </joint>

  <joint name="Link2_Y/Link2" type="continuous">
    <parent link="Link2_Y"/>
    <child link="Link2"/>
    <origin rpy="1.5708 0 0" xyz="0 0 0"/>
    <axis xyz="0 0 1"/>
    <limit effort="100" velocity="100"/>
    <dynamics damping=".1" friction=".1" />
  </joint>

  <joint name="Link2/Link3_X" type="continuous">
    <parent link="Link2"/>
    <child link="Link3_X"/>
    <origin rpy="0 0 0" xyz="0 0 0.04033"/>
    <axis xyz="1 0 0"/>
    <limit effort="100" velocity="100"/>
    <dynamics damping=".1" friction=".1" />
  </joint>

  <joint name="Link3_X/Link3_Y" type="continuous">
    <parent link="Link3_X"/>
    <child link="Link3_Y"/>
    <origin rpy="0 0 0" xyz="0 0 0"/>
    <axis xyz="0 1 0"/>
    <limit effort="100" velocity="100"/>
    <dynamics damping=".1" friction=".1" />
  </joint>

  <joint name="Link3_Y/Link3" type="continuous">
    <parent link="Link3_Y"/>
    <child link="Link3"/>
    <origin rpy="0 0 0" xyz="0 0 0"/>
    <axis xyz="0 0 1"/>
    <limit effort="100" velocity="100"/>
    <dynamics damping=".1" friction=".1" />
  </joint>

  <joint name="Link3/Link4_X" type="continuous">
    <parent link="Link3"/>
    <child link="Link4_X"/>
    <origin rpy="0 0 0" xyz="0 0 0.04733"/>
    <axis xyz="1 0 0"/>
    <limit effort="100" velocity="100"/>
    <dynamics damping=".1" friction=".1" />
  </joint>

  <joint name="Link4_X/Link4_Y" type="continuous">
    <parent link="Link4_X"/>
    <child link="Link4_Y"/>
    <origin rpy="0 0 0" xyz="0 0 0"/>
    <axis xyz="0 1 0"/>
    <limit effort="100" velocity="100"/>
    <dynamics damping=".1" friction=".1" />
  </joint>

  <joint name="Link4_Y/Link4" type="continuous">
    <parent link="Link4_Y"/>
    <child link="Link4"/>
    <origin rpy="0 0 0" xyz="0 0 0"/>
    <axis xyz="0 0 1"/>
    <limit effort="100" velocity="100"/>
    <dynamics damping=".1" friction=".1" />
  </joint>

  <joint name="Link4/Link5_X" type="continuous">
    <parent link="Link4"/>
    <child link="Link5_X"/>
    <origin rpy="0 0 0" xyz="0 0 0.03811"/>
    <axis xyz="1 0 0"/>
    <limit effort="100" velocity="100"/>
    <dynamics damping=".1" friction=".1" />
  </joint>

  <joint name="Link5_X/Link5_Y" type="continuous">
    <parent link="Link5_X"/>
    <child link="Link5_Y"/>
    <origin rpy="0 0 0" xyz="0 0 0"/>
    <axis xyz="0 1 0"/>
    <limit effort="100" velocity="100"/>
    <dynamics damping=".1" friction=".1" />
  </joint>

  <joint name="Link5_Y/Link5" type="continuous">
    <parent link="Link5_Y"/>
    <child link="Link5"/>
    <origin rpy="0 0  0" xyz="0 0 0"/>
    <axis xyz="0 0 1"/>
    <limit effort="100" velocity="100"/>
    <dynamics damping=".1" friction=".1" />
  </joint>

  <joint name="Link5/Taskboard_Slot2_B05_X" type="continuous">
    <parent link="Link5"/>
    <child link="Taskboard_Slot2_B05_X"/>
    <origin rpy="0 0 0" xyz="0 0 0.006223"/>
    <axis xyz="1 0 0"/>
    <limit effort="100" velocity="100"/>
    <dynamics damping=".1" friction=".1" />
  </joint>

  <joint name="Taskboard_Slot2_B05_X/Taskboard_Slot2_B05_Y" type="continuous">
    <parent link="Taskboard_Slot2_B05_X"/>
    <child link="Taskboard_Slot2_B05_Y"/>
    <origin rpy="0 0 0" xyz="0 0 0"/>
    <axis xyz="0 1 0"/>
    <limit effort="100" velocity="100"/>
    <dynamics damping=".1" friction=".1" />
  </joint>

  <joint name="Taskboard_Slot2_B05_Y/Taskboard_Slot2_B05" type="continuous">
    <parent link="Taskboard_Slot2_B05_Y"/>
    <child link="Taskboard_Slot2_B05"/>
    <origin rpy="0 0 0" xyz="0 0 0"/>
    <axis xyz="0 0 1"/>
    <limit effort="100" velocity="100"/>
    <dynamics damping=".1" friction=".1" />
  </joint>

  <gazebo reference="Link1">
    <material value="Gazebo/Black" />
  </gazebo>

  <gazebo reference="Link2">
    <material value="Gazebo/Black" />
  </gazebo>

  <gazebo reference="Link3">
    <material value="Gazebo/Black" />
  </gazebo>

  <gazebo reference="Link4">
    <material value="Gazebo/Black" />
  </gazebo>

  <gazebo reference="Link5">
    <material value="Gazebo/Black" />
  </gazebo>

  <gazebo reference="Taskboard_Slot2_B01">
    <material value="PR2/Grey3" />
  </gazebo>

</robot>
